Workbook
Name a: [1]Terminal!$F$1:$F$3
Name countif: #REF!
Name countif: #REF!
Name countif: #REF!
Name countif: #REF!
Name countif: #REF!
Name countif: #REF!
Name countif: #REF!
Name countif: #REF!
Name countif: #REF!
Name countif: #REF!
Name countif: #REF!
Name countif: #REF!
Name D: #REF!
Name D: #REF!
Name D: #REF!
Name D: #REF!
Name D: #REF!
Name D: #REF!
Name D: #REF!
Name D: #REF!
Name D: #REF!
Name D: #REF!
Name D: #REF!
Name D: #REF!
Name 公用设备大类: OFFSET(#REF!,1,0,COUNTA(#REF!)-COUNTIF(#REF!,0)-1,1)
Name 公用设备大类: OFFSET(#REF!,1,0,COUNTA(#REF!)-COUNTIF(#REF!,0)-1,1)
Name 公用设备大类: OFFSET(#REF!,1,0,COUNTA(#REF!)-COUNTIF(#REF!,0)-1,1)
Name 公用设备大类: OFFSET(#REF!,1,0,COUNTA(#REF!)-COUNTIF(#REF!,0)-1,1)
Name 公用设备大类: OFFSET(#REF!,1,0,COUNTA(#REF!)-COUNTIF(#REF!,0)-1,1)
Name 公用设备大类: OFFSET(#REF!,1,0,COUNTA(#REF!)-COUNTIF(#REF!,0)-1,1)
Name 公用设备大类: OFFSET(#REF!,1,0,COUNTA(#REF!)-COUNTIF(#REF!,0)-1,1)
Name 公用设备大类: OFFSET(#REF!,1,0,COUNTA(#REF!)-COUNTIF(#REF!,0)-1,1)
Name 公用设备大类: OFFSET(#REF!,1,0,COUNTA(#REF!)-COUNTIF(#REF!,0)-1,1)
Name 公用设备大类: OFFSET(#REF!,1,0,COUNTA(#REF!)-COUNTIF(#REF!,0)-1,1)
Name 公用设备大类: OFFSET(#REF!,1,0,COUNTA(#REF!)-COUNTIF(#REF!,0)-1,1)
Name 公用设备大类: OFFSET(#REF!,1,0,COUNTA(#REF!)-COUNTIF(#REF!,0)-1,1)
Name 公用设备名称: OFFSET(#REF!,MATCH(#REF!,#REF!,0)-1,0,COUNTIF(#REF!,#REF!),1)
Name 公用设备名称: OFFSET(#REF!,MATCH(#REF!,#REF!,0)-1,0,COUNTIF(#REF!,#REF!),1)
Name 公用设备名称: OFFSET(#REF!,MATCH(#REF!,#REF!,0)-1,0,COUNTIF(#REF!,#REF!),1)
Name 公用设备名称: OFFSET(#REF!,MATCH(#REF!,#REF!,0)-1,0,COUNTIF(#REF!,#REF!),1)
Name 公用设备名称: OFFSET(#REF!,MATCH(#REF!,#REF!,0)-1,0,COUNTIF(#REF!,#REF!),1)
Name 公用设备名称: OFFSET(#REF!,MATCH(#REF!,#REF!,0)-1,0,COUNTIF(#REF!,#REF!),1)
Name 公用设备名称: OFFSET(#REF!,MATCH(#REF!,#REF!,0)-1,0,COUNTIF(#REF!,#REF!),1)
Name 公用设备名称: OFFSET(#REF!,MATCH(#REF!,#REF!,0)-1,0,COUNTIF(#REF!,#REF!),1)
Name 公用设备名称: OFFSET(#REF!,MATCH(#REF!,#REF!,0)-1,0,COUNTIF(#REF!,#REF!),1)
Name 公用设备名称: OFFSET(#REF!,MATCH(#REF!,#REF!,0)-1,0,COUNTIF(#REF!,#REF!),1)
Name 公用设备名称: OFFSET(#REF!,MATCH(#REF!,#REF!,0)-1,0,COUNTIF(#REF!,#REF!),1)
Name 公用设备名称: OFFSET(#REF!,MATCH(#REF!,#REF!,0)-1,0,COUNTIF(#REF!,#REF!),1)
Name 专用工装设备大类: OFFSET(#REF!,1,0,COUNTA(#REF!)-COUNTIF(#REF!,0)-1,1)
Name 专用工装设备大类: OFFSET(#REF!,1,0,COUNTA(#REF!)-COUNTIF(#REF!,0)-1,1)
Name 专用工装设备大类: OFFSET(#REF!,1,0,COUNTA(#REF!)-COUNTIF(#REF!,0)-1,1)
Name 专用工装设备大类: OFFSET(#REF!,1,0,COUNTA(#REF!)-COUNTIF(#REF!,0)-1,1)
Name 专用工装设备大类: OFFSET(#REF!,1,0,COUNTA(#REF!)-COUNTIF(#REF!,0)-1,1)
Name 专用工装设备大类: OFFSET(#REF!,1,0,COUNTA(#REF!)-COUNTIF(#REF!,0)-1,1)
Name 专用工装设备大类: OFFSET(#REF!,1,0,COUNTA(#REF!)-COUNTIF(#REF!,0)-1,1)
Name 专用工装设备大类: OFFSET(#REF!,1,0,COUNTA(#REF!)-COUNTIF(#REF!,0)-1,1)
Name 专用工装设备大类: OFFSET(#REF!,1,0,COUNTA(#REF!)-COUNTIF(#REF!,0)-1,1)
Name 专用工装设备大类: OFFSET(#REF!,1,0,COUNTA(#REF!)-COUNTIF(#REF!,0)-1,1)
Name 专用工装设备大类: OFFSET(#REF!,1,0,COUNTA(#REF!)-COUNTIF(#REF!,0)-1,1)

Sheet 变更履历
A1: 序号 | B1: 零件包名称 | C1: 线束零件号 | D1: 零件名称 | E1: 临时图纸号 | F1: 正式图纸号 | G1: 客户PCR号 | H1: 内部ECN号 | I1: 对应样线订单 | J1: 变更履历 | K1: 更改时间 | L1: 备注
A2: 1 | B2: E281 | C2: 6608491523 | D2: 直流母线总成 | J2: 50mm²屏蔽镀锡铜包铝硅胶铝导线（FHLALR2GCCAATB2G/50.0/橙）导线用量由1.54m变更为1.59m； 16OR橙色编织套管（SCS2165A016）套管用量由1m变更为1.15m; 橙色布基胶带(LY5016019-OR2)布基胶带用量由4m变更为4.6m; 塑料支架E281-HB-04，数据变更，用量不变； 金属支架E281-ZJ-06，数据变更，用量不变； 新增4PCS 橡胶件 E281-XJ-09； | K2: 2025.12.29 | L2: 与报价BOM差异
J3: 1、50mm²屏蔽镀锡铜包铝硅胶铝导线（FHLALR2GCCAATB2G/50.0/橙）变更为35mm²屏蔽镀锡铜包铝导线，导线用量不变； 2、安费诺连接器总成型号： HVPC2P1600FT550-NH-P010变更为HVPC2P1600FT535-NH-P010 IPT2PFS050-S02P010变更为IPT2PFS035-S02P010 3、不带胶-热缩管型号变更： HS-125(2X)N20-30变更为HS-125(3X) 18-30，用量不变； | K3: 2026.01.04 | L3: 降线径
A4: 2 | B4: E281 | C4: 6608491524 | D4: 直流母线总成 | J4: 50mm²屏蔽镀锡铜包铝硅胶铝导线（FHLALR2GCCAATB2G/50.0/橙）导线用量由1.37m变更为1.41m； 16OR橙色编织套管（SCS2165A016）套管用量由0.85m变更为0.97m; 橙色布基胶带(LY5016019-OR2)布基胶带用量由4m变更为4.6m; 塑料支架E281-HB-03，数据变更，用量不变； 金属支架E281-ZJ-06，数据变更，用量不变； 新增4PCS 橡胶件 E281-XJ-09； | K4: 2025.12.29
J5: 1、50mm²屏蔽镀锡铜包铝硅胶铝导线（FHLALR2GCCAATB2G/50.0/橙）变更为35mm²屏蔽镀锡铜包铝导线，导线用量不变； 2、安费诺连接器总成型号： HVPC2P1600FV550-NH-P010变更为HVPC2P1600FV535-NH-P010 IPT2PFS050-S02P010变更为IPT2PFS035-S02P010 3、不带胶-热缩管型号变更： HS-125(2X)N20-30变更为HS-125(3X) 18-30，用量不变； | K5: 2026.01.04
J6: 安费诺连接器HVPC2P1600FV535-NH-P010 HVPC2P1600FV-15-P010 挡板_黑色 料号更改为HVPC2P1600FV-15P010，用量不变 HVPC2P1600FV-06-35-P010 外屏蔽环 料号更改为HVPC2P1600FV-06-35P010，用量不变 HVPC2P1600FV-12-35-P010 密封圈-黑色 料号更改为HVPC2P1600FV-12-35P010，用量不变 HVPC2P1600FV-11-35-P010 线卡-黑色 料号更改为HVPC2P1600FV-11-35P010，用量不变 HVPC2P1600FV-10-35-P010 尾盖-橙色 料号更改为HVPC2P1600FV-10-35P010，用量不变 | K6: 2026.02.05
A7: 3 | B7: E281 | C7: 6608442962 | D7: 直流母线总成 | J7: 50mm²屏蔽镀锡铜包铝硅胶铝导线（FHLALR2GCCAATB2G/50.0/橙）导线用量由1.9m变更为1.96m； 16OR橙色编织套管（SCS2165A016）套管用量由1.5m变更为1.52m; 橙色布基胶带(LY5016019-OR2)布基胶带用量由4m变更为4.6m; 塑料支架E281-HB-03，数据变更，用量不变； 金属支架E281-ZJ-06，数据变更，用量不变； 新增4PCS 橡胶件 E281-XJ-09； | K7: 2025.12.29
J8: 1、50mm²屏蔽镀锡铜包铝硅胶铝导线（FHLALR2GCCAATB2G/50.0/橙）变更为35mm²屏蔽镀锡铜包铝导线，导线用量不变； 2、安费诺连接器总成型号： HVPC2P1600FT550-NH-P010变更为HVPC2P1600FT535-NH-P010 IPT2PFS050-S02P010变更为IPT2PFS035-S02P010 3、不带胶-热缩管型号变更： HS-125(2X)N20-30变更为HS-125(3X) 18-30，用量不变； | K8: 2026.01.04
J9: 1.删除2PCS MS11-XJ-05； 2.增加2PCS E281-XJ-06，E281-XJ-06用量由2PCS变为4PCS； | K9: 2026.02.05
A10: 4 | B10: E281 | C10: 6608544875 | D10: 前驱直流母线 | J10: 50mm²屏蔽镀锡铜包铝硅胶铝导线 FHLALR2GCCAATB2G/50.0/橙变更为35mm²屏蔽镀锡铜包铝硅胶铜导线 FHLR2GCCAATB2G/35.0/橙，用量不变，供应商改为鑫宏业/斯普乐。 | K10: 2025.11.11
J11: E281-ZJ-09、E281-ZJ-10 金属支架外形变更，用量不变 | K11: 2025.12.4
B12: E281 | C12: 6608544875 | J12: 35方屏蔽铜包铝导线-FHLR2GCCAATB2G/35.0/橙导线用量由2.4m变为2.43m; 16OR橙色编织套管（SCS2165A016）套管用量由1.95m变更为2.01m; 塑料支架E281-HB-05，数据变更，用量不变； 金属支架E281-ZJ-10，数据变更，用量不变； 扎带绳111-00563用量由4PC变更为6PC； | K12: 2025.12.31
J13: 1、35mm²屏蔽镀锡铜包铝硅胶铜导线（FHLR2GCCAATB2G/35.0/橙）变更为25mm²屏蔽镀锡铜包铝硅胶铜导线（FHLR2GCCAATB2G/25.0/橙），导线用量不变； 2、安费诺连接器总成型号： HVPC2P1600FT535-NH-P010变更为HVPC2P1600FT525-NH-P010 IPT2P35P001-P010变更为IPT2P25P001-P010 3、IPT端子型号变更 3-2177380-1变更为1-2177380-1； 4、不带胶-热缩管型号变更： HS-125(2X)N20-30变更为HS-125(3X) 18-30，用量不变； | K13: 2026.01.04
J14: 1.SCS2165A016（A04101476）变更为SCS2165A013（A04101537），套管用量不变； | K14: 2026.03.02 | L14: 内部VAVE
J15: 扎带绳111-00563用量由4PC变更为7PC。 | K15: 2026.03.08
A16: 5 | B16: E281 | C16: 6608442964 | D16: 电动压缩机线束总成 | J16: YGC1612-EV-P2PNA2-6连接器更改为YGC1612-EV-PW2PNA2-4连接器，删除原有散件，用量不变。 | K16: 2025.11.11
B17: E281 | C17: 6608442964 | D17: 电动压缩机线束总成 | J17: 4.0mm²屏蔽镀锡铜包铝交联铝导线（FHLALR91XCCAATB91X/4.0/橙）导线用量由1.5m变更为1.59m; 橙色布基胶带(LY5016019-OR2)橙色布基胶带用量由0.4m变更为1.2m; 删除1PCS M6竖置螺柱卡PP9122201（A06101666）; 删除1PCS M6抬高螺柱卡PP9114201（A06003890）； 增加1PCS 7*12竖向杉树卡PP9118501（A06004939）； 增加1PCS T5抬高螺柱卡156-03490（A06101040）； 亚化 PVC胶带由P111W0192510002变更为P111W0192510003，用量不变； | K17: 2025.12.29
J18: 增加1PCS小扎带 111-00563； 增加1PCS橡胶件 E281-XJ-09； YGC1612-EV-PW2PNA2-4连接器型号变为YGC1612-EV-P2PWNA1-4，连接器散件按照永贵提供的资料更新 | K18: 2026.02.05
A19: 6 | B19: E281 | C19: 6608442963 | D19: 电动压缩机线束总成 | J19: YGC1612-EV-P2PNA2-6连接器更改为YGC1612-EV-PW2PNA2-4连接器，删除原有散件，用量不变。 | K19: 2025.11.11
B20: E281 | C20: 6608442963 | D20: 电动压缩机线束总成 | J20: 4.0mm²屏蔽镀锡铜包铝交联铝导线（FHLALR91XCCAATB91X/4.0/橙）导线用量由2.2m变更为2.72m; 橙色布基胶带(LY5016019-OR2)橙色布基胶带用量由0.4m变更为1.2m; 增加垫圈E281-XJ-10，1PCS； 分线器总成型号由F02-372011-110变更为F02-372011-111； 亚化 PVC胶带由P111W0192510002变更为P111W0192510003，用量不变； 删除1PCS M6抬高螺柱卡PP9114201（A06003890）； 增加1PCS T5抬高螺柱卡156-03490（A06101040）； | K20: 2025.12.29
J21: 增加1PCS小扎带 111-00563； 橡胶件 E281-XJ-10变更为E281-XJ-09，用量不变； 删除2PCS热缩管 HS-125 7.0-20； 橙色布基胶带LY5016019-OR2用量增加0.05m； YGC1612-EV-PW2PNA2-4连接器型号变为YGC1612-EV-P2PWNA1-4，连接器散件按照永贵提供的资料更新 | K21: 2026.02.05
A22: 7 | B22: E281 | C22: 6608516992 | D22: 电动压缩机线束总成 | J22: YGC1612-EV-P2PNA2-6连接器更改为YGC1612-EV-PW2PNA2-4连接器，删除原有散件，用量不变。 | K22: 2025.11.11
B23: E281 | C23: 6608516992 | D23: 电动压缩机线束总成 | J23: 4.0mm²屏蔽镀锡铜包铝交联铝导线（FHLALR91XCCAATB91X/4.0/橙）导线用量由2.31m变更为2.53m; 橙色布基胶带(LY5016019-OR2)橙色布基胶带用量由0.4m变更为1.2m; 增加垫圈E281-XJ-10，1PCS； 分线器总成型号由F02-372011-110变更为F02-372011-111； 亚化 PVC胶带由P111W0192510002变更为P111W0192510003，用量不变； 删除1PCS M6抬高螺柱卡PP9114201（A06003890）； 增加1PCS T5抬高螺柱卡156-03490（A06101040）； | K23: 2025.12.20
J24: 增加1PCS小扎带 111-00563； 橡胶件 E281-XJ-10变更为E281-XJ-09，用量不变； 删除2PCS热缩管 HS-125 7.0-20； 橙色布基胶带LY5016019-OR2用量增加0.05m； YGC1612-EV-PW2PNA2-4连接器型号变为YGC1612-EV-P2PWNA1-4，连接器散件按照永贵提供的资料更新 | K24: 2026.02.05
A25: 8 | B25: E281 | C25: 6608519100 | D25: 电动压缩机线束总成 | J25: 1. 新增E281-HB-06塑料支架、E281-ZJ-11金属支架，用量为1PCS； 2. LY5016019-OR2橙色布基胶带用量由0.6m增加为1m； 3. PP9104320箭头扎带数量由4PCS减少为3PCS； 4. 删除PP9121201管架卡扣； 5. 新增111-00563扎带绳，用量为2PCS。 | K25: 2025.12.4
B26: E281 | C26: 6608519100 | D26: 电动压缩机线束总成 | J26: 12OR橙色波纹管（LG3305D012B）波纹管用量由0.8m变更为0.82m; 塑料支架E281-HB-06，数据变更，用量不变； 金属支架E281-ZJ-11，数据变更，用量不变； 亚化 PVC胶带由P111W0192510002变更为P111W0192510003，用量不变； | K26: 2025.12.29
J27: 金属支架E281-ZJ-11变为塑料支架E281-HB-10； 7*12箭头卡扣PP9104320数量由3PCS变为2PCS； 扎带绳111-00563数量由2PCS变为3PCS | K27: 2026.02.05
A28: 9 | B28: E281 | C28: 6608442966 | D28: 组合式充电插座线束总成 | J28: 1. 更新充电插座2523328-1 散件料号； 2. 更新低压插件1-2438787-1散件料号； 3. 更新低压插件1-2355517-5散件料号； 4.删除电子锁低压插件805-122-541，新增电子锁低压插件5-965906-5； 5.更新直流HVSPC2P1900FS112和交流HVC2PG263UFSW106-NH高压插件散件； 6.亚化 PVC胶带由P111W0192510002变更为P111W0192510003，用量不变； 7.删除塑料支架1PCS E281-HB-01和1 PCS E281-HB-02，增加1 PCS塑料支架E281-HB-07； 8.新增1 PCS橡胶件E281-XJ-11； 9.删除1 PCS M8箭头卡扣PP9108401，新增1PCS M6.5箭头卡扣126-00177； 10.删除 1PCS M5螺柱卡扣PP9123801，新增1PCS M6侧置螺柱卡PP9120801； 11.扎带绳扎带绳数量由7PCS变更为9PCS； 12.删除3 PCS 扎带绳108-00150，新增3PCS 扎带绳111-00580； 13.新增1PCS 隔线扎带绳PP9127401； | K28: 2025.12.29
J29: 1、充电插座电子锁拉绳料号由2518993-3/4变更为2518993-4 2、更新低压插件5-2385463-1的散件信息 3、热缩管变更 删除2PCS带胶-热缩管10106880； 新增2PCS带胶-热缩管-黑色HDGW 12-30； 新增4PCS不带胶-热缩管-黑色HS-125(3X) 9-30； 新增1PCS带胶-热缩管-透明HDGW 6-30； | K29: 2026.01.04
J30: 1、111-00563数量由9PCS变更为4PCS； 2、111-00580数量由3PCS变更为4PCS； 3、电子锁低压连接器总成2298159-1，端子型号由965906-1变更为5-965906-1，用量不变 4、6方接地线 FHL91X/6.0/黄绿用量增加0.03m； 5、0.5方低压线由黑色变为不同颜色； 6、LG3305D012B变更为LG3305R010B，用量不变； 备注：按照客户要求3孔橡胶件需要配合国内外做兼容，由于国内AC线为2根6方，国外AC线为4根（2根5方，2根2.5方），国内AC线采用10OR波纹管，国外AC线采用编织套管。 7、7*12箭头扎带PP9104320用量由2PCS变为3PCS； 8、删除1PCS一字卡PP9220301； 9、111-00563用量由9PCS变为4PCS； 10、111-00580用量由3PCS变为4PCS； 11、橡胶件E281-XJ-11变更为E281-XJ-09； 12.删除4PCS不带胶热缩管HS-125(3X) 9-30； | K30: 2026.02.05
J31: 1.带胶热缩管-透明由长春海达HDGW 6-30变更为双宇DPHS12-X0-5.75/1.27-L30（A04101758），用量不变； 2.防水泥由6211015110AL变更为CH101-1.5*19*100，用量不变；——防水泥暂无验证长度先不变更，待工艺验证后更改BOM； | K31: 2026.02.25 | L31: 内部VAVE待实施
J32: 橙色PVC胶带P111W0192510003用量由4.5米减少为3米； 增加黑色PVC胶带P111W1192510003，用量1.5米； | K32: 2026.03.08 | L32: 低压线上使用黑色PVC胶带
A33: 10 | B33: E281 | C33: 6608442965 | D33: 组合式充电插座线束总成 | J33: 1. 更新充电插座2523328-1 散件料号； 2. 更新低压插件1-2438787-1散件料号； 3. 更新低压插件1-2355517-5散件料号； 4.删除电子锁低压插件805-122-541，新增电子锁低压插件5-965906-5； 5.更新直流HVSPC2P1900FS112和交流HVC2PG263UFSW106-NH高压插件散件； 6.亚化 PVC胶带由P111W0192510002变更为P111W0192510003，用量不变； 7.删除塑料支架1PCS E281-HB-01和1 PCS E281-HB-02，增加1 PCS塑料支架E281-HB-07； 8.新增1 PCS橡胶件E281-XJ-11； 9.删除1 PCS M8箭头卡扣PP9108401，新增1PCS M6.5箭头卡扣126-00177； 10.删除 1PCS M5螺柱卡扣PP9123801，新增1PCS M6侧置螺柱卡PP9120801； 11.扎带绳扎带绳数量由7PCS变更为9PCS； 12.删除3 PCS 扎带绳108-00150，新增3PCS 扎带绳111-00580； 13.新增1PCS 隔线扎带绳PP9127401； | K33: 2025.12.29
J34: 1、充电插座电子锁拉绳料号由2518993-3/4变更为2518993-4 2、更新低压插件5-2385463-1的散件信息 3、热缩管变更 删除2PCS带胶-热缩管10106880； 新增2PCS带胶-热缩管-黑色HDGW 12-30； 新增4PCS不带胶-热缩管-黑色HS-125(3X) 9-30； 新增1PCS带胶-热缩管-透明HDGW 6-30； | K34: 2026.01.04
J35: 1、111-00563数量由9PCS变更为4PCS； 2、111-00580数量由3PCS变更为4PCS； 3、电子锁低压连接器总成2298159-1，端子型号由965906-1变更为5-965906-1，用量不变 4、6方接地线 FHL91X/6.0/黄绿用量增加0.03m； 5、0.5方低压线由黑色变为不同颜色； 6、LG3305D012B变更为LG3305R010B，用量不变； 备注：按照客户要求3孔橡胶件需要配合国内外做兼容，由于国内AC线为2根6方，国外AC线为4根（2根5方，2根2.5方），国内AC线采用10OR波纹管，国外AC线采用编织套管。 7、7*12箭头扎带PP9104320用量由2PCS变为3PCS； 8、删除1PCS一字卡PP9220301； 9、111-00563用量由9PCS变为4PCS； 10、111-00580用量由3PCS变为4PCS； 11、橡胶件E281-XJ-11变更为E281-XJ-09； 12.删除4PCS不带胶热缩管HS-125(3X) 9-30； | K35: 2026.02.05
J36: 1.带胶热缩管-透明由长春海达HDGW 6-30变更为双宇DPHS12-X0-5.75/1.27-L30（A04101758），用量不变； 2.防水泥由6211015110AL变更为CH101-1.5*19*100，用量不变；——防水泥暂无验证长度先不变更，待工艺验证后更改BOM； | K36: 2026.02.25 | L36: 内部VAVE待实施
J37: 橙色PVC胶带P111W0192510003用量由4.5米减少为3米； 增加黑色PVC胶带P111W1192510003，用量1.5米； | K37: 2026.03.08 | L37: 低压线上使用黑色PVC胶带
A38: 11 | B38: E281 | C38: 6608507680 | D38: 组合式充电插座线束总成 | J38: 1. 更新充电插座2523328-1 散件料号； 2. 更新低压插件1-2438787-1散件料号； 3. 更新低压插件1-2355517-5散件料号； 4.删除电子锁低压插件805-122-541，新增电子锁低压插件5-965906-5； 5.更新直流HVSPC2P1900FS112和交流HVC2PG263UFSW106-NH高压插件散件； 6.亚化 PVC胶带由P111W0192510002变更为P111W0192510003，用量不变； 7.删除塑料支架1PCS E281-HB-01和1 PCS E281-HB-02，增加1 PCS塑料支架E281-HB-07； 8.新增1 PCS橡胶件E281-XJ-11； 9.删除1 PCS M8箭头卡扣PP9108401，新增1PCS M6.5箭头卡扣126-00177； 10.删除 1PCS M5螺柱卡扣PP9123801，新增1PCS M6侧置螺柱卡PP9120801； 11.扎带绳扎带绳数量由9PCS变更为11PCS； 12.删除3 PCS 扎带绳108-00150，新增3PCS 扎带绳111-00580； 13.新增1PCS 隔线扎带绳PP9127401； | K38: 2025.12.29
J39: 1、充电插座电子锁拉绳料号由2518993-3/4变更为2518993-4 2、更新低压插件5-2385463-1的散件信息 3、热缩管变更 删除2PCS带胶-热缩管10106880； 新增2PCS带胶-热缩管-黑色HDGW 12-30； 新增4PCS不带胶-热缩管-黑色HS-125(3X) 9-30； 新增1PCS带胶-热缩管-透明HDGW 6-30； | K39: 2026.01.04
J40: 1、111-00563数量由9PCS变更为4PCS； 2、111-00580数量由3PCS变更为4PCS； 3、电子锁低压连接器总成2298159-1，端子型号由965906-1变更为5-965906-1，用量不变 4、6方接地线 FHL91X/6.0/黄绿用量增加0.03m； 5、0.5方低压线由黑色变为不同颜色； 6、LG3305D012B变更为LG3305R010B，用量不变； 备注：按照客户要求3孔橡胶件需要配合国内外做兼容，由于国内AC线为2根6方，国外AC线为4根（2根5方，2根2.5方），国内AC线采用10OR波纹管，国外AC线采用编织套管。 7、7*12箭头扎带PP9104320用量由2PCS变为3PCS； 8、删除1PCS一字卡PP9220301； 9、111-00563用量由11PCS变为6PCS； 10、111-00580用量由3PCS变为4PCS； 11、橡胶件E281-XJ-11变更为E281-XJ-09； 12.删除4PCS不带胶热缩管HS-125(3X) 9-30； | K40: 2026.02.05
...

Sheet 二次物料明细
A1: ★ | B1: 若有其他方案推荐,经评估可行后可更新至K列
A2: 组件描述 | B2: 物料名称（英文/中文） | C2: 用量 | D2: 单位 | E2: 单价(CU=7.2) | F2: 单位铜重 | G2: 铜重 | H2: 供应商名称 | I2: 产地 | J2: SAP号 | K2: 备注
A3: HVPC2P1600FT5-NH-MP010 | B3: =VLOOKUP(A3,KSK线束BOM明细!D:N,2,0) -> 护套（145度反装 A键位） | C3: =SUMIFS(KSK线束BOM明细!K:K,KSK线束BOM明细!D:D,A3) -> 3 | D3: =VLOOKUP(A3,KSK线束BOM明细!D:N,9,0) -> PCS | H3: =VLOOKUP(A3,KSK线束BOM明细!D:N,10,0) -> 安费诺 | J3: =VLOOKUP(A3,KSK线束BOM明细!D:N,4,0) -> A02105032 | K3: =VLOOKUP(A3,KSK线束BOM明细!D:N,11,0) -> 客户指定
A4: HVPC2P1600FT-09P010 | B4: =VLOOKUP(A4,KSK线束BOM明细!D:N,2,0) -> 插头端子-单粒焊接 | C4: =SUMIFS(KSK线束BOM明细!K:K,KSK线束BOM明细!D:D,A4) -> 6 | D4: =VLOOKUP(A4,KSK线束BOM明细!D:N,9,0) -> PCS | H4: =VLOOKUP(A4,KSK线束BOM明细!D:N,10,0) -> 安费诺 | J4: =VLOOKUP(A4,KSK线束BOM明细!D:N,4,0) -> A03103389 | K4: =VLOOKUP(A4,KSK线束BOM明细!D:N,11,0) -> 客户指定
A5: HVPC2P1600FV-15P010 | B5: =VLOOKUP(A5,KSK线束BOM明细!D:N,2,0) -> 挡板_黑色 | C5: =SUMIFS(KSK线束BOM明细!K:K,KSK线束BOM明细!D:D,A5) -> 8 | D5: =VLOOKUP(A5,KSK线束BOM明细!D:N,9,0) -> PCS | H5: =VLOOKUP(A5,KSK线束BOM明细!D:N,10,0) -> 安费诺 | J5: =VLOOKUP(A5,KSK线束BOM明细!D:N,4,0) -> A02104375 | K5: =VLOOKUP(A5,KSK线束BOM明细!D:N,11,0) -> 客户指定
A6: HVPC2P1600FV-06-35P010 | B6: =VLOOKUP(A6,KSK线束BOM明细!D:N,2,0) -> 插头外屏蔽环 | C6: =SUMIFS(KSK线束BOM明细!K:K,KSK线束BOM明细!D:D,A6) -> 6 | D6: =VLOOKUP(A6,KSK线束BOM明细!D:N,9,0) -> PCS | H6: =VLOOKUP(A6,KSK线束BOM明细!D:N,10,0) -> 安费诺 | J6: =VLOOKUP(A6,KSK线束BOM明细!D:N,4,0) -> A03103387 | K6: =VLOOKUP(A6,KSK线束BOM明细!D:N,11,0) -> 客户指定
A7: HVC2P80FS1-47P010 | B7: =VLOOKUP(A7,KSK线束BOM明细!D:N,2,0) -> 插头屏蔽内环 | C7: =SUMIFS(KSK线束BOM明细!K:K,KSK线束BOM明细!D:D,A7) -> 4 | D7: =VLOOKUP(A7,KSK线束BOM明细!D:N,9,0) -> PCS | H7: =VLOOKUP(A7,KSK线束BOM明细!D:N,10,0) -> 安费诺 | J7: =VLOOKUP(A7,KSK线束BOM明细!D:N,4,0) -> A03103388 | K7: =VLOOKUP(A7,KSK线束BOM明细!D:N,11,0) -> 客户指定
A8: HVPC2P1600FV-12-35P010 | B8: =VLOOKUP(A8,KSK线束BOM明细!D:N,2,0) -> 插头线束密封圈 | C8: =SUMIFS(KSK线束BOM明细!K:K,KSK线束BOM明细!D:D,A8) -> 6 | D8: =VLOOKUP(A8,KSK线束BOM明细!D:N,9,0) -> PCS | H8: =VLOOKUP(A8,KSK线束BOM明细!D:N,10,0) -> 安费诺 | J8: =VLOOKUP(A8,KSK线束BOM明细!D:N,4,0) -> A02105020 | K8: =VLOOKUP(A8,KSK线束BOM明细!D:N,11,0) -> 客户指定
A9: HVPC2P1600FV-11-35P010 | B9: =VLOOKUP(A9,KSK线束BOM明细!D:N,2,0) -> 插头线卡 | C9: =SUMIFS(KSK线束BOM明细!K:K,KSK线束BOM明细!D:D,A9) -> 6 | D9: =VLOOKUP(A9,KSK线束BOM明细!D:N,9,0) -> PCS | H9: =VLOOKUP(A9,KSK线束BOM明细!D:N,10,0) -> 安费诺 | J9: =VLOOKUP(A9,KSK线束BOM明细!D:N,4,0) -> A02105018 | K9: =VLOOKUP(A9,KSK线束BOM明细!D:N,11,0) -> 客户指定
A10: HVPC2P1600FV-10-35P010 | B10: =VLOOKUP(A10,KSK线束BOM明细!D:N,2,0) -> 插头尾盖 | C10: =SUMIFS(KSK线束BOM明细!K:K,KSK线束BOM明细!D:D,A10) -> 6 | D10: =VLOOKUP(A10,KSK线束BOM明细!D:N,9,0) -> PCS | H10: =VLOOKUP(A10,KSK线束BOM明细!D:N,10,0) -> 安费诺 | J10: =VLOOKUP(A10,KSK线束BOM明细!D:N,4,0) -> A02105019 | K10: =VLOOKUP(A10,KSK线束BOM明细!D:N,11,0) -> 客户指定
A11: N022525276C | B11: =VLOOKUP(A11,KSK线束BOM明细!D:N,2,0) -> 焊接端子-70 | C11: =SUMIFS(KSK线束BOM明细!K:K,KSK线束BOM明细!D:D,A11) -> 6 | D11: =VLOOKUP(A11,KSK线束BOM明细!D:N,9,0) -> PCS | H11: =VLOOKUP(A11,KSK线束BOM明细!D:N,10,0) -> 安费诺 | J11: =VLOOKUP(A11,KSK线束BOM明细!D:N,4,0) -> A03103440 | K11: =VLOOKUP(A11,KSK线束BOM明细!D:N,11,0) -> 客户指定
A12: IPT2PFS035-GA-01P010 | B12: =VLOOKUP(A12,KSK线束BOM明细!D:N,2,0) -> 主体组合件 | C12: =SUMIFS(KSK线束BOM明细!K:K,KSK线束BOM明细!D:D,A12) -> 3 | D12: =VLOOKUP(A12,KSK线束BOM明细!D:N,9,0) -> PCS | H12: =VLOOKUP(A12,KSK线束BOM明细!D:N,10,0) -> 安费诺 | J12: =VLOOKUP(A12,KSK线束BOM明细!D:N,4,0) -> A02102660 | K12: =VLOOKUP(A12,KSK线束BOM明细!D:N,11,0) -> 客户指定
A13: IPT2PFS-S01-35P010 | B13: =VLOOKUP(A13,KSK线束BOM明细!D:N,2,0) -> 压接屏蔽内环-35 | C13: =SUMIFS(KSK线束BOM明细!K:K,KSK线束BOM明细!D:D,A13) -> 6 | D13: =VLOOKUP(A13,KSK线束BOM明细!D:N,9,0) -> PCS | H13: =VLOOKUP(A13,KSK线束BOM明细!D:N,10,0) -> 安费诺 | J13: =VLOOKUP(A13,KSK线束BOM明细!D:N,4,0) -> A03101954 | K13: =VLOOKUP(A13,KSK线束BOM明细!D:N,11,0) -> 客户指定
A14: IPT2PFS-S02-35P010 | B14: =VLOOKUP(A14,KSK线束BOM明细!D:N,2,0) -> 压接屏蔽外环-35/50 | C14: =SUMIFS(KSK线束BOM明细!K:K,KSK线束BOM明细!D:D,A14) -> 6 | D14: =VLOOKUP(A14,KSK线束BOM明细!D:N,9,0) -> PCS | H14: =VLOOKUP(A14,KSK线束BOM明细!D:N,10,0) -> 安费诺 | J14: =VLOOKUP(A14,KSK线束BOM明细!D:N,4,0) -> A03101953 | K14: =VLOOKUP(A14,KSK线束BOM明细!D:N,11,0) -> 客户指定
... A26: 111-00563 | B26: =VLOOKUP(A26,KSK线束BOM明细!D:N,2,0) -> 扎带绳 | C26: =SUMIFS(KSK线束BOM明细!K:K,KSK线束BOM明细!D:D,A26) -> 47 | D26: =VLOOKUP(A26,KSK线束BOM明细!D:N,9,0) -> PCS | H26: =VLOOKUP(A26,KSK线束BOM明细!D:N,10,0) -> 海尔曼太通 | J26: =VLOOKUP(A26,KSK线束BOM明细!D:N,4,0) -> A06010012 | K26: =VLOOKUP(A26,KSK线束BOM明细!D:N,11,0) -> ★
A27: X1-BQ-01 标签140x30mm | B27: =VLOOKUP(A27,KSK线束BOM明细!D:N,2,0) -> 产品标签 | C27: =SUMIFS(KSK线束BOM明细!K:K,KSK线束BOM明细!D:D,A27) -> 11 | D27: =VLOOKUP(A27,KSK线束BOM明细!D:N,9,0) -> PCS | H27: =VLOOKUP(A27,KSK线束BOM明细!D:N,10,0) -> 洪众 | J27: =VLOOKUP(A27,KSK线束BOM明细!D:N,4,0) -> 70002326
A28: HVPC2P1600FV5-NH-M-P010 | B28: =VLOOKUP(A28,KSK线束BOM明细!D:N,2,0) -> 护套-90度-反装-CODE A | C28: =SUMIFS(KSK线束BOM明细!K:K,KSK线束BOM明细!D:D,A28) -> 1 | D28: =VLOOKUP(A28,KSK线束BOM明细!D:N,9,0) -> PCS | H28: =VLOOKUP(A28,KSK线束BOM明细!D:N,10,0) -> 安费诺 | J28: =VLOOKUP(A28,KSK线束BOM明细!D:N,4,0) -> A02105143 | K28: =VLOOKUP(A28,KSK线束BOM明细!D:N,11,0) -> 客户指定
A29: HVPC2P1600FV-09-P010 | B29: =VLOOKUP(A29,KSK线束BOM明细!D:N,2,0) -> 焊接端子-镀银 | C29: =SUMIFS(KSK线束BOM明细!K:K,KSK线束BOM明细!D:D,A29) -> 2 | D29: =VLOOKUP(A29,KSK线束BOM明细!D:N,9,0) -> PCS | H29: =VLOOKUP(A29,KSK线束BOM明细!D:N,10,0) -> 安费诺 | J29: =VLOOKUP(A29,KSK线束BOM明细!D:N,4,0) -> A03103438 | K29: =VLOOKUP(A29,KSK线束BOM明细!D:N,11,0) -> 客户指定
A30: HVPC2P1800FS-11-25G-P010 | B30: =VLOOKUP(A30,KSK线束BOM明细!D:N,2,0) -> 内屏蔽环 | C30: =SUMIFS(KSK线束BOM明细!K:K,KSK线束BOM明细!D:D,A30) -> 2 | D30: =VLOOKUP(A30,KSK线束BOM明细!D:N,9,0) -> PCS | H30: =VLOOKUP(A30,KSK线束BOM明细!D:N,10,0) -> 安费诺 | J30: =VLOOKUP(A30,KSK线束BOM明细!D:N,4,0) -> A03103437 | K30: =VLOOKUP(A30,KSK线束BOM明细!D:N,11,0) -> 客户指定
A31: E281-HB-03 | B31: =VLOOKUP(A31,KSK线束BOM明细!D:N,2,0) -> 塑料支架（带2个衬套） | C31: =SUMIFS(KSK线束BOM明细!K:K,KSK线束BOM明细!D:D,A31) -> 1 | D31: =VLOOKUP(A31,KSK线束BOM明细!D:N,9,0) -> PCS | H31: =VLOOKUP(A31,KSK线束BOM明细!D:N,10,0) -> 上海程达 | J31: =VLOOKUP(A31,KSK线束BOM明细!D:N,4,0) -> A06102157 | K31: =VLOOKUP(A31,KSK线束BOM明细!D:N,11,0) -> ★
A32: E281-ZJ-07 | B32: =VLOOKUP(A32,KSK线束BOM明细!D:N,2,0) -> 金属支架 | C32: =SUMIFS(KSK线束BOM明细!K:K,KSK线束BOM明细!D:D,A32) -> 1 | D32: =VLOOKUP(A32,KSK线束BOM明细!D:N,9,0) -> PCS | H32: =VLOOKUP(A32,KSK线束BOM明细!D:N,10,0) -> 华凯 | J32: =VLOOKUP(A32,KSK线束BOM明细!D:N,4,0) -> A06102145 | K32: =VLOOKUP(A32,KSK线束BOM明细!D:N,11,0) -> ★
A33: HVPC2P1600FV-06-25P010 | B33: =VLOOKUP(A33,KSK线束BOM明细!D:N,2,0) -> 插头外屏蔽环 | C33: =SUMIFS(KSK线束BOM明细!K:K,KSK线束BOM明细!D:D,A33) -> 2 | D33: =VLOOKUP(A33,KSK线束BOM明细!D:N,9,0) -> PCS | H33: =VLOOKUP(A33,KSK线束BOM明细!D:N,10,0) -> 安费诺 | J33: =VLOOKUP(A33,KSK线束BOM明细!D:N,4,0) -> A03103410 | K33: =VLOOKUP(A33,KSK线束BOM明细!D:N,11,0) -> 客户指定
A34: HVPC2P1800FS-11-25P010 | B34: =VLOOKUP(A34,KSK线束BOM明细!D:N,2,0) -> 插头屏蔽内环 | C34: =SUMIFS(KSK线束BOM明细!K:K,KSK线束BOM明细!D:D,A34) -> 2 | D34: =VLOOKUP(A34,KSK线束BOM明细!D:N,9,0) -> PCS | H34: =VLOOKUP(A34,KSK线束BOM明细!D:N,10,0) -> 安费诺 | J34: =VLOOKUP(A34,KSK线束BOM明细!D:N,4,0) -> A03103409 | K34: =VLOOKUP(A34,KSK线束BOM明细!D:N,11,0) -> 客户指定
A35: HVPC2P1600FV-12-25P010 | B35: =VLOOKUP(A35,KSK线束BOM明细!D:N,2,0) -> 插头线束密封圈 | C35: =SUMIFS(KSK线束BOM明细!K:K,KSK线束BOM明细!D:D,A35) -> 2 | D35: =VLOOKUP(A35,KSK线束BOM明细!D:N,9,0) -> PCS | H35: =VLOOKUP(A35,KSK线束BOM明细!D:N,10,0) -> 安费诺 | J35: =VLOOKUP(A35,KSK线束BOM明细!D:N,4,0) -> A02105062 | K35: =VLOOKUP(A35,KSK线束BOM明细!D:N,11,0) -> 客户指定
A36: HVPC2P1600FV-11-25P010 | B36: =VLOOKUP(A36,KSK线束BOM明细!D:N,2,0) -> 插头线卡 | C36: =SUMIFS(KSK线束BOM明细!K:K,KSK线束BOM明细!D:D,A36) -> 2 | D36: =VLOOKUP(A36,KSK线束BOM明细!D:N,9,0) -> PCS | H36: =VLOOKUP(A36,KSK线束BOM明细!D:N,10,0) -> 安费诺 | J36: =VLOOKUP(A36,KSK线束BOM明细!D:N,4,0) -> A02105060 | K36: =VLOOKUP(A36,KSK线束BOM明细!D:N,11,0) -> 客户指定
A37: HVPC2P1600FV-10-25P010 | B37: =VLOOKUP(A37,KSK线束BOM明细!D:N,2,0) -> 插头尾盖 | C37: =SUMIFS(KSK线束BOM明细!K:K,KSK线束BOM明细!D:D,A37) -> 2 | D37: =VLOOKUP(A37,KSK线束BOM明细!D:N,9,0) -> PCS | H37: =VLOOKUP(A37,KSK线束BOM明细!D:N,10,0) -> 安费诺 | J37: =VLOOKUP(A37,KSK线束BOM明细!D:N,4,0) -> A02105061 | K37: =VLOOKUP(A37,KSK线束BOM明细!D:N,11,0) -> 客户指定
A38: 1-2177380-1 | B38: =VLOOKUP(A38,KSK线束BOM明细!D:N,2,0) -> IPT 压接端子 | C38: =SUMIFS(KSK线束BOM明细!K:K,KSK线束BOM明细!D:D,A38) -> 2 | D38: =VLOOKUP(A38,KSK线束BOM明细!D:N,9,0) -> PCS | H38: =VLOOKUP(A38,KSK线束BOM明细!D:N,10,0) -> 泰科 | J38: =VLOOKUP(A38,KSK线束BOM明细!D:N,4,0) -> A03000392 | K38: =VLOOKUP(A38,KSK线束BOM明细!D:N,11,0) -> ★
A39: IPT3P-01-06 | B39: =VLOOKUP(A39,KSK线束BOM明细!D:N,2,0) -> 特殊屏蔽件 | C39: =SUMIFS(KSK线束BOM明细!K:K,KSK线束BOM明细!D:D,A39) -> 2 | D39: =VLOOKUP(A39,KSK线束BOM明细!D:N,9,0) -> PCS | H39: =VLOOKUP(A39,KSK线束BOM明细!D:N,10,0) -> 安费诺 | J39: =VLOOKUP(A39,KSK线束BOM明细!D:N,4,0) -> A02030991 | K39: =VLOOKUP(A39,KSK线束BOM明细!D:N,11,0) -> 客户指定
... A97: 1-2310469-5 | B97: =VLOOKUP(A97,KSK线束BOM明细!D:N,2,0) -> 尾盖 | C97: =SUMIFS(KSK线束BOM明细!K:K,KSK线束BOM明细!D:D,A97) -> 1 | D97: =VLOOKUP(A97,KSK线束BOM明细!D:N,9,0) -> PCS | H97: =VLOOKUP(A97,KSK线束BOM明细!D:N,10,0) -> TE | J97: =VLOOKUP(A97,KSK线束BOM明细!D:N,4,0) -> A02033357 | K97: =VLOOKUP(A97,KSK线束BOM明细!D:N,11,0) -> 客户指定
A98: 1890945 | B98: =VLOOKUP(A98,KSK线束BOM明细!D:N,2,0) -> 护套-插头半成品 | C98: =SUMIFS(KSK线束BOM明细!K:K,KSK线束BOM明细!D:D,A98) -> 1 | D98: =VLOOKUP(A98,KSK线束BOM明细!D:N,9,0) -> PCS | H98: =VLOOKUP(A98,KSK线束BOM明细!D:N,10,0) -> 菲尼克斯 | J98: =VLOOKUP(A98,KSK线束BOM明细!D:N,4,0) -> A02105026 | K98: =VLOOKUP(A98,KSK线束BOM明细!D:N,11,0) -> 客户指定
A99: 1890948 | B99: =VLOOKUP(A99,KSK线束BOM明细!D:N,2,0) -> 焊接端子 | C99: =SUMIFS(KSK线束BOM明细!K:K,KSK线束BOM明细!D:D,A99) -> 2 | D99: =VLOOKUP(A99,KSK线束BOM明细!D:N,9,0) -> PCS | H99: =VLOOKUP(A99,KSK线束BOM明细!D:N,10,0) -> 菲尼克斯 | J99: =VLOOKUP(A99,KSK线束BOM明细!D:N,4,0) -> A03103392 | K99: =VLOOKUP(A99,KSK线束BOM明细!D:N,11,0) -> 客户指定
A100: 1806556 | B100: =VLOOKUP(A100,KSK线束BOM明细!D:N,2,0) -> 屏蔽外环 | C100: =SUMIFS(KSK线束BOM明细!K:K,KSK线束BOM明细!D:D,A100) -> 2 | D100: =VLOOKUP(A100,KSK线束BOM明细!D:N,9,0) -> PCS | H100: =VLOOKUP(A100,KSK线束BOM明细!D:N,10,0) -> 菲尼克斯 | J100: =VLOOKUP(A100,KSK线束BOM明细!D:N,4,0) -> A03103390 | K100: =VLOOKUP(A100,KSK线束BOM明细!D:N,11,0) -> 客户指定
A101: 1806554 | B101: =VLOOKUP(A101,KSK线束BOM明细!D:N,2,0) -> 4方屏蔽内环 | C101: =SUMIFS(KSK线束BOM明细!K:K,KSK线束BOM明细!D:D,A101) -> 2 | D101: =VLOOKUP(A101,KSK线束BOM明细!D:N,9,0) -> PCS | H101: =VLOOKUP(A101,KSK线束BOM明细!D:N,10,0) -> 菲尼克斯 | J101: =VLOOKUP(A101,KSK线束BOM明细!D:N,4,0) -> A03103391 | K101: =VLOOKUP(A101,KSK线束BOM明细!D:N,11,0) -> 客户指定
A102: 1806550 | B102: =VLOOKUP(A102,KSK线束BOM明细!D:N,2,0) -> 4方线束密封圈(红色) | C102: =SUMIFS(KSK线束BOM明细!K:K,KSK线束BOM明细!D:D,A102) -> 4 | D102: =VLOOKUP(A102,KSK线束BOM明细!D:N,9,0) -> PCS | H102: =VLOOKUP(A102,KSK线束BOM明细!D:N,10,0) -> 菲尼克斯 | J102: =VLOOKUP(A102,KSK线束BOM明细!D:N,4,0) -> A02105023 | K102: =VLOOKUP(A102,KSK线束BOM明细!D:N,11,0) -> 客户指定
A103: 1806425 | B103: =VLOOKUP(A103,KSK线束BOM明细!D:N,2,0) -> 4方线束尾盖(红色) | C103: =SUMIFS(KSK线束BOM明细!K:K,KSK线束BOM明细!D:D,A103) -> 4 | D103: =VLOOKUP(A103,KSK线束BOM明细!D:N,9,0) -> PCS | H103: =VLOOKUP(A103,KSK线束BOM明细!D:N,10,0) -> 菲尼克斯 | J103: =VLOOKUP(A103,KSK线束BOM明细!D:N,4,0) -> A02105024 | K103: =VLOOKUP(A103,KSK线束BOM明细!D:N,11,0) -> 客户指定
A104: 1806416 | B104: =VLOOKUP(A104,KSK线束BOM明细!D:N,2,0) -> 4方盲堵(红色) | C104: =SUMIFS(KSK线束BOM明细!K:K,KSK线束BOM明细!D:D,A104) -> 2 | D104: =VLOOKUP(A104,KSK线束BOM明细!D:N,9,0) -> PCS | H104: =VLOOKUP(A104,KSK线束BOM明细!D:N,10,0) -> 菲尼克斯 | J104: =VLOOKUP(A104,KSK线束BOM明细!D:N,4,0) -> A02105022 | K104: =VLOOKUP(A104,KSK线束BOM明细!D:N,11,0) -> 客户指定
A105: E281-HB-06 | B105: =VLOOKUP(A105,KSK线束BOM明细!D:N,2,0) -> 塑料支架（带1个衬套） | C105: =SUMIFS(KSK线束BOM明细!K:K,KSK线束BOM明细!D:D,A105) -> 1 | D105: =VLOOKUP(A105,KSK线束BOM明细!D:N,9,0) -> PCS | H105: =VLOOKUP(A105,KSK线束BOM明细!D:N,10,0) -> 上海程达 | J105: =VLOOKUP(A105,KSK线束BOM明细!D:N,4,0) -> A06102156 | K105: =VLOOKUP(A105,KSK线束BOM明细!D:N,11,0) -> ★
A106: E281-HB-10 | B106: =VLOOKUP(A106,KSK线束BOM明细!D:N,2,0) -> 塑料支架（带卡扣） | C106: =SUMIFS(KSK线束BOM明细!K:K,KSK线束BOM明细!D:D,A106) -> 1 | D106: =VLOOKUP(A106,KSK线束BOM明细!D:N,9,0) -> PCS | H106: =VLOOKUP(A106,KSK线束BOM明细!D:N,10,0) -> 上海程达 | J106: =VLOOKUP(A106,KSK线束BOM明细!D:N,4,0) -> A06102206 | K106: =VLOOKUP(A106,KSK线束BOM明细!D:N,11,0) -> ★
A107: PP9104320 | B107: =VLOOKUP(A107,KSK线束BOM明细!D:N,2,0) -> 7*12箭头扎带 | C107: =SUMIFS(KSK线束BOM明细!K:K,KSK线束BOM明细!D:D,A107) -> 11 | D107: =VLOOKUP(A107,KSK线束BOM明细!D:N,9,0) -> PCS | H107: =VLOOKUP(A107,KSK线束BOM明细!D:N,10,0) -> 上海众安 | J107: =VLOOKUP(A107,KSK线束BOM明细!D:N,4,0) -> A06101606 | K107: =VLOOKUP(A107,KSK线束BOM明细!D:N,11,0) -> ★
A108: 2519063-1 | B108: =VLOOKUP(A108,KSK线束BOM明细!D:N,2,0) -> 防尘盖组件 | C108: =SUMIFS(KSK线束BOM明细!K:K,KSK线束BOM明细!D:D,A108) -> 3 | D108: =VLOOKUP(A108,KSK线束BOM明细!D:N,9,0) -> PCS | H108: =VLOOKUP(A108,KSK线束BOM明细!D:N,10,0) -> TE | J108: =VLOOKUP(A108,KSK线束BOM明细!D:N,4,0) -> A02105132 | K108: =VLOOKUP(A108,KSK线束BOM明细!D:N,11,0) -> 客户指定
...

Sheet 配置清单
A1: 配置信息和用量 (Feature & Take Rate) | H1: E281国内项目
H2: CM010_E281_启航版_R WD_LHD_CN 标配 | I2: CM010_E281_启航版_R WD_LHD_CN 选配 | J2: CM015_E281_探索版+远航版_R WD_LHD_CN 标配 | K2: CM015_E281_探索版+远航版_R WD_LHD_CN 选配 | L2: CM030_E281_星舰版_R WD_LHD_CN 标配 | M2: CM030_E281_星舰版_R WD_LHD_CN 标配 | N2: CM030_E281_星舰版_R WD_LHD_CN 选配 | O2: 2026/2/14 63.8两驱不带PTC | P2: 2026/2/14 75.2两驱不带PTC | Q2: 2月14日汇总 | R2: 2026/3/10 75.2两驱不带PTC | S2: 2026/3/10 75.2四驱 | T2: 2026/3/10 63.8 | U2: 2026/3/10 52.4 | V2: 3月10日汇总
A3: 序号 | B3: 零件包名称 | C3: 零件号 | D3: 零件名称 | E3: 适配导线 | F3: 配置 | G3: 标配/选配 | H3: 52.4 不带PTC 2驱 标配 | I3: 52.4 带PTC 2驱 选配 | J3: 63.8 不带PTC 2驱 标配 | K3: 63.8 带PTC 2驱 选配 | L3: 75.2 不带PTC 2驱 标配 | M3: 75.2 带PTC 2驱 选配 | N3: 75.2 不带PTC 4驱 标配 | X3: 图示
A4: 1 | B4: 高压线束 | C4: 6608491523 | D4: 直流母线总成 | E4: 35mm²屏蔽硅胶铝导线（屏蔽层镀锡铜包铝） | F4: 63.8 | G4: S | J4: 1 | K4: 1 | O4: =J4*16 -> 16 | Q4: =O4+P4 -> 16 | T4: 3 | V4: =R4+S4+T4+U4 -> 3 | W4: =Q4+V4 -> 19
A5: 2 | B5: 高压线束 | C5: 6608491524 | D5: 直流母线总成 | E5: 35mm²屏蔽硅胶铝导线（屏蔽层镀锡铜包铝） | F5: 75.2 | G5: S | L5: 1 | M5: 1 | N5: 1 | P5: =L5*6 -> 6 | Q5: =O5+P5 -> 6 | R5: 2 | S5: 3 | V5: =R5+S5+T5+U5 -> 5 | W5: =Q5+V5 -> 11
A6: 3 | B6: 高压线束 | C6: 6608442962 | D6: 直流母线总成 | E6: 35mm²屏蔽硅胶铝导线（屏蔽层镀锡铜包铝） | F6: 52.4 | G6: S | H6: 1 | I6: 1 | Q6: =O6+P6 -> 0 | U6: 4 | V6: =R6+S6+T6+U6 -> 4 | W6: =Q6+V6 -> 4
A7: 4 | B7: 高压线束 | C7: 6608442964 | D7: 电动压缩机线束总成 | E7: 4.0mm²屏蔽镀锡铜包铝交联铝导线 | F7: 52.4/63.8/75.2不带PTC | G7: S | H7: 1 | J7: 1 | L7: 1 | O7: =J7*16 -> 16 | P7: =L7*6 -> 6 | Q7: =O7+P7 -> 22 | R7: 2 | T7: 3 | U7: 4 | V7: =R7+S7+T7+U7 -> 9 | W7: =Q7+V7 -> 31
A8: 5 | B8: 高压线束 | C8: 6608442963 | D8: 电动压缩机线束总成 | E8: 4.0mm²屏蔽镀锡铜包铝交联铝导线 | F8: 52.4带PTC | G8: O | I8: 1 | Q8: =O8+P8 -> 0 | V8: =R8+S8+T8+U8 -> 0
A9: 6 | B9: 高压线束 | C9: 6608516992 | D9: 电动压缩机线束总成 | E9: 4.0mm²屏蔽镀锡铜包铝交联铝导线 | F9: 63.8/75.2带PTC | G9: O | K9: 1 | M9: 1 | Q9: =O9+P9 -> 0 | V9: =R9+S9+T9+U9 -> 0
A10: 7 | B10: 高压线束 | C10: 6608519100 | D10: 电动压缩机线束总成 | E10: 4.0mm²屏蔽镀锡铜包铝交联铝导线 | F10: 75.2四驱 | G10: S | N10: 1 | Q10: =O10+P10 -> 0 | S10: 3 | V10: =R10+S10+T10+U10 -> 3 | W10: =Q10+V10 -> 3
A11: 8 | B11: 高压线束 | C11: 6608442966 | D11: 组合式充电插座线束总成 | E11: 120mm²非屏蔽硅胶铝导线 6mm²非屏蔽铝导线 6mm²非屏蔽黄绿铜导线 5mm²非屏蔽黄绿铜导线 | F11: 63.8 | G11: S | J11: 1 | K11: 1 | O11: =J11*16 -> 16 | Q11: =O11+P11 -> 16 | T11: 3 | V11: =R11+S11+T11+U11 -> 3 | W11: =Q11+V11 -> 19
A12: 9 | B12: 高压线束 | C12: 6608442965 | D12: 组合式充电插座线束总成 | E12: 120mm²非屏蔽硅胶铝导线 6mm²非屏蔽铝导线 6mm²非屏蔽黄绿铜导线 5mm²非屏蔽黄绿铜导线 | F12: 75.2 | G12: S | L12: 1 | M12: 1 | N12: 1 | P12: =L12*6 -> 6 | Q12: =O12+P12 -> 6 | R12: 2 | S12: 3 | V12: =R12+S12+T12+U12 -> 5 | W12: =Q12+V12 -> 11
A13: 10 | B13: 高压线束 | C13: 6608507680 | D13: 组合式充电插座线束总成 | E13: 120mm²非屏蔽硅胶铝导线 6mm²非屏蔽铝导线 6mm²非屏蔽黄绿铜导线 5mm²非屏蔽黄绿铜导线 | F13: 52.4 | G13: S | H13: 1 | I13: 1 | Q13: =O13+P13 -> 0 | U13: 4 | V13: =R13+S13+T13+U13 -> 4 | W13: =Q13+V13 -> 4
A14: 11 | B14: 高压线束 | C14: 6608544875 | D14: 前驱直流母线总成 | E14: 25mm²屏蔽硅胶铜导线（屏蔽层镀锡铜包铝） | F14: 75.2 | G14: S | N14: 1 | Q14: =O14+P14 -> 0 | S14: 3 | V14: =R14+S14+T14+U14 -> 3 | W14: =Q14+V14 -> 3

Sheet 总成散件清单
A1: NO. | B1: Function 功能 | C1: Part Number 零件号 | D1: Part Name 零件名称 | E1: Semi-Finished 是否半成品 | F1: Wire NO. 回路号 | G1: PIN | H1: OPTION | I1: SPEC 规格 | J1: Quantity 数量 | K1: Unit 单位 | L1: Remark | M1: 其他备注 | P1: 备注差异原因 | R1: 确认C列与O列物料型号是否一致 | Y1: 确认J列与U列用量是否一致
A2: 1 | B2: HVPC2P1600FT535-NH-P010 接电池端 适配2*35mm²屏蔽铜包铝硅胶铝导线 | C2: HVPC2P1600FT5-NH-MP010 | D2: 护套（145度反装 A键位） | E2: N | F2: A02105032 | J2: 1 | K2: PCS | L2: 安费诺 | M2: 客户指定 | N2: HVPC2P1600FT535-NH-P010 接电池端 适配2*35mm²屏蔽铜包铝硅胶铝导线 | O2: HVPC2P1600FT5-NH-MP010 | Q2: 护套（145度反装 A键位） | R2: =IF(C2=O2,1,0) -> 1 | S2: N | T2: A02105032 | U2: 1 | V2: PCS | W2: 安费诺 | X2: 客户指定 | Y2: =IF(J2=U2,1,0) -> 1
A3: 2 | C3: HVPC2P1600FT-09P010 | D3: 插头端子-单粒焊接 | E3: N | F3: A03103389 | J3: 2 | K3: PCS | L3: 安费诺 | M3: 客户指定 | O3: HVPC2P1600FT-09P010 | Q3: 插头端子-单粒焊接 | R3: =IF(C3=O3,1,0) -> 1 | S3: N | T3: A03103389 | U3: 2 | V3: PCS | W3: 安费诺 | X3: 客户指定 | Y3: =IF(J3=U3,1,0) -> 1
A4: 3 | C4: HVPC2P1600FV-15P010 | D4: 挡板_黑色 | E4: N | F4: A02104375 | J4: 2 | K4: PCS | L4: 安费诺 | M4: 客户指定 | O4: HVPC2P1600FV-15P010 | Q4: 挡板 | R4: =IF(C4=O4,1,0) -> 1 | S4: N | T4: A02104375 | U4: 2 | V4: PCS | W4: 安费诺 | X4: 客户指定 | Y4: =IF(J4=U4,1,0) -> 1
A5: 4 | C5: HVPC2P1600FV-06-35P010 | D5: 插头外屏蔽环 | E5: N | F5: A03103387 | J5: 2 | K5: PCS | L5: 安费诺 | M5: 客户指定 | O5: HVPC2P1600FV-06-35P010 | Q5: 插头外屏蔽环 | R5: =IF(C5=O5,1,0) -> 1 | S5: N | T5: A03103387 | U5: 2 | V5: PCS | W5: 安费诺 | X5: 客户指定 | Y5: =IF(J5=U5,1,0) -> 1
A6: 5 | C6: HVC2P80FS1-47P010 | D6: 插头屏蔽内环 | E6: N | F6: A03103388 | J6: 2 | K6: PCS | L6: 安费诺 | M6: 客户指定 | O6: HVC2P80FS1-47P010 | Q6: 插头屏蔽内环 | R6: =IF(C6=O6,1,0) -> 1 | S6: N | T6: A03103388 | U6: 2 | V6: PCS | W6: 安费诺 | X6: 客户指定 | Y6: =IF(J6=U6,1,0) -> 1
A7: 6 | C7: HVPC2P1600FV-12-35P010 | D7: 插头线束密封圈 | E7: N | F7: A02105020 | J7: 2 | K7: PCS | L7: 安费诺 | M7: 客户指定 | O7: HVPC2P1600FV-12-35P010 | Q7: 插头线束密封圈 | R7: =IF(C7=O7,1,0) -> 1 | S7: N | T7: A02105020 | U7: 2 | V7: PCS | W7: 安费诺 | X7: 客户指定 | Y7: =IF(J7=U7,1,0) -> 1
A8: 7 | C8: HVPC2P1600FV-11-35P010 | D8: 插头线卡 | E8: N | F8: A02105018 | J8: 2 | K8: PCS | L8: 安费诺 | M8: 客户指定 | O8: HVPC2P1600FV-11-35P010 | Q8: 插头线卡 | R8: =IF(C8=O8,1,0) -> 1 | S8: N | T8: A02105018 | U8: 2 | V8: PCS | W8: 安费诺 | X8: 客户指定 | Y8: =IF(J8=U8,1,0) -> 1
A9: 8 | C9: HVPC2P1600FV-10-35P010 | D9: 插头尾盖 | E9: N | F9: A02105019 | J9: 2 | K9: PCS | L9: 安费诺 | M9: 客户指定 | O9: HVPC2P1600FV-10-35P010 | Q9: 插头尾盖 | R9: =IF(C9=O9,1,0) -> 1 | S9: N | T9: A02105019 | U9: 2 | V9: PCS | W9: 安费诺 | X9: 客户指定 | Y9: =IF(J9=U9,1,0) -> 1
A10: 9 | B10: IPT2PFS035-S02P010（安费诺） 接电驱端 适配2*35mm²屏蔽铜包铝硅胶铝导线 | C10: N022525276C | D10: 焊接端子-70 | E10: N | F10: A03103440 | J10: 2 | K10: PCS | L10: 安费诺 | M10: 客户指定 | N10: IPT2PFS035-S02P010（安费诺） 接电驱端 适配2*35mm²屏蔽铜包铝硅胶铝导线 | O10: N022525276C | Q10: 焊接端子-70 | R10: =IF(C10=O10,1,0) -> 1 | S10: N | T10: / | U10: 2 | V10: PCS | W10: 安费诺 | X10: 客户指定 | Y10: =IF(J10=U10,1,0) -> 1
A11: 10 | C11: IPT2PFS035-GA-01P010 | D11: 主体组合件 | E11: N | F11: A02102660 | J11: 1 | K11: PCS | L11: 安费诺 | M11: 客户指定 | O11: IPT2PFS035-GA-01P010 | Q11: 主体组合件 | R11: =IF(C11=O11,1,0) -> 1 | S11: N | T11: A02102660 | U11: 1 | V11: PCS | W11: 安费诺 | X11: 客户指定 | Y11: =IF(J11=U11,1,0) -> 1
A12: 11 | C12: IPT2PFS-S01-35P010 | D12: 压接屏蔽内环-35 | E12: N | F12: A03101954 | J12: 2 | K12: PCS | L12: 安费诺 | M12: 客户指定 | O12: IPT2PFS-S01-35P010 | Q12: 压接屏蔽内环-35 | R12: =IF(C12=O12,1,0) -> 1 | S12: N | T12: A03101954 | U12: 2 | V12: PCS | W12: 安费诺 | X12: 客户指定 | Y12: =IF(J12=U12,1,0) -> 1
A13: 12 | C13: IPT2PFS-S02-35P010 | D13: 压接屏蔽外环-35/50 | E13: N | F13: A03101953 | J13: 2 | K13: PCS | L13: 安费诺 | M13: 客户指定 | O13: IPT2PFS-S02-35P010 | Q13: 压接屏蔽外环-35/50 | R13: =IF(C13=O13,1,0) -> 1 | S13: N | T13: A03101953 | U13: 2 | V13: PCS | W13: 安费诺 | X13: 客户指定 | Y13: =IF(J13=U13,1,0) -> 1
A14: 13 | C14: IPT2PFS-M04-35P010 | D14: 屏蔽固定件-16/25/35 | E14: N | F14: A02102662 | J14: 4 | K14: PCS | L14: 安费诺 | M14: 客户指定 | O14: IPT2PFS-MO4-35P010 | P14: 相同物料，建SAP号时物料更正 物料型号MO4和M04的差异 | Q14: 屏蔽固定件-16/25/35 | R14: =IF(C14=O14,1,0) -> 0 | S14: N | T14: / | U14: 4 | V14: PCS | W14: 安费诺 | X14: 客户指定 | Y14: =IF(J14=U14,1,0) -> 1
A15: 14 | C15: IPT2PFS-R02-35P010 | D15: 密封圈-35 | E15: N | F15: A02102663 | J15: 2 | K15: PCS | L15: 安费诺 | M15: 客户指定 | O15: IPT2PFS-R02-35P010 | Q15: 密封圈-35 | R15: =IF(C15=O15,1,0) -> 1 | S15: N | T15: A02102663 | U15: 2 | V15: PCS | W15: 安费诺 | X15: 客户指定 | Y15: =IF(J15=U15,1,0) -> 1
A16: 15 | C16: IPT2PFS-M05-35P010 | D16: 尾盖-35 | E16: N | F16: A02105144 | J16: 2 | K16: PCS | L16: 安费诺 | M16: 客户指定 | O16: IPT2PFS-M05-35P010 | Q16: 尾盖-35 | R16: =IF(C16=O16,1,0) -> 1 | S16: N | T16: / | U16: 2 | V16: PCS | W16: 安费诺 | X16: 客户指定 | Y16: =IF(J16=U16,1,0) -> 1
A17: 16 | B17: HVPC2P1600FV535-NH-P010 接电池端 适配2*35mm²屏蔽铜包铝硅胶铝导线 | C17: HVPC2P1600FV5-NH-M-P010 | D17: 护套-90度-反装-CODE A | E17: N | F17: A02105143 | J17: 1 | K17: PCS | L17: 安费诺 | M17: 客户指定 | N17: HVPC2P1600FV535-NH-P010 接电池端 适配2*35mm²屏蔽铜包铝硅胶铝导线 | O17: HVPC2P1600FV5-NH-M-P010 | Q17: 护套-90度-反装-CODE A | R17: =IF(C17=O17,1,0) -> 1 | S17: N | T17: / | U17: 1 | V17: PCS | W17: 安费诺 | X17: 客户指定 | Y17: =IF(J17=U17,1,0) -> 1
A18: 17 | C18: HVPC2P1600FV-09-P010 | D18: 焊接端子-镀银 | E18: N | F18: A03103438 | J18: 2 | K18: PCS | L18: 安费诺 | M18: 客户指定 | O18: HVPC2P1600FV-09-P010 | Q18: 焊接端子-镀银 | R18: =IF(C18=O18,1,0) -> 1 | S18: N | T18: / | U18: 2 | V18: PCS | W18: 安费诺 | X18: 客户指定 | Y18: =IF(J18=U18,1,0) -> 1
A19: 18 | C19: HVPC2P1600FV-15P010 | D19: 挡板_黑色 | E19: N | F19: A02104375 | J19: 2 | K19: PCS | L19: 安费诺 | M19: 客户指定 | O19: HVPC2P1600FV-15-P010 | P19: 安费诺提供的两款连接器规格书中挡板使用的物料型号不同，因系统内内部物料统一使用不带-的料号 | Q19: 挡板_黑色 | R19: =IF(C19=O19,1,0) -> 0 | S19: N | T19: / | U19: 2 | V19: PCS | W19: 安费诺 | X19: 客户指定 | Y19: =IF(J19=U19,1,0) -> 1
A20: 19 | C20: HVPC2P1600FV-06-35P010 | D20: 插头外屏蔽环 | E20: N | F20: A03103387 | J20: 2 | K20: PCS | L20: 安费诺 | M20: 客户指定 | O20: HVPC2P1600FV-06-35-P010 | P20: 安费诺提供的两款连接器规格书中屏蔽环使用的物料型号不同，内部物料统一使用不带-的料号 | Q20: 外屏蔽环 | R20: =IF(C20=O20,1,0) -> 0 | S20: N | T20: / | U20: 2 | V20: PCS | W20: 安费诺 | X20: 客户指定 | Y20: =IF(J20=U20,1,0) -> 1
A21: 20 | C21: HVPC2P1800FS-11-25G-P010 | D21: 内屏蔽环 | E21: N | F21: A03103437 | J21: 2 | K21: PCS | L21: 安费诺 | M21: 客户指定 | O21: HVPC2P1800FS-11-25G-P010 | Q21: 内屏蔽环 | R21: =IF(C21=O21,1,0) -> 1 | S21: N | T21: / | U21: 2 | V21: PCS | W21: 安费诺 | X21: 客户指定 | Y21: =IF(J21=U21,1,0) -> 1
A22: 21 | C22: HVPC2P1600FV-12-35P010 | D22: 密封圈-黑色 | E22: N | F22: A02105020 | J22: 2 | K22: PCS | L22: 安费诺 | M22: 客户指定 | O22: HVPC2P1600FV-12-35-P010 | P22: 安费诺提供的两款连接器规格书中屏蔽环使用的物料型号不同，内部物料统一使用不带-的料号 | Q22: 密封圈-黑色 | R22: =IF(C22=O22,1,0) -> 0 | S22: N | T22: / | U22: 2 | V22: PCS | W22: 安费诺 | X22: 客户指定 | Y22: =IF(J22=U22,1,0) -> 1
A23: 22 | C23: HVPC2P1600FV-11-35P010 | D23: 线卡-黑色 | E23: N | F23: A02105018 | J23: 2 | K23: PCS | L23: 安费诺 | M23: 客户指定 | O23: HVPC2P1600FV-11-35-P010 | P23: 安费诺提供的两款连接器规格书中屏蔽环使用的物料型号不同，内部物料统一使用不带-的料号 | Q23: 线卡-黑色 | R23: =IF(C23=O23,1,0) -> 0 | S23: N | T23: / | U23: 2 | V23: PCS | W23: 安费诺 | X23: 客户指定 | Y23: =IF(J23=U23,1,0) -> 1
A24: 23 | C24: HVPC2P1600FV-10-35P010 | D24: 尾盖-橙色 | E24: N | F24: A02105019 | J24: 2 | K24: PCS | L24: 安费诺 | M24: 客户指定 | O24: HVPC2P1600FV-10-35-P010 | P24: 安费诺提供的两款连接器规格书中屏蔽环使用的物料型号不同，内部物料统一使用不带-的料号 | Q24: 尾盖-橙色 | R24: =IF(C24=O24,1,0) -> 0 | S24: N | T24: / | U24: 2 | V24: PCS | W24: 安费诺 | X24: 客户指定 | Y24: =IF(J24=U24,1,0) -> 1
A25: 24 | B25: HVPC2P1600FT525-NH-P010 接电池端 适配2*25mm²屏蔽铜包铝硅胶铜导线 | C25: HVPC2P1600FT5-NH-MP010 | D25: 护套（145度反装 A键位） | E25: N | F25: A02105032 | J25: 1 | K25: PCS | L25: 安费诺 | M25: 客户指定 | N25: HVPC2P1600FT525-NH-P010 接电池端 适配2*25mm²屏蔽铜包铝硅胶铜导线 | O25: HVPC2P1600FT5-NH-MP010 | Q25: 护套（145度反装 A键位） | R25: =IF(C25=O25,1,0) -> 1 | S25: N | T25: A02105032 | U25: 1 | V25: PCS | W25: 安费诺 | X25: 客户指定 | Y25: =IF(J25=U25,1,0) -> 1
A26: 25 | C26: HVPC2P1600FT-09P010 | D26: 插头端子-单粒焊接 | E26: N | F26: A03103389 | J26: 2 | K26: PCS | L26: 安费诺 | M26: 客户指定 | O26: HVPC2P1600FT-09P010 | Q26: 插头端子-单粒焊接 | R26: =IF(C26=O26,1,0) -> 1 | S26: N | T26: A03103389 | U26: 2 | V26: PCS | W26: 安费诺 | X26: 客户指定 | Y26: =IF(J26=U26,1,0) -> 1
A27: 26 | C27: HVPC2P1600FV-15P010 | D27: 挡板_黑色 | E27: N | F27: A02104375 | J27: 2 | K27: PCS | L27: 安费诺 | M27: 客户指定 | O27: HVPC2P1600FV-15P010 | Q27: 挡板 | R27: =IF(C27=O27,1,0) -> 1 | S27: N | T27: A02104375 | U27: 2 | V27: PCS | W27: 安费诺 | X27: 客户指定 | Y27: =IF(J27=U27,1,0) -> 1
A28: 27 | C28: HVPC2P1600FV-06-25P010 | D28: 插头外屏蔽环 | E28: N | F28: A03103410 | J28: 2 | K28: PCS | L28: 安费诺 | M28: 客户指定 | O28: HVPC2P1600FV-06-25P010 | Q28: 插头外屏蔽环 | R28: =IF(C28=O28,1,0) -> 1 | S28: N | T28: / | U28: 2 | V28: PCS | W28: 安费诺 | X28: 客户指定 | Y28: =IF(J28=U28,1,0) -> 1
A29: 28 | C29: HVPC2P1800FS-11-25P010 | D29: 插头屏蔽内环 | E29: N | F29: A03103409 | J29: 2 | K29: PCS | L29: 安费诺 | M29: 客户指定 | O29: HVPC2P1800FS-11-25P010 | Q29: 插头屏蔽内环 | R29: =IF(C29=O29,1,0) -> 1 | S29: N | T29: / | U29: 2 | V29: PCS | W29: 安费诺 | X29: 客户指定 | Y29: =IF(J29=U29,1,0) -> 1
A30: 29 | C30: HVPC2P1600FV-12-25P010 | D30: 插头线束密封圈 | E30: N | F30: A02105062 | J30: 2 | K30: PCS | L30: 安费诺 | M30: 客户指定 | O30: HVPC2P1600FV-12-25P010 | Q30: 插头线束密封圈 | R30: =IF(C30=O30,1,0) -> 1 | S30: N | T30: / | U30: 2 | V30: PCS | W30: 安费诺 | X30: 客户指定 | Y30: =IF(J30=U30,1,0) -> 1
A31: 30 | C31: HVPC2P1600FV-11-25P010 | D31: 插头线卡 | E31: N | F31: A02105060 | J31: 2 | K31: PCS | L31: 安费诺 | M31: 客户指定 | O31: HVPC2P1600FV-11-25P010 | Q31: 插头线卡 | R31: =IF(C31=O31,1,0) -> 1 | S31: N | T31: / | U31: 2 | V31: PCS | W31: 安费诺 | X31: 客户指定 | Y31: =IF(J31=U31,1,0) -> 1
A32: 31 | C32: HVPC2P1600FV-10-25P010 | D32: 插头尾盖 | E32: N | F32: A02105061 | J32: 2 | K32: PCS | L32: 安费诺 | M32: 客户指定 | O32: HVPC2P1600FV-10-25P010 | Q32: 插头尾盖 | R32: =IF(C32=O32,1,0) -> 1 | S32: N | T32: / | U32: 2 | V32: PCS | W32: 安费诺 | X32: 客户指定 | Y32: =IF(J32=U32,1,0) -> 1
A33: 32 | B33: IPT 压接端子 | C33: 1-2177380-1 | D33: IPT 压接端子 | E33: N | F33: A03000392 | J33: 2 | K33: PCS | L33: 泰科 | M33: ★ | N33: IPT 压接端子 | O33: 1-2177380-1 | Q33: IPT 压接端子 | R33: =IF(C33=O33,1,0) -> 1 | S33: N | T33: A03000392 | U33: 2 | V33: PCS | W33: TE | X33: ★ | Y33: =IF(J33=U33,1,0) -> 1
A34: 33 | B34: IPT2P25P001-P010（安费诺 不含端子） 接电驱端 适配2*25mm²屏蔽铜包铝硅胶铜导线 | C34: IPT3P-01-06 | D34: 特殊屏蔽件 | E34: N | F34: A02030991 | J34: 2 | K34: PCS | L34: 安费诺 | M34: 客户指定 | N34: IPT2P25P001-P010（安费诺 不含端子） 接电驱端 适配2*25mm²屏蔽铜包铝硅胶铜导线 | O34: IPT3P-01-06 | Q34: 特殊屏蔽件 | R34: =IF(C34=O34,1,0) -> 1 | S34: N | T34: A02030991 | U34: 2 | V34: PCS | W34: 安费诺 | X34: 客户指定 | Y34: =IF(J34=U34,1,0) -> 1
A35: 34 | C35: IPT3P-01-19 | D35: 25mm2 屏蔽外环 | E35: N | F35: A03103408 | J35: 2 | K35: PCS | L35: 安费诺 | M35: 客户指定 | O35: IPT3P-01-19 | Q35: 25mm2 屏蔽外环 | R35: =IF(C35=O35,1,0) -> 1 | S35: N | T35: / | U35: 2 | V35: PCS | W35: 安费诺 | X35: 客户指定 | Y35: =IF(J35=U35,1,0) -> 1
A36: 35 | C36: IPT3P-01-20 | D36: 25mm2 屏蔽内环 | E36: N | F36: A03103407 | J36: 2 | K36: PCS | L36: 安费诺 | M36: 客户指定 | O36: IPT3P-01-20 | Q36: 25mm2 屏蔽内环 | R36: =IF(C36=O36,1,0) -> 1 | S36: N | T36: / | U36: 2 | V36: PCS | W36: 安费诺 | X36: 客户指定 | Y36: =IF(J36=U36,1,0) -> 1
A37: 36 | C37: IPT3P-01-21 | D37: 护套密封圈 | E37: N | F37: A02030990 | J37: 2 | K37: PCS | L37: 安费诺 | M37: 客户指定 | O37: IPT3P-01-21 | Q37: 护套密封圈 | R37: =IF(C37=O37,1,0) -> 1 | S37: N | T37: A02030990 | U37: 2 | V37: PCS | W37: 安费诺 | X37: 客户指定 | Y37: =IF(J37=U37,1,0) -> 1
A38: 37 | C38: IPT2PP-01-01 | D38: 护套主体 | E38: N | F38: A02031898 | J38: 1 | K38: PCS | L38: 安费诺 | M38: 客户指定 | O38: IPT2PP-01-01 | Q38: 护套主体 | R38: =IF(C38=O38,1,0) -> 1 | S38: N | T38: A02031898 | U38: 1 | V38: PCS | W38: 安费诺 | X38: 客户指定 | Y38: =IF(J38=U38,1,0) -> 1
A39: 38 | C39: IPT3P-01-18 | D39: 25mm2 线密封圈 | E39: N | F39: A02105058 | J39: 2 | K39: PCS | L39: 安费诺 | M39: 客户指定 | O39: IPT3P-01-18 | Q39: 25mm2 线密封圈 | R39: =IF(C39=O39,1,0) -> 1 | S39: N | T39: / | U39: 2 | V39: PCS | W39: 安费诺 | X39: 客户指定 | Y39: =IF(J39=U39,1,0) -> 1
A40: 39 | C40: IPT3P-01-16 | D40: 25mm2 尾盖 | E40: N | F40: A02105059 | J40: 2 | K40: PCS | L40: 安费诺 | M40: 客户指定 | O40: IPT3P-01-16 | Q40: 25mm2 尾盖 | R40: =IF(C40=O40,1,0) -> 1 | S40: N | T40: / | U40: 2 | V40: PCS | W40: 安费诺 | X40: 客户指定 | Y40: =IF(J40=U40,1,0) -> 1
...

Sheet KSK线束BOM明细
A1: 线束零件号 | B1: 零件名称 | C1: 总成号 | D1: 零件号 | E1: 物料名称/零件名称 | F1: 是否半成品 | G1: 物料型号/SAP | J1: 回路 | K1: 数量 | L1: 单位 | M1: 供应商 | N1: 其他备注
A2: 6608491523 | B2: 直流母线总成 | C2: HVPC2P1600FT535-NH-P010 接电池端 适配2*35mm²屏蔽铜包铝硅胶铝导线 | D2: HVPC2P1600FT5-NH-MP010 | E2: 护套（145度反装 A键位） | F2: N | G2: A02105032 | K2: 1 | L2: PCS | M2: 安费诺 | N2: 客户指定
A3: 6608491523 | B3: 直流母线总成 | D3: HVPC2P1600FT-09P010 | E3: 插头端子-单粒焊接 | F3: N | G3: A03103389 | K3: 2 | L3: PCS | M3: 安费诺 | N3: 客户指定
A4: 6608491523 | B4: 直流母线总成 | D4: HVPC2P1600FV-15P010 | E4: 挡板_黑色 | F4: N | G4: A02104375 | K4: 2 | L4: PCS | M4: 安费诺 | N4: 客户指定
A5: 6608491523 | B5: 直流母线总成 | D5: HVPC2P1600FV-06-35P010 | E5: 插头外屏蔽环 | F5: N | G5: A03103387 | K5: 2 | L5: PCS | M5: 安费诺 | N5: 客户指定
A6: 6608491523 | B6: 直流母线总成 | D6: HVC2P80FS1-47P010 | E6: 插头屏蔽内环 | F6: N | G6: A03103388 | K6: 2 | L6: PCS | M6: 安费诺 | N6: 客户指定
A7: 6608491523 | B7: 直流母线总成 | D7: HVPC2P1600FV-12-35P010 | E7: 插头线束密封圈 | F7: N | G7: A02105020 | K7: 2 | L7: PCS | M7: 安费诺 | N7: 客户指定
A8: 6608491523 | B8: 直流母线总成 | D8: HVPC2P1600FV-11-35P010 | E8: 插头线卡 | F8: N | G8: A02105018 | K8: 2 | L8: PCS | M8: 安费诺 | N8: 客户指定
A9: 6608491523 | B9: 直流母线总成 | D9: HVPC2P1600FV-10-35P010 | E9: 插头尾盖 | F9: N | G9: A02105019 | K9: 2 | L9: PCS | M9: 安费诺 | N9: 客户指定
A10: 6608491523 | B10: 直流母线总成 | C10: IPT2PFS035-S02P010（安费诺） 接电驱端 适配2*35mm²屏蔽铜包铝硅胶铝导线 | D10: N022525276C | E10: 焊接端子-70 | F10: N | G10: A03103440 | K10: 2 | L10: PCS | M10: 安费诺 | N10: 客户指定
A11: 6608491523 | B11: 直流母线总成 | D11: IPT2PFS035-GA-01P010 | E11: 主体组合件 | F11: N | G11: A02102660 | K11: 1 | L11: PCS | M11: 安费诺 | N11: 客户指定
A12: 6608491523 | B12: 直流母线总成 | D12: IPT2PFS-S01-35P010 | E12: 压接屏蔽内环-35 | F12: N | G12: A03101954 | K12: 2 | L12: PCS | M12: 安费诺 | N12: 客户指定
A13: 6608491523 | B13: 直流母线总成 | D13: IPT2PFS-S02-35P010 | E13: 压接屏蔽外环-35/50 | F13: N | G13: A03101953 | K13: 2 | L13: PCS | M13: 安费诺 | N13: 客户指定
A14: 6608491523 | B14: 直流母线总成 | D14: IPT2PFS-M04-35P010 | E14: 屏蔽固定件-16/25/35 | F14: N | G14: A02102662 | K14: 4 | L14: PCS | M14: 安费诺 | N14: 客户指定
A15: 6608491523 | B15: 直流母线总成 | D15: IPT2PFS-R02-35P010 | E15: 密封圈-35 | F15: N | G15: A02102663 | K15: 2 | L15: PCS | M15: 安费诺 | N15: 客户指定
A16: 6608491523 | B16: 直流母线总成 | D16: IPT2PFS-M05-35P010 | E16: 尾盖-35 | F16: N | G16: A02105144 | K16: 2 | L16: PCS | M16: 安费诺 | N16: 客户指定
A17: 6608491523 | B17: 直流母线总成 | D17: HS-125(3X) 18-30 | E17: 不带胶-热缩管 | F17: N | G17: A04102622 | K17: 2 | L17: PCS | M17: 长春海达 | N17: ★
A18: 6608491523 | B18: 直流母线总成 | D18: FHLALR2GCCAATB2G/35.0/橙 | E18: 35mm²屏蔽镀锡铜包铝硅胶铝导线 | F18: N | G18: A01103420 | K18: 1.59 | L18: M | M18: 太平洋 | N18: ★
A19: 6608491523 | B19: 直流母线总成 | D19: SCS2165A016 | E19: 16OR橙色编织套管 | F19: N | G19: A04101476 | K19: 1.15 | L19: M | M19: 骏鼎达 | N19: ★
A20: 6608491523 | B20: 直流母线总成 | D20: LY5016019-OR2 | E20: 橙色布基胶带 | F20: N | G20: A04101159 | K20: 4.6 | L20: M | M20: 联益 | N20: ★
A21: 6608491523 | B21: 直流母线总成 | D21: E281-HB-04 | E21: 塑料支架（带2个衬套） | F21: N | G21: A06102155 | K21: 1 | L21: PCS | M21: 上海程达 | N21: ★
A22: 6608491523 | B22: 直流母线总成 | D22: E281-ZJ-06 | E22: 金属支架 | F22: N | G22: A06102146 | K22: 1 | L22: PCS | M22: 华凯 | N22: ★
... A25: 6608491523 | B25: 直流母线总成 | D25: 111-00563 | E25: 扎带绳 | F25: N | G25: A06010012 | K25: 6 | L25: PCS | M25: 海尔曼太通 | N25: ★
A26: 6608491523 | B26: 直流母线总成 | D26: X1-BQ-01 标签140x30mm | E26: 产品标签 | F26: N | G26: 70002326 | K26: 1 | L26: PCS | M26: 洪众
A27: 6608491524 | B27: 直流母线总成 | C27: HVPC2P1600FV535-NH-P010 接电池端 适配2*35mm²屏蔽铜包铝硅胶铝导线 | D27: HVPC2P1600FV5-NH-M-P010 | E27: 护套-90度-反装-CODE A | F27: N | G27: A02105143 | K27: 1 | L27: PCS | M27: 安费诺 | N27: 客户指定
A28: 6608491524 | B28: 直流母线总成 | D28: HVPC2P1600FV-09-P010 | E28: 焊接端子-镀银 | F28: N | G28: A03103438 | K28: 2 | L28: PCS | M28: 安费诺 | N28: 客户指定
A29: 6608491524 | B29: 直流母线总成 | D29: HVPC2P1600FV-15P010 | E29: 挡板_黑色 | F29: N | G29: A02104375 | K29: 2 | L29: PCS | M29: 安费诺 | N29: 客户指定
A30: 6608491524 | B30: 直流母线总成 | D30: HVPC2P1600FV-06-35P010 | E30: 插头外屏蔽环 | F30: N | G30: A03103387 | K30: 2 | L30: PCS | M30: 安费诺 | N30: 客户指定
A31: 6608491524 | B31: 直流母线总成 | D31: HVPC2P1800FS-11-25G-P010 | E31: 内屏蔽环 | F31: N | G31: A03103437 | K31: 2 | L31: PCS | M31: 安费诺 | N31: 客户指定
A32: 6608491524 | B32: 直流母线总成 | D32: HVPC2P1600FV-12-35P010 | E32: 密封圈-黑色 | F32: N | G32: A02105020 | K32: 2 | L32: PCS | M32: 安费诺 | N32: 客户指定
A33: 6608491524 | B33: 直流母线总成 | D33: HVPC2P1600FV-11-35P010 | E33: 线卡-黑色 | F33: N | G33: A02105018 | K33: 2 | L33: PCS | M33: 安费诺 | N33: 客户指定
A34: 6608491524 | B34: 直流母线总成 | D34: HVPC2P1600FV-10-35P010 | E34: 尾盖-橙色 | F34: N | G34: A02105019 | K34: 2 | L34: PCS | M34: 安费诺 | N34: 客户指定
A35: 6608491524 | B35: 直流母线总成 | C35: IPT2PFS035-S02P010（安费诺） 接电驱端 适配2*35mm²屏蔽铜包铝硅胶铝导线 | D35: N022525276C | E35: 焊接端子-70 | F35: N | G35: A03103440 | K35: 2 | L35: PCS | M35: 安费诺 | N35: 客户指定
A36: 6608491524 | B36: 直流母线总成 | D36: IPT2PFS035-GA-01P010 | E36: 主体组合件 | F36: N | G36: A02102660 | K36: 1 | L36: PCS | M36: 安费诺 | N36: 客户指定
A37: 6608491524 | B37: 直流母线总成 | D37: IPT2PFS-S01-35P010 | E37: 压接屏蔽内环-35 | F37: N | G37: A03101954 | K37: 2 | L37: PCS | M37: 安费诺 | N37: 客户指定
A38: 6608491524 | B38: 直流母线总成 | D38: IPT2PFS-S02-35P010 | E38: 压接屏蔽外环-35/50 | F38: N | G38: A03101953 | K38: 2 | L38: PCS | M38: 安费诺 | N38: 客户指定
A39: 6608491524 | B39: 直流母线总成 | D39: IPT2PFS-M04-35P010 | E39: 屏蔽固定件-16/25/35 | F39: N | G39: A02102662 | K39: 4 | L39: PCS | M39: 安费诺 | N39: 客户指定
A40: 6608491524 | B40: 直流母线总成 | D40: IPT2PFS-R02-35P010 | E40: 密封圈-35 | F40: N | G40: A02102663 | K40: 2 | L40: PCS | M40: 安费诺 | N40: 客户指定
A41: 6608491524 | B41: 直流母线总成 | D41: IPT2PFS-M05-35P010 | E41: 尾盖-35 | F41: N | G41: A02105144 | K41: 2 | L41: PCS | M41: 安费诺 | N41: 客户指定
A42: 6608491524 | B42: 直流母线总成 | D42: HS-125(3X) 18-30 | E42: 不带胶-热缩管 | F42: N | G42: A04102622 | K42: 2 | L42: PCS | M42: 长春海达 | N42: ★
...

Sheet 6608491523
A1: Version 版本 | B1: Draw No. 图纸号 | C1: entry name 项目名称 | D1: Harness number 零件号 | E1: Harness Name 零件名称 | F1: Draw Version 图纸版本 | G1: Creat Date 报价日期 | H1: Recent AEM 最新AEM | I1: Total Wire 总回路数 | J1: Total Wire length 总导线长度 | K1: Total Connector 总护套数 | L1: Total Terminal 总端子数
A2: V01 | C2: E281 | D2: 6608491523 | E2: 直流母线总成
A4: NO. | B4: Function 功能 | C4: Part Number 零件号 | D4: Part Name 零件名称 | E4: Semi-Finished 是否半成品 | F4: Wire NO. 回路号 | G4: PIN | H4: OPTION | I4: SPEC 规格 | J4: Quantity 数量 | K4: Unit 单位 | L4: Remark | M4: Other-Remark 其他备注 | N4: Sub-Part Number 半成品号 | O4: Sub-Part Name 半成品名称 | P4: Sub-Part Quantity 半成品数量 | Q4: Sub-Part Unit 单位
A5: 1 | B5: HVPC2P1600FT535-NH-P010 接电池端 适配2*35mm²屏蔽铜包铝硅胶铝导线 | C5: HVPC2P1600FT5-NH-MP010 | D5: 护套（145度反装 A键位） | E5: N | F5: A02105032 | J5: 1 | K5: PCS | L5: 安费诺 | M5: 客户指定
A6: 2 | C6: HVPC2P1600FT-09P010 | D6: 插头端子-单粒焊接 | E6: N | F6: A03103389 | J6: 2 | K6: PCS | L6: 安费诺 | M6: 客户指定
A7: 3 | C7: HVPC2P1600FV-15P010 | D7: 挡板_黑色 | E7: N | F7: A02104375 | J7: 2 | K7: PCS | L7: 安费诺 | M7: 客户指定
A8: 4 | C8: HVPC2P1600FV-06-35P010 | D8: 插头外屏蔽环 | E8: N | F8: A03103387 | J8: 2 | K8: PCS | L8: 安费诺 | M8: 客户指定
A9: 5 | C9: HVC2P80FS1-47P010 | D9: 插头屏蔽内环 | E9: N | F9: A03103388 | J9: 2 | K9: PCS | L9: 安费诺 | M9: 客户指定
A10: 6 | C10: HVPC2P1600FV-12-35P010 | D10: 插头线束密封圈 | E10: N | F10: A02105020 | J10: 2 | K10: PCS | L10: 安费诺 | M10: 客户指定
A11: 7 | C11: HVPC2P1600FV-11-35P010 | D11: 插头线卡 | E11: N | F11: A02105018 | J11: 2 | K11: PCS | L11: 安费诺 | M11: 客户指定
A12: 8 | C12: HVPC2P1600FV-10-35P010 | D12: 插头尾盖 | E12: N | F12: A02105019 | J12: 2 | K12: PCS | L12: 安费诺 | M12: 客户指定
A13: 9 | B13: IPT2PFS035-S02P010（安费诺） 接电驱端 适配2*35mm²屏蔽铜包铝硅胶铝导线 | C13: N022525276C | D13: 焊接端子-70 | E13: N | F13: A03103440 | J13: 2 | K13: PCS | L13: 安费诺 | M13: 客户指定
A14: 10 | C14: IPT2PFS035-GA-01P010 | D14: 主体组合件 | E14: N | F14: A02102660 | J14: 1 | K14: PCS | L14: 安费诺 | M14: 客户指定
A15: 11 | C15: IPT2PFS-S01-35P010 | D15: 压接屏蔽内环-35 | E15: N | F15: A03101954 | J15: 2 | K15: PCS | L15: 安费诺 | M15: 客户指定
A16: 12 | C16: IPT2PFS-S02-35P010 | D16: 压接屏蔽外环-35/50 | E16: N | F16: A03101953 | J16: 2 | K16: PCS | L16: 安费诺 | M16: 客户指定
A17: 13 | C17: IPT2PFS-M04-35P010 | D17: 屏蔽固定件-16/25/35 | E17: N | F17: A02102662 | J17: 4 | K17: PCS | L17: 安费诺 | M17: 客户指定
A18: 14 | C18: IPT2PFS-R02-35P010 | D18: 密封圈-35 | E18: N | F18: A02102663 | J18: 2 | K18: PCS | L18: 安费诺 | M18: 客户指定
A19: 15 | C19: IPT2PFS-M05-35P010 | D19: 尾盖-35 | E19: N | F19: A02105144 | J19: 2 | K19: PCS | L19: 安费诺 | M19: 客户指定
A20: 16 | C20: HS-125(3X) 18-30 | D20: 不带胶-热缩管 | E20: N | F20: A04102622 | J20: 2 | K20: PCS | L20: 长春海达 | M20: ★
A21: 17 | C21: FHLALR2GCCAATB2G/35.0/橙 | D21: 35mm²屏蔽镀锡铜包铝硅胶铝导线 | E21: N | F21: A01103420 | H21: =1506/1000 -> 1.506 | J21: 1.59 | K21: M | L21: 太平洋 | M21: ★
A22: 18 | C22: SCS2165A016 | D22: 16OR橙色编织套管 | E22: N | F22: A04101476 | J22: 1.15 | K22: M | L22: 骏鼎达 | M22: ★
A23: 19 | C23: LY5016019-OR2 | D23: 橙色布基胶带 | E23: N | F23: A04101159 | J23: 4.6 | K23: M | L23: 联益 | M23: ★
A24: 20 | C24: E281-HB-04 | D24: 塑料支架（带2个衬套） | E24: N | F24: A06102155 | J24: 1 | K24: PCS | L24: 上海程达 | M24: ★
A25: 21 | C25: E281-ZJ-06 | D25: 金属支架 | E25: N | F25: A06102146 | J25: 1 | K25: PCS | L25: 华凯 | M25: ★
A26: 22 | C26: E281-XJ-06 | D26: 橡胶件 | E26: N | F26: A04102659 | J26: 2 | K26: PCS | L26: 博昊 | M26: ★
A27: 23 | C27: E281-XJ-09 | D27: 橡胶件 | E27: N | F27: A04102661 | J27: 4 | K27: PCS | L27: 博昊 | M27: ★
A28: 24 | C28: 111-00563 | D28: 扎带绳 | E28: N | F28: A06010012 | J28: 6 | K28: PCS | L28: 海尔曼太通 | M28: ★
A29: 25 | C29: X1-BQ-01 标签140x30mm | D29: 产品标签 | E29: N | F29: 70002326 | J29: 1 | K29: PCS | L29: 洪众
D165: 3

Sheet 6608491524
A1: Version 版本 | B1: Draw No. 图纸号 | C1: entry name 项目名称 | D1: Harness number 零件号 | E1: Harness Name 零件名称 | F1: Draw Version 图纸版本 | G1: Creat Date 报价日期 | H1: Recent AEM 最新AEM | I1: Total Wire 总回路数 | J1: Total Wire length 总导线长度 | K1: Total Connector 总护套数 | L1: Total Terminal 总端子数
A2: V01 | C2: E281 | D2: 6608491524 | E2: 直流母线总成
A4: NO. | B4: Function 功能 | C4: Part Number 零件号 | D4: Part Name 零件名称 | E4: Semi-Finished 是否半成品 | F4: Wire NO. 回路号 | G4: PIN | H4: OPTION | I4: SPEC 规格 | J4: Quantity 数量 | K4: Unit 单位 | L4: Remark | M4: Other-Remark 其他备注 | N4: Sub-Part Number 半成品号 | O4: Sub-Part Name 半成品名称 | P4: Sub-Part Quantity 半成品数量 | Q4: Sub-Part Unit 单位
A5: 1 | B5: HVPC2P1600FV535-NH-P010 接电池端 适配2*35mm²屏蔽铜包铝硅胶铝导线 | C5: HVPC2P1600FV5-NH-M-P010 | D5: 护套-90度-反装-CODE A | E5: N | F5: A02105143 | J5: 1 | K5: PCS | L5: 安费诺 | M5: 客户指定
A6: 2 | C6: HVPC2P1600FV-09-P010 | D6: 焊接端子-镀银 | E6: N | F6: A03103438 | J6: 2 | K6: PCS | L6: 安费诺 | M6: 客户指定
A7: 3 | C7: HVPC2P1600FV-15P010 | D7: 挡板_黑色 | E7: N | F7: A02104375 | J7: 2 | K7: PCS | L7: 安费诺 | M7: 客户指定
A8: 4 | C8: HVPC2P1600FV-06-35P010 | D8: 插头外屏蔽环 | E8: N | F8: A03103387 | J8: 2 | K8: PCS | L8: 安费诺 | M8: 客户指定
A9: 5 | C9: HVPC2P1800FS-11-25G-P010 | D9: 内屏蔽环 | E9: N | F9: A03103437 | J9: 2 | K9: PCS | L9: 安费诺 | M9: 客户指定
A10: 6 | C10: HVPC2P1600FV-12-35P010 | D10: 密封圈-黑色 | E10: N | F10: A02105020 | J10: 2 | K10: PCS | L10: 安费诺 | M10: 客户指定
A11: 7 | C11: HVPC2P1600FV-11-35P010 | D11: 线卡-黑色 | E11: N | F11: A02105018 | J11: 2 | K11: PCS | L11: 安费诺 | M11: 客户指定
A12: 8 | C12: HVPC2P1600FV-10-35P010 | D12: 尾盖-橙色 | E12: N | F12: A02105019 | J12: 2 | K12: PCS | L12: 安费诺 | M12: 客户指定
A13: 9 | B13: IPT2PFS035-S02P010（安费诺） 接电驱端 适配2*35mm²屏蔽铜包铝硅胶铝导线 | C13: N022525276C | D13: 焊接端子-70 | E13: N | F13: A03103440 | J13: 2 | K13: PCS | L13: 安费诺 | M13: 客户指定
A14: 10 | C14: IPT2PFS035-GA-01P010 | D14: 主体组合件 | E14: N | F14: A02102660 | J14: 1 | K14: PCS | L14: 安费诺 | M14: 客户指定
A15: 11 | C15: IPT2PFS-S01-35P010 | D15: 压接屏蔽内环-35 | E15: N | F15: A03101954 | J15: 2 | K15: PCS | L15: 安费诺 | M15: 客户指定
A16: 12 | C16: IPT2PFS-S02-35P010 | D16: 压接屏蔽外环-35/50 | E16: N | F16: A03101953 | J16: 2 | K16: PCS | L16: 安费诺 | M16: 客户指定
A17: 13 | C17: IPT2PFS-M04-35P010 | D17: 屏蔽固定件-16/25/35 | E17: N | F17: A02102662 | J17: 4 | K17: PCS | L17: 安费诺 | M17: 客户指定
A18: 14 | C18: IPT2PFS-R02-35P010 | D18: 密封圈-35 | E18: N | F18: A02102663 | J18: 2 | K18: PCS | L18: 安费诺 | M18: 客户指定
A19: 15 | C19: IPT2PFS-M05-35P010 | D19: 尾盖-35 | E19: N | F19: A02105144 | J19: 2 | K19: PCS | L19: 安费诺 | M19: 客户指定
A20: 16 | C20: HS-125(3X) 18-30 | D20: 不带胶-热缩管 | E20: N | F20: A04102622 | J20: 2 | K20: PCS | L20: 长春海达 | M20: ★
A21: 17 | C21: FHLALR2GCCAATB2G/35.0/橙 | D21: 35mm²屏蔽镀锡铜包铝硅胶铝导线 | E21: N | F21: A01103420 | H21: =1317/1000 -> 1.317 | J21: 1.41 | K21: M | L21: 太平洋 | M21: ★
A22: 18 | C22: SCS2165A016 | D22: 16OR橙色编织套管 | E22: N | F22: A04101476 | J22: 0.97 | K22: M | L22: 骏鼎达 | M22: ★
A23: 19 | C23: LY5016019-OR2 | D23: 橙色布基胶带 | E23: N | F23: A04101159 | J23: 4.6 | K23: M | L23: 联益 | M23: ★
A24: 20 | C24: E281-HB-03 | D24: 塑料支架（带2个衬套） | E24: N | F24: A06102157 | J24: 1 | K24: PCS | L24: 上海程达 | M24: ★
A25: 21 | C25: E281-ZJ-06 | D25: 金属支架 | E25: N | F25: A06102146 | J25: 1 | K25: PCS | L25: 华凯 | M25: ★
A26: 22 | C26: E281-XJ-06 | D26: 橡胶件 | E26: N | F26: A04102659 | J26: 2 | K26: PCS | L26: 博昊 | M26: ★
A27: 23 | C27: E281-XJ-09 | D27: 橡胶件 | E27: N | F27: A04102661 | J27: 4 | K27: PCS | L27: 博昊 | M27: ★
A28: 24 | C28: 111-00563 | D28: 扎带绳 | E28: N | F28: A06010012 | J28: 6 | K28: PCS | L28: 海尔曼太通 | M28: ★
A29: 25 | C29: X1-BQ-01 标签140x30mm | D29: 产品标签 | E29: N | F29: 70002326 | J29: 1 | K29: PCS | L29: 洪众
G66: 黄色报价数据
G67: 橙色正式数据
D165: 3

Sheet 6608442962
A1: Version 版本 | B1: Draw No. 图纸号 | C1: entry name 项目名称 | D1: Harness number 零件号 | E1: Harness Name 零件名称 | F1: Draw Version 图纸版本 | G1: Creat Date 报价日期 | H1: Recent AEM 最新AEM | I1: Total Wire 总回路数 | J1: Total Wire length 总导线长度 | K1: Total Connector 总护套数 | L1: Total Terminal 总端子数
A2: V01 | C2: E281 | D2: 6608442962 | E2: 直流母线总成
A4: NO. | B4: Function 功能 | C4: Part Number 零件号 | D4: Part Name 零件名称 | E4: Semi-Finished 是否半成品 | F4: Wire NO. 回路号 | G4: PIN | H4: OPTION | I4: SPEC 规格 | J4: Quantity 数量 | K4: Unit 单位 | L4: Remark | M4: Other-Remark 其他备注 | N4: Sub-Part Number 半成品号 | O4: Sub-Part Name 半成品名称 | P4: Sub-Part Quantity 半成品数量 | Q4: Sub-Part Unit 单位
A5: 1 | B5: HVPC2P1600FT535-NH-P010 接电池端 适配2*35mm²屏蔽铜包铝硅胶铝导线 | C5: HVPC2P1600FT5-NH-MP010 | D5: 护套（145度反装 A键位） | E5: N | F5: A02105032 | J5: 1 | K5: PCS | L5: 安费诺 | M5: 客户指定
A6: 2 | C6: HVPC2P1600FT-09P010 | D6: 插头端子-单粒焊接 | E6: N | F6: A03103389 | J6: 2 | K6: PCS | L6: 安费诺 | M6: 客户指定
A7: 3 | C7: HVPC2P1600FV-15P010 | D7: 挡板_黑色 | E7: N | F7: A02104375 | J7: 2 | K7: PCS | L7: 安费诺 | M7: 客户指定
A8: 4 | C8: HVPC2P1600FV-06-35P010 | D8: 插头外屏蔽环 | E8: N | F8: A03103387 | J8: 2 | K8: PCS | L8: 安费诺 | M8: 客户指定
A9: 5 | C9: HVC2P80FS1-47P010 | D9: 插头屏蔽内环 | E9: N | F9: A03103388 | J9: 2 | K9: PCS | L9: 安费诺 | M9: 客户指定
A10: 6 | C10: HVPC2P1600FV-12-35P010 | D10: 插头线束密封圈 | E10: N | F10: A02105020 | J10: 2 | K10: PCS | L10: 安费诺 | M10: 客户指定
A11: 7 | C11: HVPC2P1600FV-11-35P010 | D11: 插头线卡 | E11: N | F11: A02105018 | J11: 2 | K11: PCS | L11: 安费诺 | M11: 客户指定
A12: 8 | C12: HVPC2P1600FV-10-35P010 | D12: 插头尾盖 | E12: N | F12: A02105019 | J12: 2 | K12: PCS | L12: 安费诺 | M12: 客户指定
A13: 9 | B13: IPT2PFS035-S02P010（安费诺） 接电驱端 适配2*35mm²屏蔽铜包铝硅胶铝导线 | C13: N022525276C | D13: 焊接端子-70 | E13: N | F13: A03103440 | J13: 2 | K13: PCS | L13: 安费诺 | M13: 客户指定
A14: 10 | C14: IPT2PFS035-GA-01P010 | D14: 主体组合件 | E14: N | F14: A02102660 | J14: 1 | K14: PCS | L14: 安费诺 | M14: 客户指定
A15: 11 | C15: IPT2PFS-S01-35P010 | D15: 压接屏蔽内环-35 | E15: N | F15: A03101954 | J15: 2 | K15: PCS | L15: 安费诺 | M15: 客户指定
A16: 12 | C16: IPT2PFS-S02-35P010 | D16: 压接屏蔽外环-35/50 | E16: N | F16: A03101953 | J16: 2 | K16: PCS | L16: 安费诺 | M16: 客户指定
A17: 13 | C17: IPT2PFS-M04-35P010 | D17: 屏蔽固定件-16/25/35 | E17: N | F17: A02102662 | J17: 4 | K17: PCS | L17: 安费诺 | M17: 客户指定
A18: 14 | C18: IPT2PFS-R02-35P010 | D18: 密封圈-35 | E18: N | F18: A02102663 | J18: 2 | K18: PCS | L18: 安费诺 | M18: 客户指定
A19: 15 | C19: IPT2PFS-M05-35P010 | D19: 尾盖-35 | E19: N | F19: A02105144 | J19: 2 | K19: PCS | L19: 安费诺 | M19: 客户指定
A20: 16 | C20: HS-125(3X) 18-30 | D20: 不带胶-热缩管 | E20: N | F20: A04102622 | J20: 2 | K20: PCS | L20: 长春海达 | M20: ★
A21: 17 | C21: FHLALR2GCCAATB2G/35.0/橙 | D21: 35mm²屏蔽镀锡铜包铝硅胶铝导线 | E21: N | F21: A01103420 | H21: =1886/1000 -> 1.886 | J21: 1.98 | K21: M | L21: 太平洋 | M21: ★
A22: 18 | C22: SCS2165A016 | D22: 16OR橙色编织套管 | E22: N | F22: A04101476 | J22: 1.54 | K22: M | L22: 骏鼎达 | M22: ★
A23: 19 | C23: LY5016019-OR2 | D23: 橙色布基胶带 | E23: N | F23: A04101159 | J23: 4.6 | K23: M | L23: 联益 | M23: ★
A24: 20 | C24: E281-HB-04 | D24: 塑料支架（带2个衬套） | E24: N | F24: A06102155 | J24: 1 | K24: PCS | L24: 上海程达 | M24: ★
A25: 21 | C25: E281-ZJ-06 | D25: 金属支架 | E25: N | F25: A06102146 | J25: 1 | K25: PCS | L25: 华凯 | M25: ★
A26: 22 | C26: E281-ZJ-07 | D26: 金属支架 | E26: N | F26: A06102145 | J26: 1 | K26: PCS | L26: 华凯 | M26: ★
A27: 23 | B27: 原沿用MS11-XJ-05 2PCS改为E281-XJ-06 | C27: E281-XJ-06 | D27: 橡胶件 | E27: N | F27: A04102659 | J27: 4 | K27: PCS | L27: 博昊 | M27: ★
A28: 24 | C28: E281-XJ-09 | D28: 橡胶件 | E28: N | F28: A04102661 | J28: 4 | K28: PCS | L28: 博昊 | M28: ★
A29: 25 | C29: 111-00563 | D29: 扎带绳 | E29: N | F29: A06010012 | J29: 8 | K29: PCS | L29: 海尔曼太通 | M29: ★
A30: 26 | C30: X1-BQ-01 标签140x30mm | D30: 产品标签 | E30: N | F30: 70002326 | J30: 1 | K30: PCS | L30: 洪众
D166: 3

Sheet 6608544875
A1: Version 版本 | B1: Draw No. 图纸号 | C1: entry name 项目名称 | D1: Harness number 零件号 | E1: Harness Name 零件名称 | F1: Draw Version 图纸版本 | G1: Creat Date 报价日期 | H1: Recent AEM 最新AEM | I1: Total Wire 总回路数 | J1: Total Wire length 总导线长度 | K1: Total Connector 总护套数 | L1: Total Terminal 总端子数
A2: V01 | C2: E281 | D2: 6608544875 | E2: 前驱直流母线
A4: NO. | B4: Function 功能 | C4: Part Number 零件号 | D4: Part Name 零件名称 | E4: Semi-Finished 是否半成品 | F4: Wire NO. 回路号 | G4: PIN | H4: OPTION | I4: SPEC 规格 | J4: Quantity 数量 | K4: Unit 单位 | L4: Remark | M4: Other-Remark 其他备注 | N4: Sub-Part Number 半成品号 | O4: Sub-Part Name 半成品名称 | P4: Sub-Part Quantity 半成品数量 | Q4: Sub-Part Unit 单位
A5: 1 | B5: HVPC2P1600FT525-NH-P010 接电池端 适配2*25mm²屏蔽铜包铝硅胶铜导线 | C5: HVPC2P1600FT5-NH-MP010 | D5: 护套（145度反装 A键位） | E5: N | F5: A02105032 | J5: 1 | K5: PCS | L5: 安费诺 | M5: 客户指定
A6: 2 | C6: HVPC2P1600FT-09P010 | D6: 插头端子-单粒焊接 | E6: N | F6: A03103389 | J6: 2 | K6: PCS | L6: 安费诺 | M6: 客户指定
A7: 3 | C7: HVPC2P1600FV-15P010 | D7: 挡板_黑色 | E7: N | F7: A02104375 | J7: 2 | K7: PCS | L7: 安费诺 | M7: 客户指定
A8: 4 | C8: HVPC2P1600FV-06-25P010 | D8: 插头外屏蔽环 | E8: N | F8: A03103410 | J8: 2 | K8: PCS | L8: 安费诺 | M8: 客户指定
A9: 5 | C9: HVPC2P1800FS-11-25P010 | D9: 插头屏蔽内环 | E9: N | F9: A03103409 | J9: 2 | K9: PCS | L9: 安费诺 | M9: 客户指定
A10: 6 | C10: HVPC2P1600FV-12-25P010 | D10: 插头线束密封圈 | E10: N | F10: A02105062 | J10: 2 | K10: PCS | L10: 安费诺 | M10: 客户指定
A11: 7 | C11: HVPC2P1600FV-11-25P010 | D11: 插头线卡 | E11: N | F11: A02105060 | J11: 2 | K11: PCS | L11: 安费诺 | M11: 客户指定
A12: 8 | C12: HVPC2P1600FV-10-25P010 | D12: 插头尾盖 | E12: N | F12: A02105061 | J12: 2 | K12: PCS | L12: 安费诺 | M12: 客户指定
A13: 9 | B13: IPT 压接端子 | C13: 1-2177380-1 | D13: IPT 压接端子 | E13: N | F13: A03000392 | J13: 2 | K13: PCS | L13: 泰科 | M13: ★
A14: 10 | B14: IPT2P25P001-P010（安费诺 不含端子） 接电驱端 适配2*25mm²屏蔽铜包铝硅胶铜导线 | C14: IPT3P-01-06 | D14: 特殊屏蔽件 | E14: N | F14: A02030991 | J14: 2 | K14: PCS | L14: 安费诺 | M14: 客户指定
A15: 11 | C15: IPT3P-01-19 | D15: 25mm2 屏蔽外环 | E15: N | F15: A03103408 | J15: 2 | K15: PCS | L15: 安费诺 | M15: 客户指定
A16: 12 | C16: IPT3P-01-20 | D16: 25mm2 屏蔽内环 | E16: N | F16: A03103407 | J16: 2 | K16: PCS | L16: 安费诺 | M16: 客户指定
A17: 13 | C17: IPT3P-01-21 | D17: 护套密封圈 | E17: N | F17: A02030990 | J17: 2 | K17: PCS | L17: 安费诺 | M17: 客户指定
A18: 14 | C18: IPT2PP-01-01 | D18: 护套主体 | E18: N | F18: A02031898 | J18: 1 | K18: PCS | L18: 安费诺 | M18: 客户指定
A19: 15 | C19: IPT3P-01-18 | D19: 25mm2 线密封圈 | E19: N | F19: A02105058 | J19: 2 | K19: PCS | L19: 安费诺 | M19: 客户指定
