Workbook
Name a: [3]Terminal!$F$1:$F$3
Name countif: #REF!
Name countif: #REF!
Name countif: #REF!
Name countif: #REF!
Name D: #REF!
Name D: #REF!
Name D: #REF!
Name D: #REF!
Name E: #REF!
Name E: #REF!
Name E: #REF!
Name Erstelldatum: #REF!
Name Erstelldatum: #REF!
Name Erstelldatum: #REF!
Name Erstelldatum: #REF!
Name EXCEL_EXPORT1: #REF!
Name EXCEL_EXPORT1: #REF!
Name EXCEL_EXPORT1: #REF!
Name FZG_Beschriftung: #REF!
Name FZG_Beschriftung: #REF!
Name PA_Beschriftung: #REF!
Name PA_Beschriftung: #REF!
Name PA_Beschriftung: #REF!
Name Planungsstand: #REF!
Name Planungsstand: #REF!
Name Planungsstand: #REF!
Name Vergleichsplanung: #REF!
Name Vergleichsplanung: #REF!
Name Vergleichsplanung: #REF!
Name x: #REF!
Name x: #REF!
Name x: #REF!
Name Z: #REF!
Name Z: #REF!
Name Z: #REF!
Name 公用设备大类: OFFSET([4]资源数据源!$S$1,1,0,COUNTA([4]资源数据源!$S:$S)-COUNTIF([4]资源数据源!$S:$S,0)-1,1)
Name 公用设备大类: OFFSET([5]资源数据源!$S$1,1,0,COUNTA([5]资源数据源!$S:$S)-COUNTIF([5]资源数据源!$S:$S,0)-1,1)
Name 公用设备大类: OFFSET([5]资源数据源!$S$1,1,0,COUNTA([5]资源数据源!$S:$S)-COUNTIF([5]资源数据源!$S:$S,0)-1,1)
Name 公用设备大类: OFFSET([5]资源数据源!$S$1,1,0,COUNTA([5]资源数据源!$S:$S)-COUNTIF([5]资源数据源!$S:$S,0)-1,1)
Name 公用设备大类: OFFSET([4]资源数据源!$S$1,1,0,COUNTA([4]资源数据源!$S:$S)-COUNTIF([4]资源数据源!$S:$S,0)-1,1)
Name 公用设备大类: OFFSET([7]资源数据源!$S$1,1,0,COUNTA([7]资源数据源!$S:$S)-COUNTIF([7]资源数据源!$S:$S,0)-1,1)
Name 公用设备名称: OFFSET([4]资源数据源!$G$1,MATCH('[4]项目评估汇总-样表'!$C1,[4]资源数据源!$F:$F,0)-1,0,COUNTIF([4]资源数据源!$F:$F,'[4]项目评估汇总-样表'!$C1),1)
Name 公用设备名称: OFFSET([5]资源数据源!$G$1,MATCH(设备投资明细!#REF!,[5]资源数据源!$F:$F,0)-1,0,COUNTIF([5]资源数据源!$F:$F,设备投资明细!#REF!),1)
Name 公用设备名称: OFFSET([5]资源数据源!$G$1,MATCH([5]项目设备投入!$C1,[5]资源数据源!$F:$F,0)-1,0,COUNTIF([5]资源数据源!$F:$F,[5]项目设备投入!$C1),1)
Name 公用设备名称: OFFSET([5]资源数据源!$G$1,MATCH([5]项目设备投入!$C1,[5]资源数据源!$F:$F,0)-1,0,COUNTIF([5]资源数据源!$F:$F,[5]项目设备投入!$C1),1)
Name 公用设备名称: OFFSET([4]资源数据源!$G$1,MATCH('[4]项目评估汇总-样表'!$C1,[4]资源数据源!$F:$F,0)-1,0,COUNTIF([4]资源数据源!$F:$F,'[4]项目评估汇总-样表'!$C1),1)
Name 公用设备名称: OFFSET([7]资源数据源!$G$1,MATCH('[7]项目评估汇总-样表'!$C1,[7]资源数据源!$F:$F,0)-1,0,COUNTIF([7]资源数据源!$F:$F,'[7]项目评估汇总-样表'!$C1),1)
Name 项目评估: #REF!
Name 项目评估: #REF!
Name 项目评估: #REF!
Name 专用工装设备大类: OFFSET([4]资源数据源!$W$1,1,0,COUNTA([4]资源数据源!$W:$W)-COUNTIF([4]资源数据源!$W:$W,0)-1,1)
Name 专用工装设备大类: OFFSET([5]资源数据源!$W$1,1,0,COUNTA([5]资源数据源!$W:$W)-COUNTIF([5]资源数据源!$W:$W,0)-1,1)
Name 专用工装设备大类: OFFSET([5]资源数据源!$W$1,1,0,COUNTA([5]资源数据源!$W:$W)-COUNTIF([5]资源数据源!$W:$W,0)-1,1)
Name 专用工装设备大类: OFFSET([5]资源数据源!$W$1,1,0,COUNTA([5]资源数据源!$W:$W)-COUNTIF([5]资源数据源!$W:$W,0)-1,1)
Name 专用工装设备大类: OFFSET([4]资源数据源!$W$1,1,0,COUNTA([4]资源数据源!$W:$W)-COUNTIF([4]资源数据源!$W:$W,0)-1,1)
Name 专用工装设备大类: OFFSET([7]资源数据源!$W$1,1,0,COUNTA([7]资源数据源!$W:$W)-COUNTIF([7]资源数据源!$W:$W,0)-1,1)
Name 专用工装设备名称: OFFSET([9]资源数据源!$G$1,MATCH(#REF!,[9]资源数据源!$F:$F,0)-1,0,COUNTIF([9]资源数据源!$F:$F,#REF!),1)
Name 专用工装设备名称: OFFSET([5]资源数据源!$G$1,MATCH([5]项目工装投入!$C1,[5]资源数据源!$F:$F,0)-1,0,COUNTIF([5]资源数据源!$F:$F,[5]项目工装投入!$C1),1)
Name 专用工装设备名称: OFFSET([5]资源数据源!$G$1,MATCH('项目工装投入 '!$C1,[5]资源数据源!$F:$F,0)-1,0,COUNTIF([5]资源数据源!$F:$F,'项目工装投入 '!$C1),1)

Sheet 项目评估汇总（昆山90%）-一个配置
A1: 吉利E281高压
A2: 内 容 | E2: 产 品 周 期 汇 总 | N2: 备 注 | P2: 1 | Q2: 5 | R2: 9
C3: 费率 | E3: 目标汇总值 | F3: 第一年2026年 | G3: 第二年2027年 | H3: 第三年2028年 | I3: 第四年2029年 | J3: 第五年2030年 | K3: 第六年2031年 | P3: 6608491523 | Q3: 6608442964 | R3: 6608442966
A4: 回路数（PCS） | F4: =#REF! -> #REF! | G4: =F4 -> #REF! | H4: =G4 -> #REF! | I4: =H4 -> #REF! | J4: =I4 -> #REF! | K4: =J4 -> #REF! | P4: =VLOOKUP(P3,#REF!,15,0) -> #REF! | Q4: =VLOOKUP(Q3,#REF!,15,0) -> #REF! | R4: =VLOOKUP(R3,#REF!,15,0) -> #REF!
A5: 目标销售数量（PCS） | E5: =SUM(F5:K5) -> 240000 | F5: 34000 | G5: 54000 | H5: 50000 | I5: 45600 | J5: 37600 | K5: 18800 | P5: =P37 -> 240000 | Q5: =Q37 -> 240000 | R5: =R37 -> 240000
A6: 目标销售单价（元） | F6: =I38 -> #REF! | G6: =I41 -> #REF! | H6: =H35 -> #REF! | I6: =H6 -> #REF! | J6: =I6 -> #REF! | K6: =J6 -> #REF! | N6: 平均售价 | P6: =VLOOKUP(P$3,#REF!,9,0) -> #REF! | Q6: =VLOOKUP(Q$3,#REF!,9,0) -> #REF! | R6: =VLOOKUP(R$3,#REF!,9,0) -> #REF!
A7: 回路单价 （元） | F7: =F6/F4 -> #REF! | G7: =G6/G4 -> #REF! | H7: =H6/H4 -> #REF! | I7: =I6/I4 -> #REF! | J7: =I7 -> #REF! | K7: =J7 -> #REF! | N7: =(E9-E13)/E5 -> #REF! | P7: =P6/P4 -> #REF! | Q7: =Q6/Q4 -> #REF! | R7: =R6/R4 -> #REF!
A8: 回路工时 （秒） | F8: =(#REF!+#REF!+#REF!)*3600/F4 -> #REF! | G8: =F8 -> #REF! | H8: =G8 -> #REF! | I8: =H8 -> #REF! | J8: =I8 -> #REF! | K8: =J8 -> #REF!
A9: 目标销售收入（元） | E9: =SUM(F9:M9) -> #REF! | F9: =F6*F5 -> #REF! | G9: =G6*G5 -> #REF! | H9: =H6*H5 -> #REF! | I9: =I6*I5 -> #REF! | J9: =J6*J5 -> #REF! | K9: =K6*K5 -> #REF! | N9: =E9/E5 -> #REF! | P9: =P6*P5 -> #REF! | Q9: =Q6*Q5 -> #REF! | R9: =R6*R5 -> #REF!
A10: 目标利润额（元） | E10: =E9-E14 -> #REF! | F10: =(F6-F14)*F5 -> #REF! | G10: =(G6-G14)*G5 -> #REF! | H10: =(H6-H14)*H5 -> #REF! | I10: =(I6-I14)*I5 -> #REF! | J10: =(J6-J14)*J5 -> #REF! | K10: =(K6-K14)*K5 -> #REF! | P10: =(P6-P14)*P5 -> #REF! | Q10: =(Q6-Q14)*Q5 -> #REF! | R10: =(R6-R14)*R5 -> #REF!
A11: 毛利（%） | E11: =(E9-E15-E16-E20-E23-E13-E31-E32)/E9 -> #REF! | F11: =((F6-F15-F16-F20-F23)-(F13/F5)-F31-F32)/F6 -> #REF! | G11: =((G6-G15-G16-G20-G23)-(G13/G5)-G31-G32)/G6 -> #REF! | H11: =((H6-H15-H16-H20-H23)-(H13/H5)-H31-H32)/H6 -> #REF! | I11: =((I6-I15-I16-I20-I23)-(I13/I5)-I31-I32)/I6 -> #REF! | J11: =((J6-J15-J16-J20-J23)-(J13/J5)-J31-J32)/J6 -> #REF! | K11: =((K6-K15-K16-K20-K23)-(K13/K5)-K31-K32)/K6 -> #REF! | P11: =((P6-P15-P16-P20-P23)-(P13/P5)-P31-P32)/P6 -> #REF! | Q11: =((Q6-Q15-Q16-Q20-Q23)-(Q13/Q5)-Q31-Q32)/Q6 -> #REF! | R11: =((R6-R15-R16-R20-R23)-(R13/R5)-R31-R32)/R6 -> #REF!
A12: 毛利（元） | E12: =E11*E9 -> #REF! | F12: =F11*F9 -> #REF! | G12: =G11*G9 -> #REF! | H12: =H11*H9 -> #REF! | I12: =I11*I9 -> #REF! | J12: =J11*J9 -> #REF! | K12: =K11*K9 -> #REF! | P12: =P11*P9 -> #REF! | Q12: =Q11*Q9 -> #REF! | R12: =R11*R9 -> #REF!
A13: 返点金额（QS）（元） | E13: =SUM(F13:J13) -> #REF! | F13: =10000000*E34 -> #REF!
A14: 单套项目总成本（元/PCS） | E14: =F14*$F$5+G14*$G$5+H14*$H$5+$I$5*I14+J14*$J$5+K14*$K$5+L14*$L$5+M14*$M$5 -> #REF! | F14: =SUM(P14:R14) -> #REF! | G14: =G16+G15+G20+G23+G31+G32 -> #REF! | H14: =H16+H15+H20+H23+H31+H32 -> #REF! | I14: =I16+I15+I20+I23+I31+I32 -> #REF! | J14: =J16+J15+J20+J23+J31+J32 -> #REF! | K14: =K16+K15+K20+K23+K31+K32 -> #REF! | L14: =L16+L15+L20+L23+L31+L32 -> 0 | M14: =M16+M15+M20+M23+M31+M32 -> 0 | N14: =(E14/$E$5)/($N$7-$E$13/$E$5) -> #REF! | O14: {=SUMPRODUCT(P14:R14,$P$35:$R$35)-K14} -> #REF! | P14: =P16+P15+P20+P23+P31+P32 -> #REF! | Q14: =Q16+Q15+Q20+Q23+Q31+Q32 -> #REF! | R14: =R16+R15+R20+R23+R31+R32 -> #REF!
A15: 单套材料成本（元/PCS） | D15: BOM材料成本 | E15: =F15*$F$5+G15*$G$5+H15*$H$5+$I$5*I15+J15*$J$5+K15*$K$5+L15*$L$5+M15*$M$5 -> #REF! | F15: =SUM(P15:R15) -> #REF! | G15: =F15 -> #REF! | H15: =G15 -> #REF! | I15: =H15 -> #REF! | J15: =I15 -> #REF! | K15: =J15 -> #REF! | N15: =(E15/$E$5)/($N$7-$E$13/$E$5) -> #REF! | O15: {=SUMPRODUCT(P15:R15,$P$35:$R$35)-K15} -> #REF! | P15: =VLOOKUP(P3,#REF!,6,0) -> #REF! | Q15: =VLOOKUP(Q3,#REF!,6,0) -> #REF! | R15: =VLOOKUP(R3,#REF!,6,0) -> #REF!
A16: 单套直接人工（元/PCS） | E16: =F16*$F$5+G16*$G$5+H16*$H$5+$I$5*I16+J16*$J$5+K16*$K$5+L16*$L$5+M16*$M$5 -> #REF! | F16: =SUM(P16:R16) -> #REF! | G16: =G17+G18+G19 -> #REF! | H16: =H17+H18+H19 -> #REF! | I16: =H16 -> #REF! | J16: =I16 -> #REF! | K16: =J16 -> #REF! | N16: =(E16/$E$5)/($N$7-$E$13/$E$5) -> #REF! | O16: {=SUMPRODUCT(P16:R16,$P$35:$R$35)-K16} -> #REF! | P16: =P17+P18+P19 -> #REF! | Q16: =Q17+Q18+Q19 -> #REF! | R16: =R17+R18+R19 -> #REF!
B17: —前工程效率-开线 | C17: 工厂开线标准工时费 | D17: 工厂开线标准工时费*工时 | E17: =F17*$F$5+G17*$G$5+H17*$H$5+$I$5*I17+J17*$J$5+K17*$K$5+L17*$L$5+M17*$M$5 -> #REF! | F17: =SUM(P17:R17) -> #REF! | G17: =F17 -> #REF! | H17: =G17 -> #REF! | I17: =H17 -> #REF! | J17: =I17 -> #REF! | K17: =J17 -> #REF! | N17: =(E17/$E$5)/($N$7-$E$13/$E$5) -> #REF! | O17: {=SUMPRODUCT(P17:R17,$P$35:$R$35)-K17} -> #REF! | P17: =VLOOKUP(P3,#REF!,11,0)*运营工时费报价基准!$D$6/运营工时费报价基准!$M$5 -> #REF! | Q17: =VLOOKUP(Q3,#REF!,11,0)*运营工时费报价基准!$D$6/运营工时费报价基准!$M$5 -> #REF! | R17: =VLOOKUP(R3,#REF!,11,0)*运营工时费报价基准!$D$6/运营工时费报价基准!$M$5 -> #REF!
B18: —前工程效率 - 公共制程 | C18: 工厂公共制程标准工时费 | D18: 工厂公共制程标准工时费*工时 | E18: =F18*$F$5+G18*$G$5+H18*$H$5+$I$5*I18+J18*$J$5+K18*$K$5+L18*$L$5+M18*$M$5 -> #REF! | F18: =SUM(P18:R18) -> #REF! | G18: =F18 -> #REF! | H18: =G18 -> #REF! | I18: =H18 -> #REF! | J18: =I18 -> #REF! | K18: =J18 -> #REF! | N18: =(E18/$E$5)/($N$7-$E$13/$E$5) -> #REF! | O18: {=SUMPRODUCT(P18:R18,$P$35:$R$35)-K18} -> #REF! | P18: =VLOOKUP(P3,#REF!,12,0)*运营工时费报价基准!$E$8/运营工时费报价基准!$M$5 -> #REF! | Q18: =VLOOKUP(Q3,#REF!,12,0)*运营工时费报价基准!$E$8/运营工时费报价基准!$M$5 -> #REF! | R18: =VLOOKUP(R3,#REF!,12,0)*运营工时费报价基准!$E$8/运营工时费报价基准!$M$5 -> #REF!
B19: —后工程 - 总装 | C19: 工厂总装标准工时费 | D19: 工厂总装标准工时费*工时 | E19: =F19*$F$5+G19*$G$5+H19*$H$5+$I$5*I19+J19*$J$5+K19*$K$5+L19*$L$5+M19*$M$5 -> #REF! | F19: =SUM(P19:R19) -> #REF! | G19: =F19 -> #REF! | H19: =G19 -> #REF! | I19: =H19 -> #REF! | J19: =I19 -> #REF! | K19: =J19 -> #REF! | N19: =(E19/$E$5)/($N$7-$E$13/$E$5) -> #REF! | O19: {=SUMPRODUCT(P19:R19,$P$35:$R$35)-K19} -> #REF! | P19: =VLOOKUP(P3,#REF!,13,0)*运营工时费报价基准!$E$8/运营工时费报价基准!$M$5 -> #REF! | Q19: =VLOOKUP(Q3,#REF!,13,0)*运营工时费报价基准!$E$8/运营工时费报价基准!$M$5 -> #REF! | R19: =VLOOKUP(R3,#REF!,13,0)*运营工时费报价基准!$E$8/运营工时费报价基准!$M$5 -> #REF!
A20: 单套设备成本（元/PCS） | E20: =F20*$F$5+G20*$G$5+H20*$H$5+$I$5*I20+J20*$J$5+K20*$K$5+L20*$L$5+M20*$M$5 -> #REF! | F20: =SUM(P20:R20) -> #REF! | G20: =G21+G22 -> #REF! | H20: =H21+H22 -> #REF! | I20: =H20 -> #REF! | J20: =I20 -> #REF! | K20: =J20 -> #REF! | N20: =(E20/$E$5)/($N$7-$E$13/$E$5) -> #REF! | O20: {=SUMPRODUCT(P20:R20,$P$35:$R$35)-K20} -> #REF! | P20: =P21+P22 -> #REF! | Q20: =Q21+Q22 -> #REF! | R20: =R21+R22 -> #REF!
B21: —共用设备（元/PCS) | D21: 年折旧*使用年限/产量 | E21: =F21*$F$5+G21*$G$5+H21*$H$5+$I$5*I21+J21*$J$5+K21*$K$5+L21*$L$5+M21*$M$5 -> #REF! | F21: =SUM(P21:R21) -> #REF! | G21: =F21 -> #REF! | H21: =G21 -> #REF! | I21: =H21 -> #REF! | J21: =I21 -> #REF! | K21: =J21 -> #REF! | N21: =(E21/$E$5)/($N$7-$E$13/$E$5) -> #REF! | O21: {=SUMPRODUCT(P21:R21,$P$35:$R$35)-K21} -> #REF! | P21: =设备投资明细!Q31 -> #REF! | Q21: =设备投资明细!U31 -> #REF! | R21: =设备投资明细!Y31 -> #REF!
B22: —专用设备（元/PCS) | D22: 总价值／产量 | E22: =F22*$F$5+G22*$G$5+H22*$H$5+$I$5*I22+J22*$J$5+K22*$K$5+L22*$L$5+M22*$M$5 -> #REF! | F22: =SUM(P22:R22) -> #REF! | G22: =F22-3 -> #REF! | H22: =G22 -> #REF! | I22: =H22 -> #REF! | J22: =I22 -> #REF! | K22: =J22 -> #REF! | N22: =(E22/$E$5)/($N$7-$E$13/$E$5) -> #REF! | O22: {=SUMPRODUCT(P22:R22,$P$35:$R$35)-K22} -> #REF! | P22: =设备投资明细!Q41+项目专用模具!O14+'项目工装投入 '!O15 -> #REF! | Q22: =设备投资明细!U41+项目专用模具!S14+'项目工装投入 '!S15 -> #REF! | R22: =设备投资明细!Y41+项目专用模具!W14+'项目工装投入 '!W15 -> #REF!
A23: 制造费用(单套) D=①+②+③+④ | E23: =F23*$F$5+G23*$G$5+H23*$H$5+$I$5*I23+J23*$J$5+K23*$K$5+L23*$L$5+M23*$M$5 -> #REF! | F23: =SUM(P23:R23) -> #REF! | G23: =G24+G25+G26+G27+G28+G29+G30 -> #REF! | H23: =H24+H25+H26+H27+H28+H29+H30 -> #REF! | I23: =I24+I25+I26+I27+I28+I29+I30 -> #REF! | J23: =J24+J25+J26+J27+J28+J29+J30 -> #REF! | K23: =K24+K25+K26+K27+K28+K29+K30 -> #REF! | N23: =(E23/$E$5)/($N$7-$E$13/$E$5) -> #REF! | O23: {=SUMPRODUCT(P23:R23,$P$35:$R$35)-K23} -> #REF! | P23: =P24+P25+P26+P27+P28+P29+P30 -> #REF! | Q23: =Q24+Q25+Q26+Q27+Q28+Q29+Q30 -> #REF! | R23: =R24+R25+R26+R27+R28+R29+R30 -> #REF!
B24: —间接人工 | C24: 工厂费率 | D24: 工厂费率*工时 | E24: =F24*$F$5+G24*$G$5+H24*$H$5+$I$5*I24+J24*$J$5+K24*$K$5+L24*$L$5+M24*$M$5 -> #REF! | F24: =SUM(P24:R24) -> #REF! | G24: =F24 -> #REF! | H24: =G24 -> #REF! | I24: =H24 -> #REF! | J24: =I24 -> #REF! | K24: =J24 -> #REF! | N24: =(E24/$E$5)/($N$7-$E$13/$E$5) -> #REF! | O24: {=SUMPRODUCT(P24:R24,$P$35:$R$35)-K24} -> #REF! | P24: =(VLOOKUP(P$3,#REF!,11,0)+VLOOKUP(P$3,#REF!,12,0)+VLOOKUP(P$3,#REF!,13,0))*运营工时费报价基准!$E$10 -> #REF! | Q24: =(VLOOKUP(Q$3,#REF!,11,0)+VLOOKUP(Q$3,#REF!,12,0)+VLOOKUP(Q$3,#REF!,13,0))*运营工时费报价基准!$E$10 -> #REF! | R24: =(VLOOKUP(R$3,#REF!,11,0)+VLOOKUP(R$3,#REF!,12,0)+VLOOKUP(R$3,#REF!,13,0))*运营工时费报价基准!$E$10 -> #REF!
B25: —低值易耗品 | C25: 工厂费率 | D25: 工厂费率*工时 | E25: =F25*$F$5+G25*$G$5+H25*$H$5+$I$5*I25+J25*$J$5+K25*$K$5+L25*$L$5+M25*$M$5 -> #REF! | F25: =SUM(P25:R25) -> #REF! | G25: =F25 -> #REF! | H25: =G25 -> #REF! | I25: =H25 -> #REF! | J25: =I25 -> #REF! | K25: =J25 -> #REF! | N25: =(E25/$E$5)/($N$7-$E$13/$E$5) -> #REF! | O25: {=SUMPRODUCT(P25:R25,$P$35:$R$35)-K25} -> #REF! | P25: =(VLOOKUP(P$3,#REF!,11,0)+VLOOKUP(P$3,#REF!,12,0)+VLOOKUP(P$3,#REF!,13,0))*运营工时费报价基准!$E$11 -> #REF! | Q25: =(VLOOKUP(Q$3,#REF!,11,0)+VLOOKUP(Q$3,#REF!,12,0)+VLOOKUP(Q$3,#REF!,13,0))*运营工时费报价基准!$E$11 -> #REF! | R25: =(VLOOKUP(R$3,#REF!,11,0)+VLOOKUP(R$3,#REF!,12,0)+VLOOKUP(R$3,#REF!,13,0))*运营工时费报价基准!$E$11 -> #REF!
B26: —机物料消耗 | C26: 工厂费率 | D26: 工厂费率*工时 | E26: =F26*$F$5+G26*$G$5+H26*$H$5+$I$5*I26+J26*$J$5+K26*$K$5+L26*$L$5+M26*$M$5 -> #REF! | F26: =SUM(P26:R26) -> #REF! | G26: =F26 -> #REF! | H26: =G26 -> #REF! | I26: =H26 -> #REF! | J26: =I26 -> #REF! | K26: =J26 -> #REF! | N26: =(E26/$E$5)/($N$7-$E$13/$E$5) -> #REF! | O26: {=SUMPRODUCT(P26:R26,$P$35:$R$35)-K26} -> #REF! | P26: =(VLOOKUP(P$3,#REF!,11,0)+VLOOKUP(P$3,#REF!,12,0)+VLOOKUP(P$3,#REF!,13,0))*运营工时费报价基准!$E$12 -> #REF! | Q26: =(VLOOKUP(Q$3,#REF!,11,0)+VLOOKUP(Q$3,#REF!,12,0)+VLOOKUP(Q$3,#REF!,13,0))*运营工时费报价基准!$E$12 -> #REF! | R26: =(VLOOKUP(R$3,#REF!,11,0)+VLOOKUP(R$3,#REF!,12,0)+VLOOKUP(R$3,#REF!,13,0))*运营工时费报价基准!$E$12 -> #REF!
B27: —厂房分摊 | C27: 工厂费率 | D27: 工厂费率*工时 | E27: =F27*$F$5+G27*$G$5+H27*$H$5+$I$5*I27+J27*$J$5+K27*$K$5+L27*$L$5+M27*$M$5 -> #REF! | F27: =SUM(P27:R27) -> #REF! | G27: =F27 -> #REF! | H27: =G27 -> #REF! | I27: =H27 -> #REF! | J27: =I27 -> #REF! | K27: =J27 -> #REF! | N27: =(E27/$E$5)/($N$7-$E$13/$E$5) -> #REF! | O27: {=SUMPRODUCT(P27:R27,$P$35:$R$35)-K27} -> #REF! | P27: =(VLOOKUP(P$3,#REF!,11,0)+VLOOKUP(P$3,#REF!,12,0)+VLOOKUP(P$3,#REF!,13,0))*运营工时费报价基准!$E$13 -> #REF! | Q27: =(VLOOKUP(Q$3,#REF!,11,0)+VLOOKUP(Q$3,#REF!,12,0)+VLOOKUP(Q$3,#REF!,13,0))*运营工时费报价基准!$E$13 -> #REF! | R27: =(VLOOKUP(R$3,#REF!,11,0)+VLOOKUP(R$3,#REF!,12,0)+VLOOKUP(R$3,#REF!,13,0))*运营工时费报价基准!$E$13 -> #REF!
B28: —自动化仓、仓库分摊 | C28: 工厂费率 | D28: 工厂费率*工时 | E28: =F28*$F$5+G28*$G$5+H28*$H$5+$I$5*I28+J28*$J$5+K28*$K$5+L28*$L$5+M28*$M$5 -> #REF! | F28: =SUM(P28:R28) -> #REF! | G28: =F28 -> #REF! | H28: =G28 -> #REF! | I28: =H28 -> #REF! | J28: =I28 -> #REF! | K28: =J28 -> #REF! | N28: =(E28/$E$5)/($N$7-$E$13/$E$5) -> #REF! | O28: {=SUMPRODUCT(P28:R28,$P$35:$R$35)-K28} -> #REF! | P28: =(VLOOKUP(P$3,#REF!,11,0)+VLOOKUP(P$3,#REF!,12,0)+VLOOKUP(P$3,#REF!,13,0))*运营工时费报价基准!$E$14 -> #REF! | Q28: =(VLOOKUP(Q$3,#REF!,11,0)+VLOOKUP(Q$3,#REF!,12,0)+VLOOKUP(Q$3,#REF!,13,0))*运营工时费报价基准!$E$14 -> #REF! | R28: =(VLOOKUP(R$3,#REF!,11,0)+VLOOKUP(R$3,#REF!,12,0)+VLOOKUP(R$3,#REF!,13,0))*运营工时费报价基准!$E$14 -> #REF!
B29: —其他制费 | C29: 工厂费率 | D29: 工厂费率*工时 | E29: =F29*$F$5+G29*$G$5+H29*$H$5+$I$5*I29+J29*$J$5+K29*$K$5+L29*$L$5+M29*$M$5 -> #REF! | F29: =SUM(P29:R29) -> #REF! | G29: =F29 -> #REF! | H29: =G29 -> #REF! | I29: =H29 -> #REF! | J29: =I29 -> #REF! | K29: =J29 -> #REF! | N29: =(E29/$E$5)/($N$7-$E$13/$E$5) -> #REF! | O29: {=SUMPRODUCT(P29:R29,$P$35:$R$35)-K29} -> #REF! | P29: =(VLOOKUP(P$3,#REF!,11,0)+VLOOKUP(P$3,#REF!,12,0)+VLOOKUP(P$3,#REF!,13,0))*运营工时费报价基准!$E$15 -> #REF! | Q29: =(VLOOKUP(Q$3,#REF!,11,0)+VLOOKUP(Q$3,#REF!,12,0)+VLOOKUP(Q$3,#REF!,13,0))*运营工时费报价基准!$E$15 -> #REF! | R29: =(VLOOKUP(R$3,#REF!,11,0)+VLOOKUP(R$3,#REF!,12,0)+VLOOKUP(R$3,#REF!,13,0))*运营工时费报价基准!$E$15 -> #REF!
B30: -材料损耗 | C30: 材料*0.5% | E30: =F30*$F$5+G30*$G$5+H30*$H$5+$I$5*I30+J30*$J$5+K30*$K$5+L30*$L$5+M30*$M$5 -> #REF! | F30: =SUM(P30:R30) -> #REF! | G30: =G15*0.5% -> #REF! | H30: =H15*0.5% -> #REF! | I30: =I15*0.5% -> #REF! | J30: =J15*0.5% -> #REF! | K30: =K15*0.5% -> #REF! | N30: =(E30/$E$5)/($N$7-$E$13/$E$5) -> #REF! | O30: {=SUMPRODUCT(P30:R30,$P$35:$R$35)-K30} -> #REF! | P30: =P15*0.5% -> #REF! | Q30: =Q15*0.5% -> #REF! | R30: =R15*0.5% -> #REF!
A31: 研发费用（元/PCS） | D31: 投入费/产量 | E31: =F31*$F$5+G31*$G$5+H31*$H$5+$I$5*I31+J31*$J$5+K31*$K$5+L31*$L$5+M31*$M$5 -> #REF! | F31: =SUM(P31:R31) -> #REF! | N31: =(E31/$E$5)/($N$7-$E$13/$E$5) -> #REF! | O31: {=SUMPRODUCT(P31:R31,$P$35:$R$35)-K31} -> #REF! | P31: ='研发费用 '!$F$21*P4 -> #REF! | Q31: ='研发费用 '!$F$21*Q4 -> #REF! | R31: ='研发费用 '!$F$21*R4 -> #REF!
A32: 单套包装、物流费用（元/PCS） | D32: 投入费/产量 | E32: =F32*$F$5+G32*$G$5+H32*$H$5+$I$5*I32+J32*$J$5+K32*$K$5+L32*$L$5+M32*$M$5 -> #REF! | F32: =SUM(P32:R32) -> #REF! | G32: =F32 -> #REF! | H32: =G32 -> #REF! | I32: =H32 -> #REF! | J32: =I32 -> #REF! | K32: =J32 -> #REF! | N32: =(E32/$E$5)/($N$7-$E$13/$E$5) -> #REF! | O32: {=SUMPRODUCT(P32:R32,$P$35:$R$35)-K32} -> #REF! | P32: =VLOOKUP(P3,#REF!,12,0) -> #REF! | Q32: =VLOOKUP(Q3,#REF!,12,0) -> #REF! | R32: =VLOOKUP(R3,#REF!,12,0) -> #REF!
A34: 解释： | E34: =E5/#REF! -> #REF!
A35: 低值易耗品费：工装板、模块、辅助工具、物料盒等 | F35: 628.39 | G35: =F35*34000 -> 21365260 | H35: {=SUMPRODUCT(P6:R6,P35:R35)} -> #REF! | N35: 第一页 | O35: =设备投资明细!N43 -> 装车比 | P35: 1 | Q35: 1 | R35: 1
A36: 机物料消耗：质量检验测试、开机测试 | F36: =F35-3-9.6 -> 615.79 | G36: =F36*16000 -> 9852640 | I36: 3 | J36: 工装分摊价 | O36: =设备投资明细!N44 -> 总量纲 | P36: =$E$5 -> 240000 | Q36: =$E$5 -> 240000 | R36: =$E$5 -> 240000
A37: 其他制费：差旅费、水电费、劳保用品、备品备件等 | G37: =G36+G35 -> 31217900 | I37: 9.6 | J37: 实验费分摊价 | O37: =设备投资明细!N45 -> 数量 | P37: =P35*P36 -> 240000 | Q37: =Q35*Q36 -> 240000 | R37: =R35*R36 -> 240000
G38: =G37/54000 -> 578.10926 | I38: =H35+I36+I37 -> #REF!
A39: 删除辅助工装类→和低值易耗品重复 | P39: =P15/P6 -> #REF! | Q39: =Q15/Q6 -> #REF! | R39: =R15/R6 -> #REF!
I40: =I38*16000+H35*38000 -> #REF!
I41: =I40/G5 -> #REF!
...

Sheet 客户报价逻辑
B2: 零件号 | C2: 零件名称 | D2: 用量 | E2: 铜重 | F2: 铝重 | G2: 材料成本 （元） | H2: 废品率 （0.9%） | I2: 实际工时 | J2: 直接人工 (35元/H) | K2: 制造费 (47元/H) | L2: 人工+制造费 | M2: 管理费 (6%) | N2: 利润 | O2: 出厂价 | P2: 包装费 | Q2: 运输费 | R2: 到厂价
C3: *零件名称 | D3: *标配/选配 | E3: 铜重
B4: =#REF! -> #REF! | C4: =#REF! -> #REF! | D4: =#REF! -> #REF! | E4: =#REF! -> #REF! | F4: =#REF! -> #REF! | G4: =#REF! -> #REF! | H4: =G4*1% -> #REF! | I4: =#REF!+#REF! -> #REF! | J4: =I4*35 -> #REF! | K4: =$K$20*I4 -> #REF! | L4: =K4+J4 -> #REF! | M4: =(G4+L4)*6% -> #REF! | N4: =(L4+H4+G4)*6% -> #REF! | O4: =N4+M4+L4+G4+H4 -> #REF! | P4: =#REF!+#REF! -> #REF! | Q4: =#REF!+#REF!+#REF! -> #REF! | R4: =Q4+P4+O4 -> #REF!
B5: =#REF! -> #REF! | C5: =#REF! -> #REF! | D5: =#REF! -> #REF! | E5: =#REF! -> #REF! | F5: =#REF! -> #REF! | G5: =#REF! -> #REF! | H5: =G5*1% -> #REF! | I5: =#REF!+#REF! -> #REF! | J5: =I5*35 -> #REF! | K5: =$K$20*I5 -> #REF! | L5: =K5+J5 -> #REF! | M5: =(G5+L5)*6% -> #REF! | N5: =(L5+H5+G5)*6% -> #REF! | O5: =N5+M5+L5+G5+H5 -> #REF! | P5: =#REF!+#REF! -> #REF! | Q5: =#REF!+#REF!+#REF! -> #REF! | R5: =Q5+P5+O5 -> #REF!
B6: =#REF! -> #REF! | C6: =#REF! -> #REF! | D6: =#REF! -> #REF! | E6: =#REF! -> #REF! | F6: =#REF! -> #REF! | G6: =#REF! -> #REF! | H6: =G6*1% -> #REF! | I6: =#REF!+#REF! -> #REF! | J6: =I6*35 -> #REF! | K6: =$K$20*I6 -> #REF! | L6: =K6+J6 -> #REF! | M6: =(G6+L6)*6% -> #REF! | N6: =(L6+H6+G6)*6% -> #REF! | O6: =N6+M6+L6+G6+H6 -> #REF! | P6: =#REF!+#REF! -> #REF! | Q6: =#REF!+#REF!+#REF! -> #REF! | R6: =Q6+P6+O6 -> #REF!
B7: =#REF! -> #REF! | C7: =#REF! -> #REF! | D7: =#REF! -> #REF! | E7: =#REF! -> #REF! | F7: =#REF! -> #REF! | G7: =#REF! -> #REF! | H7: =G7*1% -> #REF! | I7: =#REF!+#REF! -> #REF! | J7: =I7*35 -> #REF! | K7: =$K$20*I7 -> #REF! | L7: =K7+J7 -> #REF! | M7: =(G7+L7)*6% -> #REF! | N7: =(L7+H7+G7)*6% -> #REF! | O7: =N7+M7+L7+G7+H7 -> #REF! | P7: =#REF!+#REF! -> #REF! | Q7: =#REF!+#REF!+#REF! -> #REF! | R7: =Q7+P7+O7 -> #REF!
B8: =#REF! -> #REF! | C8: =#REF! -> #REF! | D8: =#REF! -> #REF! | E8: =#REF! -> #REF! | F8: =#REF! -> #REF! | G8: =#REF! -> #REF! | H8: =G8*1% -> #REF! | I8: =#REF!+#REF! -> #REF! | J8: =I8*35 -> #REF! | K8: =$K$20*I8 -> #REF! | L8: =K8+J8 -> #REF! | M8: =(G8+L8)*6% -> #REF! | N8: =(L8+H8+G8)*6% -> #REF! | O8: =N8+M8+L8+G8+H8 -> #REF! | P8: =#REF!+#REF! -> #REF! | Q8: =#REF!+#REF!+#REF! -> #REF! | R8: =Q8+P8+O8 -> #REF!
B9: =#REF! -> #REF! | C9: =#REF! -> #REF! | D9: =#REF! -> #REF! | E9: =#REF! -> #REF! | F9: =#REF! -> #REF! | G9: =#REF! -> #REF! | H9: =G9*1% -> #REF! | I9: =#REF!+#REF! -> #REF! | J9: =I9*35 -> #REF! | K9: =$K$20*I9 -> #REF! | L9: =K9+J9 -> #REF! | M9: =(G9+L9)*6% -> #REF! | N9: =(L9+H9+G9)*6% -> #REF! | O9: =N9+M9+L9+G9+H9 -> #REF! | P9: =#REF!+#REF! -> #REF! | Q9: =#REF!+#REF!+#REF! -> #REF! | R9: =Q9+P9+O9 -> #REF!
B10: =#REF! -> #REF! | C10: =#REF! -> #REF! | D10: =#REF! -> #REF! | E10: =#REF! -> #REF! | F10: =#REF! -> #REF! | G10: =#REF! -> #REF! | H10: =G10*1% -> #REF! | I10: =#REF!+#REF! -> #REF! | J10: =I10*35 -> #REF! | K10: =$K$20*I10 -> #REF! | L10: =K10+J10 -> #REF! | M10: =(G10+L10)*6% -> #REF! | N10: =(L10+H10+G10)*6% -> #REF! | O10: =N10+M10+L10+G10+H10 -> #REF! | P10: =#REF!+#REF! -> #REF! | Q10: =#REF!+#REF!+#REF! -> #REF! | R10: =Q10+P10+O10 -> #REF!
B11: =#REF! -> #REF! | C11: =#REF! -> #REF! | D11: =#REF! -> #REF! | E11: =#REF! -> #REF! | F11: =#REF! -> #REF! | G11: =#REF! -> #REF! | H11: =G11*1% -> #REF! | I11: =#REF!+#REF! -> #REF! | J11: =I11*35 -> #REF! | K11: =$K$20*I11 -> #REF! | L11: =K11+J11 -> #REF! | M11: =(G11+L11)*6% -> #REF! | N11: =(L11+H11+G11)*6% -> #REF! | O11: =N11+M11+L11+G11+H11 -> #REF! | P11: =#REF!+#REF! -> #REF! | Q11: =#REF!+#REF!+#REF! -> #REF! | R11: =Q11+P11+O11 -> #REF!
B12: =#REF! -> #REF! | C12: =#REF! -> #REF! | D12: =#REF! -> #REF! | E12: =#REF! -> #REF! | F12: =#REF! -> #REF! | G12: =#REF! -> #REF! | H12: =G12*1% -> #REF! | I12: =#REF!+#REF! -> #REF! | J12: =I12*35 -> #REF! | K12: =$K$20*I12 -> #REF! | L12: =K12+J12 -> #REF! | M12: =(G12+L12)*6% -> #REF! | N12: =(L12+H12+G12)*6% -> #REF! | O12: =N12+M12+L12+G12+H12 -> #REF! | P12: =#REF!+#REF! -> #REF! | Q12: =#REF!+#REF!+#REF! -> #REF! | R12: =Q12+P12+O12 -> #REF!
B13: =#REF! -> #REF! | C13: =#REF! -> #REF! | D13: =#REF! -> #REF! | E13: =#REF! -> #REF! | F13: =#REF! -> #REF! | G13: =#REF! -> #REF! | H13: =G13*1% -> #REF! | I13: =#REF!+#REF! -> #REF! | J13: =I13*35 -> #REF! | K13: =$K$20*I13 -> #REF! | L13: =K13+J13 -> #REF! | M13: =(G13+L13)*6% -> #REF! | N13: =(L13+H13+G13)*6% -> #REF! | O13: =N13+M13+L13+G13+H13 -> #REF! | P13: =#REF!+#REF! -> #REF! | Q13: =#REF!+#REF!+#REF! -> #REF! | R13: =Q13+P13+O13 -> #REF!
B14: =#REF! -> #REF! | C14: =#REF! -> #REF! | D14: =#REF! -> #REF! | E14: =#REF! -> #REF! | F14: =#REF! -> #REF! | G14: =#REF! -> #REF! | H14: =G14*1% -> #REF! | I14: =#REF!+#REF! -> #REF! | J14: =I14*35 -> #REF! | K14: =$K$20*I14 -> #REF! | L14: =K14+J14 -> #REF! | M14: =(G14+L14)*6% -> #REF! | N14: =(L14+H14+G14)*6% -> #REF! | O14: =N14+M14+L14+G14+H14 -> #REF! | P14: =#REF!+#REF! -> #REF! | Q14: =#REF!+#REF!+#REF! -> #REF! | R14: =Q14+P14+O14 -> #REF!
B17: 装车比 | E17: {=SUMPRODUCT($D$4:$D$14,E4:E14)} -> #REF! | F17: {=SUMPRODUCT($D$4:$D$14,F4:F14)} -> #REF! | G17: {=SUMPRODUCT($D$4:$D$14,G4:G14)} -> #REF! | H17: {=SUMPRODUCT($D$4:$D$14,H4:H14)} -> #REF! | I17: {=SUMPRODUCT($D$4:$D$14,I4:I14)} -> #REF! | J17: {=SUMPRODUCT($D$4:$D$14,J4:J14)} -> #REF! | K17: {=SUMPRODUCT($D$4:$D$14,K4:K14)} -> #REF! | L17: {=SUMPRODUCT($D$4:$D$14,L4:L14)} -> #REF! | ... R17: {=SUMPRODUCT($D$4:$D$14,R4:R14)} -> #REF!
R19: =#REF! -> #REF!
K20: =37.36-1.25+0.27+11.52-1.38+0.17 -> 46.69

Sheet 运营工时费报价基准
B2: 1、运营工时费 25年1-6月 基准
B4: 区分 元/h | D4: K1K2工厂 | E4: K3工厂 | F4: 宁波工厂 | G4: 仪征工厂 | H4: 重庆工厂 低压 | I4: 重庆工厂 高压 | J4: 天津工厂
B5: 直接人工-出勤工时 | D5: 28.606853 | E5: =E8 -> 26.272887 | F5: 26.76716 | G5: 28.169428 | H5: 31.176795 | I5: 32.034397 | J5: 27.711746 | L5: 效率 | M5: =工厂效率!D17 -> 0.9
C6: -前工程效率-开线 元/h | D6: 30.198448 | G6: 28.028971 | H6: 34.195473
C7: -前工程效率 - 公共制程 元/h | D7: 28.188328 | G7: 27.662417 | H7: 30.866301
C8: -后工程 - 总装 元/h | D8: 28.580082 | E8: 26.272887 | F8: 26.76716 | G8: 32.856511 | H8: 31.038701 | I8: 32.034397 | J8: 27.711746
B9: 制造费用 | D9: 16.14+损耗 | E9: 15.17+损耗 | F9: 20.32+损耗 | G9: 15.13+损耗 | H9: 15.81+损耗 | I9: 23.46+损耗 | J9: 16.22+损耗
C10: -间接人工 元/h | D10: 8.4990788 | E10: 6.4740149 | F10: 9.45 （16.16） | G10: 10.393806 | H10: 9.748783 | I10: 11.162784 | J10: 8.8160737
C11: -低值易耗品费 元/h | D11: 0.87635407 | E11: 0.51020354 | F11: 0.41150703 | G11: 0.79522147 | H11: 2.1303395 | I11: 2.8080612 | J11: 0.51 （0.23）
C12: -机物料消耗 元/h | D12: 1.8562976 | E12: 2.4050903 | F12: 1.0939274 | G12: 0.69071852 | H12: 0.98154286 | I12: 4.9691472 | J12: 2.41 （0.11）
C13: -厂房分摊 元/h | D13: 1.45 | E13: 3.8633819 | F13: 3.2642647 | G13: 0.6107946 | H13: 1.0053462 | I13: 2.7842904 | J13: 2.9830898
C14: -自动化仓、仓库分摊 元/h | D14: 2.03 | E14: 0.24234344 | F14: 2.4354479 | G14: 0.51592727 | H14: 0.89453553 | I14: 0.89939771 | J14: 0
C15: -其他制费 元/h | D15: 1.423375 | E15: 1.6713103 | F15: 3.6629747 | G15: 2.1267819 | H15: 1.0477841 | I15: 0.83737698 | J15: 1.4978537
C16: -材料损耗 材料*0.5% | D16: 材料*0.5% | E16: 材料*0.5% | F16: 材料*0.5% | G16: 材料*0.5% | H16: 材料*0.5% | I16: 材料*0.5% | J16: 材料*0.5%
B18: 宁波工厂-间接人工 ：因产值低，按照昆山低压与仪征平均取数
B19: 天津工厂-低值易耗+机物料消耗 ：项目前期使用昆山高压物料，按照昆山高压取数
B20: K1K2工厂-厂房、自动化仓库摊销：25年1-6月产能不足，数据参考25年下半年预算

Sheet 工厂效率
B2: ● 25年报价效率：昆山低压、宁波、仪征、天津、重庆低压
B4: 总工时 | C4: 项目节拍 PCS/h | G4: 描述
C5: ≤5 | D5: 5~10 | E5: 10~20 | F5: ＞20
B6: ≤4h | C6: 0.9 | D6: 0.95 | E6: 1 | F6: 1.05 | G6: 单回路工时＞42S
B7: 4h~20h | C7: 0.85 | D7: 0.9 | E7: 0.95 | F7: 1
B8: ＞20h | C8: 0.8 | D8: 0.85 | E8: 0.9 | F8: 0.95
B9: ≤4h | C9: 0.85 | D9: 0.9 | E9: 0.95 | F9: 1 | G9: 单回路工时＜42S
B10: 4h~20h | C10: 0.8 | D10: 0.85 | E10: 0.9 | F10: 0.95
B11: ＞20h | C11: 0.75 | D11: 0.8 | E11: 0.85 | F11: 0.9
B14: ● 25年报价效率：昆山高压、天津高压、重庆高压
B16: 项目节拍 PCS/h | C16: ≤10 | D16: 10~20 | E16: >20 | F16: 描述
B17: 2025报价LE | C17: 0.85 | D17: 0.9 | E17: 0.95 | F17: 单班JPH效率

Sheet 设备投资明细
A1: =#REF! -> #REF! | Q1: 1 | R1: 2 | S1: 3 | T1: 4 | U1: 5 | V1: 6 | W1: 7 | X1: 8 | Y1: 9 | Z1: 10 | AA1: 11
A2: 一、公用设备投入（前工程） | G2: 需求资产 | I2: 剩余资产 | K2: 新增资产 | M2: 单价 （标准件-财务； 非标件-申购部门） | N2: 备注 | O2: 适用范围 | P2: 供应商 | Q2: {=TRANSPOSE(#REF!)} -> #REF!
A3: 编号 | B3: 归属 | C3: 项目投资名称 | D3: 设备名称 | E3: 工艺报价参考规格型号 | F3: 单位 | G3: 数量 | H3: 金额 | I3: 数量 | J3: 金额 | K3: 数量 | L3: 金额
A4: A0001 | B4: 公用设备类 | C4: 开线 | D4: 全自动开线机/Kappa350 | E4: Kappa350 | F4: 台 | G4: =SUM(Q4:AA4) -> 1.4387566 | K4: =G4-I4 -> 1.4387566 | L4: =K4*M4 -> 1122230.2 | M4: 780000 | Q4: 0.1916336 | R4: 0.03832672 | S4: 0.025551146 | T4: 0.041335979 | U4: 0.12480159 | V4: 0.02202381 | W4: 0.04356261 | X4: 0.32671958 | Y4: 0.46709656 | Z4: 0.093419312 | AA4: 0.064285714
A5: A0001 | B5: 公用设备类 | C5: 开线 | D5: 全自动开线压接机/Alpha550 | E5: Alpha550 | F5: 台 | G5: =SUM(Q5:AA5) -> 0.47222222 | K5: =G5-I5 -> 0.47222222 | L5: =K5*M5 -> 576696.17 | M5: 1221238.9 | Y5: 0.35416667 | Z5: 0.070833333 | AA5: 0.047222222
A6: A0001 | B6: 公用设备类 | C6: 喷码 | D6: 激光打标机/UV-3S | E6: UV-3S | F6: 台 | G6: =SUM(Q6:AA6) -> 0.41893739 | K6: =G6-I6 -> 0.41893739 | L6: =K6*M6 -> 51283.714 | M6: 122413.79 | Q6: 0.14351852 | R6: 0.028703704 | S6: 0.019135802 | T6: 0.028703704 | Y6: 0.14864418 | Z6: 0.029728836 | AA6: 0.020502646
A7: A0001 | B7: 公用设备类 | C7: 焊接 | D7: 焊接机/国产机定制 | E7: 国产机定制 | F7: 台 | G7: =SUM(Q7:AA7) -> 3 | K7: 1 | L7: =K7*M7 -> 900000 | M7: 900000 | N7: 二季度投入 | O7: 焊120铝（安奕吉 HVW-12/骄成 WL-B-AH9994-F） | Y7: 2.25 | Z7: 0.45 | AA7: 0.3
A8: A0001 | B8: 公用设备类 | C8: 焊接 | D8: 焊接机/国产机定制 | E8: 国产机定制 | F8: 台 | G8: =SUM(Q8:AA8) -> 2 | K8: 0 | L8: =K8*M8 -> 0 | M8: 300000 | O8: 焊50铝（安奕吉 HVW-6/骄成 WD-AH9940-F） | Q8: 1.3043478 | R8: 0.26086957 | S8: 0.17391304 | T8: 0.26086957
A9: A0001 | B9: 公用设备类 | C9: 焊接 | D9: 焊接机/国产机定制 | E9: 国产机定制 | F9: 台 | G9: =SUM(Q9:AA9) -> 6 | K9: 3 | L9: =K9*M9 -> 1050000 | M9: 350000 | N9: 二季度投入 | O9: 焊4方/6方铝（安奕吉 HVW-4/ WS-PH9810-F） | U9: 0.85 | V9: 0.15 | W9: 0.35294118 | X9: 2.6470588 | Y9: 1.5 | Z9: 0.3 | AA9: 0.2
A10: A0001 | B10: 公用设备类 | C10: 焊接 | D10: 焊接机/国产机定制 | E10: 国产机定制 | F10: 台 | G10: =SUM(Q10:AA10) -> 1 | K10: 0 | L10: =K10*M10 -> 0 | M10: 230000 | O10: 并线焊（安奕吉 AW-4/骄成 WE-AH9810-L） | W10: 0.11764706 | X10: 0.88235294
A11: A0001 | B11: 公用设备类 | C11: 压接 | D11: 大平方压接机/XYD-30T | E11: XYD-30T | F11: 台 | G11: =SUM(Q11:AA11) -> 2 | K11: 0 | L11: =K11*M11 -> 0 | M11: 69000 | Q11: 1.3043478 | R11: 0.26086957 | S11: 0.17391304 | T11: 0.26086957
A12: A0001 | B12: 公用设备类 | C12: 压接 | D12: 小平方压接机-伺服/XYD-4T | E12: XYD-4T | F12: 台 | G12: =SUM(Q12:AA12) -> 6 | K12: 0 | L12: =K12*M12 -> 0 | M12: 10800 | U12: 0.85 | V12: 0.15 | W12: 0.35294118 | X12: 2.6470588 | Y12: 1.5 | Z12: 0.3 | AA12: 0.2
A13: A0001 | B13: 公用设备类 | C13: 压力监控仪 | D13: 压力监控仪/Qpex | E13: Qpex | F13: 个 | G13: =SUM(Q13:AA13) -> 2 | K13: 0 | L13: =K13*M13 -> 0 | M13: 21900 | Y13: 1.5 | Z13: 0.3 | AA13: 0.2
A14: A0001 | B14: 公用设备类 | C14: 去绝缘皮 | D14: 切剥翻一体机/定制2.5mm²-25mm² | E14: 定制2.5mm²-25mm² | F14: 台 | G14: =SUM(Q14:AA14) -> 5 | K14: 0 | L14: =K14*M14 -> 0 | M14: 130000 | U14: 1.7 | V14: 0.3 | W14: 0.35294118 | X14: 2.6470588
A15: A0001 | B15: 公用设备类 | C15: 去绝缘皮 | D15: 切剥翻一体机/定制25mm²-70mm² | E15: 定制25mm²-70mm² | F15: 台 | G15: =SUM(Q15:AA15) -> 2 | K15: 0 | L15: =K15*M15 -> 0 | M15: 130000 | Q15: 1.3043478 | R15: 0.26086957 | S15: 0.17391304 | T15: 0.26086957
A16: A0001 | B16: 公用设备类 | C16: 检测设备 | D16: 高压&气密检测/定制 | E16: 定制 | F16: 台 | G16: =SUM(Q16:AA16) -> 9 | K16: 1 | L16: =K16*M16 -> 110000 | M16: 110000 | N16: 二季度投入 | O16: 高压测试台需具备检测端子到位功能 | Q16: 1.3043478 | R16: 0.26086957 | S16: 0.17391304 | T16: 0.26086957 | U16: 1.7 | V16: 0.3 | W16: 0.23529412 | X16: 1.7647059 | Y16: 2.25 | Z16: 0.45 | AA16: 0.3
A17: A0001 | B17: 公用设备类 | C17: 检测设备 | D17: 高压&气密检测/定制 | E17: 定制 | F17: 台 | G17: =SUM(Q17:AA17) -> 9 | K17: 1 | L17: =K17*M17 -> 85500 | M17: 85500 | N17: 改制1台 CGSQ-X-202600550 6400005255 | O17: 高压测试台需具备检测端子到位功能 | Q17: 1.3043478 | R17: 0.26086957 | S17: 0.17391304 | T17: 0.26086957 | U17: 1.7 | V17: 0.3 | W17: 0.23529412 | X17: 1.7647059 | Y17: 2.25 | Z17: 0.45 | AA17: 0.3
A18: A0001 | B18: 公用设备类 | C18: 检测设备 | D18: 气密检测/定制 | E18: 定制 | F18: 台 | G18: =SUM(Q18:AA18) -> 1 | K18: 0 | L18: =K18*M18 -> 0 | M18: 300000 | O18: 含模块 | Y18: 0.75 | Z18: 0.15 | AA18: 0.1
A19: A0001 | B19: 公用设备类 | C19: 扭力台 | D19: 扭力站/ST-HG-SCR | E19: ST-HG-SCR | F19: 台 | G19: =SUM(Q19:AA19) -> 3 | K19: 2 | L19: =K19*M19 -> 288000 | M19: 144000 | N19: 二季度投入 | Y19: 2.25 | Z19: 0.45 | AA19: 0.3
A20: A0001 | B20: 公用设备类 | C20: 热缩 | D20: 热缩机/UX1804 | E20: UX1804 | F20: 台 | G20: =SUM(Q20:AA20) -> 1 | K20: 0 | L20: =K20*M20 -> 0 | M20: 50000 | O20: 公共制程 | Q20: 0.32608696 | R20: 0.065217391 | S20: 0.043478261 | T20: 0.065217391 | Y20: 0.375 | Z20: 0.075 | AA20: 0.05
A21: A0001 | B21: 公用设备类 | C21: 热缩 | D21: 履带式热缩机/XB19 | E21: XB19 | F21: 台 | G21: =SUM(Q21:AA21) -> 0.31593915 | K21: =G21-I21 -> 0.31593915 | L21: =K21*M21 -> 23927.652 | M21: 75735 | W21: 0.037169312 | X21: 0.27876984
A22: A0001 | B22: 公用设备类 | C22: 剥头 | D22: 剥头机/Mira340 | F22: 台 | G22: =SUM(Q22:AA22) -> 0.24459877 | K22: =G22-I22 -> 0.24459877 | L22: =K22*M22 -> 13213.228 | M22: 54020.01 | O22: Mira340，剥10mm²以下，公共制程 | Y22: 0.18344907 | Z22: 0.036689815 | AA22: 0.024459877
A23: A0001 | B23: 公用设备类 | C23: 剥头 | D23: 剥头机/银钢WG-8023C | F23: 台 | G23: =SUM(Q23:AA23) -> 0.40828924 | K23: =G23-I23 -> 0.40828924 | L23: =K23*M23 -> 20414.462 | M23: 50000 | Y23: 0.30621693 | Z23: 0.061243386 | AA23: 0.040828924
A24: A0001 | B24: 公用设备类 | C24: 绞线 | D24: 绞线机/BT88D | F24: 台 | G24: =SUM(Q24:AA24) -> 0.14770723 | K24: =G24-I24 -> 0.14770723 | L24: =K24*M24 -> 12159.259 | M24: 82320 | Y24: 0.11078042 | Z24: 0.022156085 | AA24: 0.014770723
G31: 合计 | H31: =SUM(L4:L30) -> 4253424.6 | J31: 单套费用 | K31: =H31/10*6/#REF! -> #REF! | Q31: {=SUMPRODUCT(Q4:Q29,$M$4:$M$29)/10*6/Q45} -> #REF! | R31: {=SUMPRODUCT(R4:R29,$M$4:$M$29)/10*6/R45} -> #REF! | S31: {=SUMPRODUCT(S4:S29,$M$4:$M$29)/10*6/S45} -> #REF! | T31: {=SUMPRODUCT(T4:T29,$M$4:$M$29)/10*6/T45} -> #REF! | U31: {=SUMPRODUCT(U4:U29,$M$4:$M$29)/10*6/U45} -> #REF! | V31: {=SUMPRODUCT(V4:V29,$M$4:$M$29)/10*6/V45} -> #REF! | W31: {=SUMPRODUCT(W4:W29,$M$4:$M$29)/10*6/W45} -> #REF! | X31: {=SUMPRODUCT(X4:X29,$M$4:$M$29)/10*6/X45} -> #REF! | ... AA31: {=SUMPRODUCT(AA4:AA29,$M$4:$M$29)/10*6/AA45} -> #REF!
A32: 二、专用设备投入（后工程）
A33: B0001 | B33: 专用设备 | C33: 高压气密测试模块 | D33: 高压气密测试模块/定制 | E33: 定制 | F33: 个 | G33: =SUM(Q33:AA33) -> 35 | K33: 5 | L33: =K33*M33 -> 23000 | M33: 4600 | N33: CGSQ-X-202600502 询价中，暂未生成采购订单号 | O33: 充电座的需增加插拔次数监控功能 | Q33: 2.6086957 | R33: 0.52173913 | S33: 0.34782609 | T33: 0.52173913 | U33: 3.4 | V33: 0.6 | W33: 0.70588235 | X33: 5.2941176 | Y33: 15.75 | Z33: 3.15 | AA33: 2.1
A34: B0001 | B34: 专用设备 | C34: 卡钉台 | D34: 卡钉测试台/中（20≤模块数≥11） | E34: 中（20≤模块数≥11） | F34: 个 | G34: =SUM(Q34:AA34) -> 2 | K34: 1 | L34: =K34*M34 -> 23500 | M34: 23500 | N34: 仅新购21个模块 CGSQ-X-202600983 财务部长处，暂未生成采购订单号 | Y34: 1.5 | Z34: 0.3 | AA34: 0.2
A35: B0001 | B35: 专用设备 | C35: CCD检查机 | D35: CCD检查机/定制 | E35: 定制 | F35: 个 | G35: =SUM(Q35:AA35) -> 7 | K35: 0 | L35: =K35*M35 -> 0 | M35: 150000 | O35: 压接机（压端子）&焊接机有CCD检查 | Q35: 0.65217391 | R35: 0.13043478 | S35: 0.086956522 | T35: 0.13043478 | U35: 0.85 | V35: 0.15 | W35: 0.23529412 | X35: 1.7647059 | Y35: 2.25 | Z35: 0.45 | AA35: 0.3
K36: =G36-I36 -> 0 | L36: =K36*M36 -> 0
F39: pc | K39: =G39-I39 -> 0 | L39: =K39*M39 -> 0
G41: 合计 | H41: =SUM(L33:L40) -> 46500 | I41: 单套费用 | J41: =H41/#REF! -> #REF! | Q41: {=SUMPRODUCT(Q33:Q39,$M$33:$M$39)/Q45} -> #REF! | R41: {=SUMPRODUCT(R33:R39,$M$33:$M$39)/R45} -> #REF! | S41: {=SUMPRODUCT(S33:S39,$M$33:$M$39)/S45} -> #REF! | T41: {=SUMPRODUCT(T33:T39,$M$33:$M$39)/T45} -> #REF! | U41: {=SUMPRODUCT(U33:U39,$M$33:$M$39)/U45} -> #REF! | V41: {=SUMPRODUCT(V33:V39,$M$33:$M$39)/V45} -> #REF! | W41: {=SUMPRODUCT(W33:W39,$M$33:$M$39)/W45} -> #REF! | X41: {=SUMPRODUCT(X33:X39,$M$33:$M$39)/X45} -> #REF! | ... AA41: {=SUMPRODUCT(AA33:AA39,$M$33:$M$39)/AA45} -> #REF!
M43: 第二页 | N43: 装车比 | Q43: =#REF! -> #REF! | R43: =#REF! -> #REF! | S43: =#REF! -> #REF! | T43: =#REF! -> #REF! | U43: =#REF! -> #REF! | V43: =#REF! -> #REF! | W43: =#REF! -> #REF! | X43: =#REF! -> #REF! | ... AA43: =#REF! -> #REF!
N44: 总量纲 | Q44: =#REF! -> #REF! | R44: =#REF! -> #REF! | S44: =#REF! -> #REF! | T44: =#REF! -> #REF! | U44: =#REF! -> #REF! | V44: =#REF! -> #REF! | W44: =#REF! -> #REF! | X44: =#REF! -> #REF! | ... AA44: =#REF! -> #REF!
A45: 填写说明： | N45: 数量 | Q45: =Q44*Q43 -> #REF! | R45: =R44*R43 -> #REF! | S45: =S44*S43 -> #REF! | T45: =T44*T43 -> #REF! | U45: =U44*U43 -> #REF! | V45: =V44*V43 -> #REF! | W45: =W44*W43 -> #REF! | X45: =X44*X43 -> #REF! | ... AA45: =AA44*AA43 -> #REF!
A46: 1. 涉及自动化产线投资金额，自动化产线-公用件占比全产线金额的80%；自动化产线-专用件占比全产线金额的20%；
A47: 2. 涉及自动化产线需在备注列维护内容：a.公共部分占比自动化设备费用80%； 2、xx平参考设备尺寸：xxm*xxm*xxm； 3、涉及工序：开线，剥皮，去屏蔽层，预装；压接屏蔽环；压接端子；装塑壳；插位；
A48: 3. 如果项目设备/项目专用模具/项目工装投入表格中涉及新增内容在下拉箭头中无法选中，通知设备工程师至W:\昆山泽轩\动能工业中心\前期工艺部\04-前期设备中“泽轩设备数据库信息”中添加新增设备信息； | Q48: =Q41+项目专用模具!O14+'项目工装投入 '!O15 -> #REF! | R48: =R41+项目专用模具!P14+'项目工装投入 '!P15 -> #REF! | S48: =S41+项目专用模具!Q14+'项目工装投入 '!Q15 -> #REF! | T48: =T41+项目专用模具!R14+'项目工装投入 '!R15 -> #REF! | U48: =U41+项目专用模具!S14+'项目工装投入 '!S15 -> #REF! | V48: =V41+项目专用模具!T14+'项目工装投入 '!T15 -> #REF! | W48: =W41+项目专用模具!U14+'项目工装投入 '!U15 -> #REF! | X48: =X41+项目专用模具!V14+'项目工装投入 '!V15 -> #REF! | ... AA48: =AA41+项目专用模具!Y14+'项目工装投入 '!Y15 -> #REF!
O49: {=SUMPRODUCT(Q41:AA41,Q43:AA43)} -> #REF!

Sheet 项目专用模具
A1: =#REF! -> #REF! | O1: 1 | P1: 2 | Q1: 3 | R1: 4 | S1: 5 | T1: 6 | U1: 7 | V1: 8 | W1: 9 | X1: 10 | Y1: 11
A2: 专用模具投入 | G2: 需求模具（元） | I2: 沿用模具（元） | K2: 新增模具（元） | M2: 备 注 | N2: 单价 | O2: 6608491523 | P2: 6608491524 | Q2: 6608442962 | R2: 6608544875 | S2: 6608442964 | T2: 6608519100 | U2: 6608442963 | V2: 6608516992 | W2: 6608442966 | X2: 6608442965 | Y2: 6608507680
A3: 编号 | B3: 归属 | C3: 项目投资名称 | D3: 名称 | E3: 型号 | F3: 单位 | G3: 需求数量 | H3: 需求金额 | I3: 沿用数量 | J3: 沿用金额 | K3: 新增数量 | L3: 新增金额 | M3: 设备按生命周期量核算模具的数量(低压模具20万次；高压模具5万次；防水栓模具无限制生命周期)
A4: C0001 | B4: 模具类 | C4: 模具/模块/治具 | D4: 压接模具/大模具（50行程） | E4: 大模具（50行程） | F4: 个 | G4: =SUM(O4:Y4) -> 2 | K4: 4 | L4: =K4*N4 -> 30000 | M4: CGSQ-X-202600379 6400005186 | N4: 7500 | O4: 1.3043478 | P4: 0.26086957 | Q4: 0.17391304 | R4: 0.26086957
A5: C0001 | B5: 模具类 | C5: 模具/模块/治具 | D5: 压接模具/小模具（40行程） | E5: 小模具（40行程） | F5: 个 | G5: =SUM(O5:Y5) -> 15 | K5: 5 | L5: =K5*N5 -> 17250 | N5: 3450 | S5: 2.55 | T5: 0.45 | U5: 0.70588235 | V5: 5.2941176 | W5: 4.5 | X5: 0.9 | Y5: 0.6
A6: C0001 | B6: 模具类 | C6: 模具/模块/治具 | D6: 压接模具/小模具（40行程） | E6: 小模具（40行程） | F6: 个 | G6: =SUM(O6:Y6) -> 15 | K6: 4 | L6: =K6*N6 -> 4400 | M6: 压接模具改制 CGSQ-X-202600537 6300022537 | N6: 1100 | S6: 2.55 | T6: 0.45 | U6: 0.70588235 | V6: 5.2941176 | W6: 4.5 | X6: 0.9 | Y6: 0.6
A7: C0001 | B7: 模具类 | C7: 模具/模块/治具 | D7: 焊接治具/焊接治具 | E7: 焊接治具 | F7: 个 | G7: =SUM(O7:Y7) -> 7 | K7: 4 | L7: =K7*N7 -> 104000 | M7: CGSQ-X-202600539 6400005221 6400005219 | N7: =104000/4 -> 26000 | S7: 1 | T7: 1 | U7: 0.35294118 | V7: 2.6470588 | W7: 1.5 | X7: 0.3 | Y7: 0.2
A8: C0001 | B8: 模具类 | C8: 模具/模块/治具 | D8: 4mm²切剥翻导管 | E8: - | F8: 个 | G8: 2 | K8: 2 | L8: =K8*N8 -> 3600 | M8: CGSQ-X-202600786 6300023078 | N8: 1800 | W8: 3 | X8: 0.6 | Y8: 0.4
A9: C0001 | B9: 模具类 | C9: 模具/模块/治具 | D9: 防水栓模具 | E9: - | F9: 个 | G9: =SUM(O9:Y9) -> 4 | K9: 2 | L9: =K9*N9 -> 56000 | M9: 二季度投入 | N9: 28000 | W9: 3 | X9: 0.6 | Y9: 0.4
A10: C0001 | B10: 模具类 | C10: 模具/模块/治具 | D10: 热缩治具/ | F10: 个 | G10: =SUM(O10:Y10) -> 2 | K10: 0 | L10: =K10*N10 -> 0 | N10: 2000 | U10: 0.11764706 | V10: 0.88235294 | W10: 0.33333333 | X10: 0.33333333 | Y10: 0.33333333
A11: C0001 | B11: 模具类 | C11: 模具/模块/治具 | D11: 扭力站固定模具/ | F11: 个 | G11: =SUM(O11:Y11) -> 9 | K11: 0 | L11: =K11*N11 -> 0 | N11: 38000 | W11: 6.75 | X11: 1.35 | Y11: 0.9
K12: =G12-I12 -> 0
L14: =SUM(L4:L13) -> 215250 | O14: {=SUMPRODUCT(O4:O13,$N$4:$N$13)/O18} -> #REF! | P14: {=SUMPRODUCT(P4:P13,$N$4:$N$13)/P18} -> #REF! | Q14: {=SUMPRODUCT(Q4:Q13,$N$4:$N$13)/Q18} -> #REF! | R14: {=SUMPRODUCT(R4:R13,$N$4:$N$13)/R18} -> #REF! | S14: {=SUMPRODUCT(S4:S13,$N$4:$N$13)/S18} -> #REF! | T14: {=SUMPRODUCT(T4:T13,$N$4:$N$13)/T18} -> #REF! | U14: {=SUMPRODUCT(U4:U13,$N$4:$N$13)/U18} -> #REF! | V14: {=SUMPRODUCT(V4:V13,$N$4:$N$13)/V18} -> #REF! | ... Y14: {=SUMPRODUCT(Y4:Y13,$N$4:$N$13)/Y18} -> #REF!
K15: 单套费用 | L15: =L14/#REF! -> #REF!
L16: 第三页 | N16: =设备投资明细!N43 -> 装车比 | O16: =#REF! -> #REF! | P16: =设备投资明细!R43 -> #REF! | Q16: =设备投资明细!S43 -> #REF! | R16: =设备投资明细!T43 -> #REF! | S16: =设备投资明细!U43 -> #REF! | T16: =设备投资明细!V43 -> #REF! | U16: =设备投资明细!W43 -> #REF! | V16: =设备投资明细!X43 -> #REF! | W16: =设备投资明细!Y43 -> #REF! | ... Y16: =设备投资明细!AA43 -> #REF!
N17: =设备投资明细!N44 -> 总量纲 | O17: =#REF! -> #REF! | P17: =设备投资明细!R44 -> #REF! | Q17: =设备投资明细!S44 -> #REF! | R17: =设备投资明细!T44 -> #REF! | S17: =设备投资明细!U44 -> #REF! | T17: =设备投资明细!V44 -> #REF! | U17: =设备投资明细!W44 -> #REF! | V17: =设备投资明细!X44 -> #REF! | W17: =设备投资明细!Y44 -> #REF! | ... Y17: =设备投资明细!AA44 -> #REF!
N18: =设备投资明细!N45 -> 数量 | O18: =O16*O17 -> #REF! | P18: =P16*P17 -> #REF! | Q18: =Q16*Q17 -> #REF! | R18: =R16*R17 -> #REF! | S18: =S16*S17 -> #REF! | T18: =T16*T17 -> #REF! | U18: =U16*U17 -> #REF! | V18: =V16*V17 -> #REF! | ... Y18: =Y16*Y17 -> #REF!
M20: {=SUMPRODUCT(O14:Y14,O16:Y16)} -> #REF!
A21: 说明：模具，夹具，模块

Sheet 项目工装投入 
A1: =#REF! -> #REF! | O1: 1 | P1: 2 | Q1: 3 | R1: 4 | S1: 5 | T1: 6 | U1: 7 | V1: 8 | W1: 9 | X1: 10 | Y1: 11
A2: 新增工装投入 | G2: 需求工装（元） | I2: 沿用工装（元） | K2: 新增工装（元） | M2: 备 注 | N2: 单价 | O2: 6608491523 | P2: 6608491524 | Q2: 6608442962 | R2: 6608544875 | S2: 6608442964 | T2: 6608519100 | U2: 6608442963 | V2: 6608516992 | W2: 6608442966 | X2: 6608442965 | Y2: 6608507680
A3: 编号 | B3: 归属 | C3: 项目投资名称 | D3: 名称 | E3: 规格型号 | F3: 单位 | G3: 需求数量 | H3: 需求金额 | I3: 沿用数量 | J3: 沿用金额 | K3: 预估/实际数量 | L3: 预估/实际金额
A4: D0001 | B4: 工装类 | C4: 电脑 | D4: 电脑/一体机 | E4: 一体机 | F4: 台 | G4: =SUM(O4:Y4) -> 64 | K4: 18 | L4: =N4*K4 -> 75600 | N4: 4200 | O4: 8.4782609 | P4: 1.6956522 | Q4: 1.1304348 | R4: 1.6956522 | S4: 6.8 | T4: 1.2 | U4: 2.2352941 | V4: 16.764706 | W4: 18 | X4: 3.6 | Y4: 2.4
A5: D0001 | B5: 工装类 | C5: 辅助工装 | D5: 气动辅助工装/定制 | E5: 定制 | F5: 个 | G5: =SUM(O5:Y5) -> 9 | K5: 0 | L5: =N5*K5 -> 0 | N5: 40000 | O5: 0.65217391 | P5: 0.13043478 | Q5: 0.086956522 | R5: 0.13043478 | S5: 0.85 | T5: 0.15 | U5: 0.35294118 | V5: 2.6470588 | W5: 3 | X5: 0.6 | Y5: 0.4
A6: D0001 | B6: 工装类 | C6: 辅助工装 | D6: 插位回拉工装/定制 | E6: QDKZQ | F6: 个 | G6: =SUM(O6:Y6) -> 9 | K6: 0 | L6: =N6*K6 -> 0 | N6: 40000 | O6: 0.65217391 | P6: 0.13043478 | Q6: 0.086956522 | R6: 0.13043478 | S6: 0.85 | T6: 0.15 | U6: 0.35294118 | V6: 2.6470588 | W6: 3 | X6: 0.6 | Y6: 0.4
A7: D0001 | B7: 工装类 | C7: 辅助工装 | D7: 插位诱导工装/定制 | E7: 定制 | F7: 个 | G7: =SUM(O7:Y7) -> 0 | K7: =G7-I7 -> 0 | L7: =N7*K7 -> 0
A8: D0001 | B8: 工装类 | C8: 辅助工装 | D8: 插拔力测试工装/定制 | E8: 定制 | F8: 个 | G8: =SUM(O8:Y8) -> 1 | K8: =G8-I8 -> 1 | L8: =N8*K8 -> 4000 | M8: 验证3D打印可行性中，预计投入工装模块 | N8: 4000 | W8: 0.75 | X8: 0.15 | Y8: 0.1
A9: D0001 | B9: 工装类 | C9: 辅助工装 | D9: 焊接机侧推工装/定制 | E9: 定制 | F9: 个 | G9: =SUM(O9:Y9) -> 8 | K9: 0 | L9: =N9*K9 -> 0 | N9: 32000 | O9: 1.3043478 | P9: 0.26086957 | Q9: 0.17391304 | R9: 0.26086957 | S9: 0.85 | T9: 0.15 | W9: 3.75 | X9: 0.75 | Y9: 0.5
A10: D0001 | B10: 工装类 | C10: 扭力检测仪 | D10: 扭力检测仪/- | F10: 个 | G10: =SUM(O10:Y10) -> 1 | K10: 0 | L10: =N10*K10 -> 0 | N10: 32000 | W10: 0.75 | X10: 0.15 | Y10: 0.1
A11: D0001 | B11: 工装类 | C11: 辅助工装 | D11: 橡胶件气动扩张钳/QDKZQ | G11: =SUM(O11:Y11) -> 1 | K11: 0 | L11: =N11*K11 -> 0 | N11: 1000 | W11: 0.75 | X11: 0.15 | Y11: 0.1
G12: =SUM(O12:Y12) -> 0
K15: 合计 | L15: {=SUMPRODUCT(G4:G12,N4:N12)} -> 1281800 | O15: {=SUMPRODUCT(O4:O10,$N$4:$N$10)/O19} -> #REF! | P15: {=SUMPRODUCT(P4:P10,$N$4:$N$10)/P19} -> #REF! | Q15: {=SUMPRODUCT(Q4:Q10,$N$4:$N$10)/Q19} -> #REF! | R15: {=SUMPRODUCT(R4:R10,$N$4:$N$10)/R19} -> #REF! | S15: {=SUMPRODUCT(S4:S10,$N$4:$N$10)/S19} -> #REF! | T15: {=SUMPRODUCT(T4:T10,$N$4:$N$10)/T19} -> #REF! | U15: {=SUMPRODUCT(U4:U10,$N$4:$N$10)/U19} -> #REF! | V15: {=SUMPRODUCT(V4:V10,$N$4:$N$10)/V19} -> #REF! | ... Y15: {=SUMPRODUCT(Y4:Y10,$N$4:$N$10)/Y19} -> #REF!
K16: 单套成本 | L16: =L15/#REF! -> #REF!
N17: =项目专用模具!N16 -> 装车比 | O17: =#REF! -> #REF! | P17: =#REF! -> #REF! | Q17: =#REF! -> #REF! | R17: =#REF! -> #REF! | S17: =#REF! -> #REF! | T17: =#REF! -> #REF! | U17: =#REF! -> #REF! | V17: =#REF! -> #REF! | ... Y17: =#REF! -> #REF!
M18: 第四页 | N18: =项目专用模具!N17 -> 总量纲 | O18: =#REF! -> #REF! | P18: =#REF! -> #REF! | Q18: =#REF! -> #REF! | R18: =#REF! -> #REF! | S18: =#REF! -> #REF! | T18: =#REF! -> #REF! | U18: =#REF! -> #REF! | V18: =#REF! -> #REF! | ... Y18: =#REF! -> #REF!
N19: =项目专用模具!N18 -> 数量 | O19: =O17*O18 -> #REF! | P19: =P17*P18 -> #REF! | Q19: =Q17*Q18 -> #REF! | R19: =R17*R18 -> #REF! | S19: =S17*S18 -> #REF! | T19: =T17*T18 -> #REF! | U19: =U17*U18 -> #REF! | V19: =V17*V18 -> #REF! | ... Y19: =Y17*Y18 -> #REF!
L20: =#REF! -> #REF!
L21: =L20/50000 -> #REF!
M22: {=SUMPRODUCT(O15:Y15,O17:Y17)} -> #REF!
L23: =L15-L20 -> #REF!
L25: =L23/#REF! -> #REF! | N25: =50000*L21+L25*35000 -> #REF!
N27: =N25/#REF! -> #REF!

Sheet 研发费用 
A1: =#REF! -> #REF! | F1: 金额单位：元
A2: 研发费用成本（不包含收费样线） | G2: 备 注
A3: 编号 | B3: 归属 | C3: 项目投资名称 | D3: 单位 | E3: 新增数量 | F3: 新增金额
A4: E0001 | B4: 研发费用类 | C4: 原 材 料
A5: E0002 | B5: 研发费用类 | C5: 手工样线
A6: E0003 | B6: 研发费用类 | C6: 试验样线/样品费用 | F6: 50000
A7: E0004 | B7: 研发费用类 | C7: 工 资
A8: E0005 | B8: 研发费用类 | C8: 差 旅 费 | F8: 10800
A9: E0006 | B9: 研发费用类 | C9: 交 际 费
A10: E0007 | B10: 研发费用类 | C10: 常规DVP测试 | F10: 166000
A11: E0008 | B11: 研发费用类 | C11: 实验费
A12: E0009 | B12: 研发费用类 | C12: 资讯设备费
A13: E0010 | B13: 研发费用类 | C13: 空运费
A14: E0011 | B14: 研发费用类 | C14: 气味实验
A15: E0011 | B15: 研发费用类 | C15: 管理费用 | G15: 59,791元,费用总金额*5%
A16: E0012 | B16: 研发费用类 | C16: 专利费
A17: E0013 | B17: 研发费用类 | C17: 场地租赁
E18: 合计 | F18: =SUM(F4:F17) -> 226800
E19: 单套成本 | F19: =F18/#REF! -> #REF!
F21: =F19/#REF! -> #REF! | G21: 第五页
