Workbook
Name a: [3]Terminal!$F$1:$F$3
Name countif: #REF!
Name countif: #REF!
Name countif: #REF!
Name countif: #REF!
Name countif: #REF!
Name D: #REF!
Name D: #REF!
Name D: #REF!
Name D: #REF!
Name D: #REF!
Name E: #REF!
Name E: #REF!
Name E: #REF!
Name Erstelldatum: #REF!
Name Erstelldatum: #REF!
Name Erstelldatum: #REF!
Name Erstelldatum: #REF!
Name Erstelldatum: #REF!
Name EXCEL_EXPORT1: #REF!
Name EXCEL_EXPORT1: #REF!
Name EXCEL_EXPORT1: #REF!
Name FZG_Beschriftung: #REF!
Name FZG_Beschriftung: #REF!
Name FZG_Beschriftung: #REF!
Name PA_Beschriftung: #REF!
Name PA_Beschriftung: #REF!
Name PA_Beschriftung: #REF!
Name Planungsstand: #REF!
Name Planungsstand: #REF!
Name Planungsstand: #REF!
Name Vergleichsplanung: #REF!
Name Vergleichsplanung: #REF!
Name Vergleichsplanung: #REF!
Name x: #REF!
Name x: #REF!
Name x: #REF!
Name Z: #REF!
Name Z: #REF!
Name Z: #REF!
Name 公用设备大类: OFFSET([4]资源数据源!$S$1,1,0,COUNTA([4]资源数据源!$S:$S)-COUNTIF([4]资源数据源!$S:$S,0)-1,1)
Name 公用设备大类: OFFSET([5]资源数据源!$S$1,1,0,COUNTA([5]资源数据源!$S:$S)-COUNTIF([5]资源数据源!$S:$S,0)-1,1)
Name 公用设备大类: OFFSET([5]资源数据源!$S$1,1,0,COUNTA([5]资源数据源!$S:$S)-COUNTIF([5]资源数据源!$S:$S,0)-1,1)
Name 公用设备大类: OFFSET([6]资源数据源!$Q$1,1,0,COUNTA([6]资源数据源!$Q:$Q)-COUNTIF([6]资源数据源!$Q:$Q,0)-1,1)
Name 公用设备大类: OFFSET([5]资源数据源!$S$1,1,0,COUNTA([5]资源数据源!$S:$S)-COUNTIF([5]资源数据源!$S:$S,0)-1,1)
Name 公用设备大类: OFFSET([4]资源数据源!$S$1,1,0,COUNTA([4]资源数据源!$S:$S)-COUNTIF([4]资源数据源!$S:$S,0)-1,1)
Name 公用设备大类: OFFSET([7]资源数据源!$S$1,1,0,COUNTA([7]资源数据源!$S:$S)-COUNTIF([7]资源数据源!$S:$S,0)-1,1)
Name 公用设备名称: OFFSET([4]资源数据源!$G$1,MATCH('[4]项目评估汇总-样表'!$C1,[4]资源数据源!$F:$F,0)-1,0,COUNTIF([4]资源数据源!$F:$F,'[4]项目评估汇总-样表'!$C1),1)
Name 公用设备名称: OFFSET([5]资源数据源!$G$1,MATCH(设备投资明细!#REF!,[5]资源数据源!$F:$F,0)-1,0,COUNTIF([5]资源数据源!$F:$F,设备投资明细!#REF!),1)
Name 公用设备名称: OFFSET([5]资源数据源!$G$1,MATCH([5]项目设备投入!$C1,[5]资源数据源!$F:$F,0)-1,0,COUNTIF([5]资源数据源!$F:$F,[5]项目设备投入!$C1),1)
Name 公用设备名称: OFFSET([6]资源数据源!$G$1,MATCH('[8]项目设备投入 '!$C1,[6]资源数据源!$F:$F,0)-1,0,COUNTIF([6]资源数据源!$F:$F,'[8]项目设备投入 '!$C1),1)
Name 公用设备名称: OFFSET([5]资源数据源!$G$1,MATCH([5]项目设备投入!$C1,[5]资源数据源!$F:$F,0)-1,0,COUNTIF([5]资源数据源!$F:$F,[5]项目设备投入!$C1),1)
Name 公用设备名称: OFFSET([4]资源数据源!$G$1,MATCH('[4]项目评估汇总-样表'!$C1,[4]资源数据源!$F:$F,0)-1,0,COUNTIF([4]资源数据源!$F:$F,'[4]项目评估汇总-样表'!$C1),1)
Name 公用设备名称: OFFSET([7]资源数据源!$G$1,MATCH('[7]项目评估汇总-样表'!$C1,[7]资源数据源!$F:$F,0)-1,0,COUNTIF([7]资源数据源!$F:$F,'[7]项目评估汇总-样表'!$C1),1)
Name 项目评估: #REF!
Name 项目评估: #REF!
Name 项目评估: #REF!
Name 专用工装设备大类: OFFSET([4]资源数据源!$W$1,1,0,COUNTA([4]资源数据源!$W:$W)-COUNTIF([4]资源数据源!$W:$W,0)-1,1)
Name 专用工装设备大类: OFFSET([5]资源数据源!$W$1,1,0,COUNTA([5]资源数据源!$W:$W)-COUNTIF([5]资源数据源!$W:$W,0)-1,1)
Name 专用工装设备大类: OFFSET([5]资源数据源!$W$1,1,0,COUNTA([5]资源数据源!$W:$W)-COUNTIF([5]资源数据源!$W:$W,0)-1,1)

Sheet 项目汇总
B2: #REF!
B4: 区分 | C4: 客户目标价格（工厂实际） | E4: 第一轮报价 | G4: 备注
C6: 金额 | D6: 收入比 | E6: 金额 | F6: 收入比
B7: 目标销售数量（PCS） | C7: 450000 | E7: =C7 -> 450000
B8: 核算分摊数量 | C8: 450000
B9: 回路工时(s) | C9: =C29*3600/C10 -> #REF! | E9: =E29*3600/E10 -> #REF!
B10: 回路数 | C10: 2305 | E10: =C10 -> 2305
B11: 回路销售单价 | C11: =C14/C10 -> 2.9501085 | E11: =E14/E10 -> 2.9501085
B12: 运营成本工时费（不包含折旧） | C12: 52.275345 | E12: 52.275345
B13: 运营成本直接人工费率 | C13: =C33/C29 -> #REF! | E13: =E33/E29 -> #REF!
B14: 目标销售单价（元） | C14: 6800 | E14: =C14 -> 6800
B15: 目标销售收入（元） | C15: 2475000000
B16: 目标利润额（元）
B17: 目标实现利润点（%） | C17: -0.004040404
B18: 返点金额（QS）（元） | C18: 10000000 | E18: 10000000
B19: 毛利（元） | C19: =(C14-C26)*C7 -> #REF! | E19: =(E14-E26)*E7 -> #REF!
B20: 毛利（%） | C20: =(C14-C27-C33-C34-C47-C50-(C18/C7))/C14 -> #REF! | E20: =(E14-E27-E33-E34-E47-E50-(E18/E7))/E14 -> #REF!
B21: 项目新增投资（元）
B22: -设备、模具、工装板类 | C22: #REF!
B23: -辅助工具类 | C23: #REF!
B24: 本阶段已投资（元） | C24: 0
B25: 剩余投资金额（元） | C25: #REF!
B26: 单套项目总成本（元/PCS） | C26: =C27+C33+C34+C45+C47+C50 -> #REF! | E26: =E27+E33+E34+E45+E47+E50 -> #REF!
B27: 单套材料成本（元/PCS） | C27: #REF! | D27: =C27/$C$14 -> #REF! | E27: =F27*E14 -> 4624 | F27: 0.68
B28: 回路材料成本 | C28: 1.7353579 | E28: =E27/E10 -> 2.0060738
B29: 总工时（H) | C29: =C30+C31 -> #REF! | E29: =E30+E31 -> #REF!
B30: —前工程工时（H) | C30: #REF! | E30: =C30 -> #REF!
B31: —后工程工时（H) | C31: #REF! | E31: =C31 -> #REF!
B32: 回路制造费用
B33: 单套直接人工（元/PCS） | C33: #REF! | D33: =C33/$C$14 -> #REF! | E33: =C33 -> #REF!
B34: 单套制造费用（元/PCS） | C34: =SUM(C35:C40) -> #REF! | D34: =C34/$C$14 -> #REF!
B35: —间接人工 | C35: #REF! | D35: =C35/$C$14 -> #REF!
B36: —低值易耗品费 | C36: 4.7988473 | D36: =C36/$C$14 -> 0.00070571284
B37: —机物料消耗 | C37: 122.05998 | D37: =C37/$C$14 -> 0.017949997
B38: —厂房分摊 | C38: 51.756883 | D38: =C38/$C$14 -> 0.0076113063
B39: —自动化仓、仓库分摊 | C39: 35.367203 | D39: =C39/$C$14 -> 0.0052010593
B40: —其他制费 | C40: 26.094095 | D40: =C40/$C$14 -> 0.0038373669
C41: 318.79962 | D41: =C41/$C$14 -> 0.046882297
B42: 单套期间费用成本（元/PCS） | C42: 14.613367 | D42: =C42/$C$14 -> 0.0021490245
B43: 销售费用（元/PCS） | C43: 294.7029 | D43: =C43/$C$14 -> 0.043338662
...

Sheet 项目评估汇总（昆山90%）
A1: 吉利P162大电池包高压 | F1: 2026 | G1: 2027 | H1: 2028 | I1: 2029 | J1: 2030 | K1: 2031 | L1: 2032 | M1: 2033
A2: 内 容 | E2: 产 品 周 期 汇 总 | N2: 备 注 | P2: 1 | Q2: 2
C3: 费率 | E3: 目标汇总值 | F3: ="第一年"&F1&"年" -> 第一年2026年 | G3: ="第二年"&G1&"年" -> 第二年2027年 | H3: ="第三年"&H1&"年" -> 第三年2028年 | I3: ="第四年"&I1&"年" -> 第四年2029年 | J3: ="第五年"&J1&"年" -> 第五年2030年 | K3: ="第六年"&K1&"年" -> 第六年2031年 | L3: ="第七年"&L1&"年" -> 第七年2032年 | M3: ="第八年"&M1&"年" -> 第八年2033年 | P3: {=TRANSPOSE(配置明细!$B$3:$B$4)} -> 6608523073 | Q3: 6608523072
A4: 回路数（PCS） | F4: =配置明细!P14 -> 27 | G4: =F4 -> 27 | H4: =G4 -> 27 | I4: =H4 -> 27 | J4: =I4 -> 27 | P4: =VLOOKUP(P3,配置明细!$B:$P,15,0) -> 25 | Q4: =VLOOKUP(Q3,配置明细!$B:$P,15,0) -> 2
A5: 目标销售数量（PCS） | E5: =SUM(F5:K5) -> 201000 | F5: 48000 | G5: 48000 | H5: 42000 | I5: 39000 | J5: 24000 | P5: =P37 -> 201000 | Q5: =Q37 -> 201000
A6: 目标销售单价（元） | F6: {=SUMPRODUCT(P6:Q6,P35:Q35)} -> 585.59777 | G6: =F6 -> 585.59777 | H6: =G6 -> 585.59777 | I6: =H6 -> 585.59777 | J6: =I6 -> 585.59777 | N6: 平均售价 | P6: =(P15+P16+P20+P23+P31+P32)/85% -> 442.67059 | Q6: =(Q15+Q16+Q20+Q23+Q31+Q32)/85% -> 142.92718
A7: 回路单价 （元） | F7: =F6/F4 -> 21.688806 | G7: =G6/G4 -> 21.688806 | H7: =H6/H4 -> 21.688806 | I7: =I6/I4 -> 21.688806 | J7: =I7 -> 21.688806 | N7: =(E9-E13)/E5 -> 585.59777 | P7: =P6/P4 -> 17.706824 | Q7: =Q6/Q4 -> 71.46359
A8: 回路工时 （秒） | F8: =(配置明细!L14+配置明细!M14+配置明细!N14)*3600/F4 -> 213.06667 | G8: =F8 -> 213.06667 | H8: =G8 -> 213.06667 | I8: =H8 -> 213.06667 | J8: =I8 -> 213.06667
A9: 目标销售收入（元） | E9: =SUM(F9:M9) -> 1.1770515e+08 | F9: =F6*F5 -> 28108693 | G9: =G6*G5 -> 28108693 | H9: =H6*H5 -> 24595106 | I9: =I6*I5 -> 22838313 | J9: =J6*J5 -> 14054346 | N9: =E9/E5 -> 585.59777 | P9: =P6*P5 -> 88976788 | Q9: =Q6*Q5 -> 28728363
A10: 目标利润额（元） | E10: =E9-E14 -> 17655773 | F10: =(F6-F14)*F5 -> 4216303.9 | G10: =(G6-G14)*G5 -> 4216303.9 | H10: =(H6-H14)*H5 -> 3689265.9 | I10: =(I6-I14)*I5 -> 3425746.9 | J10: =(J6-J14)*J5 -> 2108152 | P10: =(P6-P14)*P5 -> 13346518 | Q10: =(Q6-Q14)*Q5 -> 4309254.5
A11: 毛利（%） | E11: =(E9-E15-E16-E20-E23-E13-E31-E32)/E9 -> 0.15 | F11: =((F6-F15-F16-F20-F23)-(F13/F5)-F31-F32)/F6 -> 0.15 | G11: =((G6-G15-G16-G20-G23)-(G13/G5)-G31-G32)/G6 -> 0.15 | H11: =((H6-H15-H16-H20-H23)-(H13/H5)-H31-H32)/H6 -> 0.15 | I11: =((I6-I15-I16-I20-I23)-(I13/I5)-I31-I32)/I6 -> 0.15 | J11: =((J6-J15-J16-J20-J23)-(J13/J5)-J31-J32)/J6 -> 0.15 | P11: =((P6-P15-P16-P20-P23)-(P13/P5)-P31-P32)/P6 -> 0.15 | Q11: =((Q6-Q15-Q16-Q20-Q23)-(Q13/Q5)-Q31-Q32)/Q6 -> 0.15
A12: 毛利（元） | E12: =E11*E9 -> 17655773 | F12: =F11*F9 -> 4216303.9 | G12: =G11*G9 -> 4216303.9 | H12: =H11*H9 -> 3689265.9 | I12: =I11*I9 -> 3425746.9 | J12: =J11*J9 -> 2108152 | P12: =P11*P9 -> 13346518 | Q12: =Q11*Q9 -> 4309254.5
A13: 返点金额（QS）（元） | E13: =SUM(F13:J13) -> 0
A14: 单套项目总成本（元/PCS） | E14: =F14*$F$5+G14*$G$5+H14*$H$5+$I$5*I14+J14*$J$5+K14*$K$5+L14*$L$5+M14*$M$5 -> 1.0004938e+08 | F14: =F16+F15+F20+F23+F31+F32 -> 497.7581 | G14: =G16+G15+G20+G23+G31+G32 -> 497.7581 | H14: =H16+H15+H20+H23+H31+H32 -> 497.7581 | I14: =I16+I15+I20+I23+I31+I32 -> 497.7581 | J14: =J16+J15+J20+J23+J31+J32 -> 497.7581 | L14: =L16+L15+L20+L23+L31+L32 -> 0 | M14: =M16+M15+M20+M23+M31+M32 -> 0 | N14: =(E14/$E$5)/($N$7-$E$13/$E$5) -> 0.85 | O14: {=SUMPRODUCT(P14:Q14,$P$35:$Q$35)-J14} -> 0 | P14: =P16+P15+P20+P23+P31+P32 -> 376.27 | Q14: =Q16+Q15+Q20+Q23+Q31+Q32 -> 121.4881
A15: 单套材料成本（元/PCS） | D15: BOM材料成本 | E15: =F15*$F$5+G15*$G$5+H15*$H$5+$I$5*I15+J15*$J$5+K15*$K$5+L15*$L$5+M15*$M$5 -> 77813357 | F15: =配置明细!G14 -> 387.13113 | G15: =F15 -> 387.13113 | H15: =G15 -> 387.13113 | I15: =H15 -> 387.13113 | J15: =I15 -> 387.13113 | N15: =(E15/$E$5)/($N$7-$E$13/$E$5) -> 0.6610871 | O15: {=SUMPRODUCT(P15:Q15,$P$35:$Q$35)-J15} -> 0 | P15: =VLOOKUP(P3,配置明细!$B$2:$G$13,6,0) -> 296.27997 | Q15: =VLOOKUP(Q3,配置明细!$B$2:$G$13,6,0) -> 90.851159
A16: 单套直接人工（元/PCS） | E16: =F16*$F$5+G16*$G$5+H16*$H$5+$I$5*I16+J16*$J$5+K16*$K$5+L16*$L$5+M16*$M$5 -> 9376443.1 | F16: =F17+F18+F19 -> 46.648971 | G16: =G17+G18+G19 -> 46.648971 | H16: =H17+H18+H19 -> 46.648971 | I16: =H16 -> 46.648971 | J16: =I16 -> 46.648971 | N16: =(E16/$E$5)/($N$7-$E$13/$E$5) -> 0.079660431 | O16: {=SUMPRODUCT(P16:Q16,$P$35:$Q$35)-J16} -> 0 | P16: =P17+P18+P19 -> 32.870301 | Q16: =Q17+Q18+Q19 -> 13.77867
B17: —前工程效率-开线 | C17: 工厂开线标准工时费 | D17: 工厂开线标准工时费*工时 | E17: =F17*$F$5+G17*$G$5+H17*$H$5+$I$5*I17+J17*$J$5+K17*$K$5+L17*$L$5+M17*$M$5 -> 0 | F17: =配置明细!L14*运营工时费报价基准!E8/运营工时费报价基准!$M$5 -> 0 | G17: =F17 -> 0 | H17: =G17 -> 0 | I17: =H17 -> 0 | J17: =I17 -> 0 | N17: =(E17/$E$5)/($N$7-$E$13/$E$5) -> 0 | O17: {=SUMPRODUCT(P17:Q17,$P$35:$Q$35)-J17} -> 0 | P17: =VLOOKUP(P3,配置明细!$B$2:$L$14,11,0)*运营工时费报价基准!$D$6/运营工时费报价基准!$M$5 -> 0 | Q17: =VLOOKUP(Q3,配置明细!$B$2:$L$14,11,0)*运营工时费报价基准!$D$6/运营工时费报价基准!$M$5 -> 0
B18: —前工程效率 - 公共制程 | C18: 工厂公共制程标准工时费 | D18: 工厂公共制程标准工时费*工时 | E18: =F18*$F$5+G18*$G$5+H18*$H$5+$I$5*I18+J18*$J$5+K18*$K$5+L18*$L$5+M18*$M$5 -> 5597701.3 | F18: =配置明细!M14*运营工时费报价基准!$E$8/运营工时费报价基准!$M$5 -> 27.84926 | G18: =F18 -> 27.84926 | H18: =G18 -> 27.84926 | I18: =H18 -> 27.84926 | J18: =I18 -> 27.84926 | N18: =(E18/$E$5)/($N$7-$E$13/$E$5) -> 0.047556978 | O18: {=SUMPRODUCT(P18:Q18,$P$35:$Q$35)-J18} -> 3.907985e-14 | P18: =VLOOKUP(P3,配置明细!$B$2:$M$14,12,0)*运营工时费报价基准!$E$8/运营工时费报价基准!$M$5 -> 18.65375 | Q18: =VLOOKUP(Q3,配置明细!$B$2:$M$14,12,0)*运营工时费报价基准!$E$8/运营工时费报价基准!$M$5 -> 9.1955105
B19: —后工程 - 总装 | C19: 工厂总装标准工时费 | D19: 工厂总装标准工时费*工时 | E19: =F19*$F$5+G19*$G$5+H19*$H$5+$I$5*I19+J19*$J$5+K19*$K$5+L19*$L$5+M19*$M$5 -> 3778741.8 | F19: =配置明细!N14*运营工时费报价基准!$E$8/运营工时费报价基准!$M$5 -> 18.79971 | G19: =F19 -> 18.79971 | H19: =G19 -> 18.79971 | I19: =H19 -> 18.79971 | J19: =I19 -> 18.79971 | N19: =(E19/$E$5)/($N$7-$E$13/$E$5) -> 0.032103453 | O19: {=SUMPRODUCT(P19:Q19,$P$35:$Q$35)-J19} -> 3.907985e-14 | P19: =VLOOKUP(P3,配置明细!$B$2:$N$14,13,0)*运营工时费报价基准!$E$8/运营工时费报价基准!$M$5 -> 14.216551 | Q19: =VLOOKUP(Q3,配置明细!$B$2:$N$14,13,0)*运营工时费报价基准!$E$8/运营工时费报价基准!$M$5 -> 4.5831592
A20: 单套设备成本（元/PCS） | E20: =F20*$F$5+G20*$G$5+H20*$H$5+$I$5*I20+J20*$J$5+K20*$K$5+L20*$L$5+M20*$M$5 -> 2968152.1 | F20: =F21+F22 -> 14.766926 | G20: =G21+G22 -> 14.766926 | H20: =H21+H22 -> 14.766926 | I20: =H20 -> 14.766926 | J20: =I20 -> 14.766926 | N20: =(E20/$E$5)/($N$7-$E$13/$E$5) -> 0.025216841 | O20: {=SUMPRODUCT(P20:Q20,$P$35:$Q$35)-J20} -> 0 | P20: =P21+P22 -> 9.803013 | Q20: =Q21+Q22 -> 4.9639131
B21: —共用设备（元/PCS) | D21: 年折旧*使用年限/产量 | E21: =F21*$F$5+G21*$G$5+H21*$H$5+$I$5*I21+J21*$J$5+K21*$K$5+L21*$L$5+M21*$M$5 -> 1769533.1 | F21: =设备投资明细!K20 -> 8.8036475 | G21: =F21 -> 8.8036475 | H21: =G21 -> 8.8036475 | I21: =H21 -> 8.8036475 | J21: =I21 -> 8.8036475 | N21: =(E21/$E$5)/($N$7-$E$13/$E$5) -> 0.015033608 | O21: {=SUMPRODUCT(P21:Q21,$P$35:$Q$35)-J21} -> 0 | P21: =设备投资明细!Q20 -> 5.8543015 | Q21: =设备投资明细!R20 -> 2.9493459
B22: —专用设备（元/PCS) | D22: 总价值／产量 | E22: =F22*$F$5+G22*$G$5+H22*$H$5+$I$5*I22+J22*$J$5+K22*$K$5+L22*$L$5+M22*$M$5 -> 1198619 | F22: =设备投资明细!J29+项目专用模具!L11+'项目工装投入 '!L16 -> 5.9632786 | G22: =F22 -> 5.9632786 | H22: =G22 -> 5.9632786 | I22: =H22 -> 5.9632786 | J22: =I22 -> 5.9632786 | N22: =(E22/$E$5)/($N$7-$E$13/$E$5) -> 0.010183233 | O22: {=SUMPRODUCT(P22:Q22,$P$35:$Q$35)-J22} -> 0 | P22: =设备投资明细!Q29+项目专用模具!O10+'项目工装投入 '!O15 -> 3.9487114 | Q22: =设备投资明细!R29+项目专用模具!P10+'项目工装投入 '!P15 -> 2.0145672
A23: 制造费用(单套) D=①+②+③+④ | E23: =F23*$F$5+G23*$G$5+H23*$H$5+$I$5*I23+J23*$J$5+K23*$K$5+L23*$L$5+M23*$M$5 -> 5260466.3 | F23: =F24+F25+F26+F27+F28+F29+F30 -> 26.171474 | G23: =G24+G25+G26+G27+G28+G29+G30 -> 26.171474 | H23: =H24+H25+H26+H27+H28+H29+H30 -> 26.171474 | I23: =I24+I25+I26+I27+I28+I29+I30 -> 26.171474 | J23: =J24+J25+J26+J27+J28+J29+J30 -> 26.171474 | N23: =(E23/$E$5)/($N$7-$E$13/$E$5) -> 0.044691895 | O23: {=SUMPRODUCT(P23:Q23,$P$35:$Q$35)-J23} -> -3.5527137e-14 | P23: =P24+P25+P26+P27+P28+P29+P30 -> 18.558704 | Q23: =Q24+Q25+Q26+Q27+Q28+Q29+Q30 -> 7.6127703
B24: —间接人工 | C24: 工厂费率 | D24: 工厂费率*工时 | E24: =F24*$F$5+G24*$G$5+H24*$H$5+$I$5*I24+J24*$J$5+K24*$K$5+L24*$L$5+M24*$M$5 -> 2079440.6 | F24: =(配置明细!$L$14+配置明细!$M$14+配置明细!$N$14)*运营工时费报价基准!E10 -> 10.345476 | G24: =F24 -> 10.345476 | H24: =G24 -> 10.345476 | I24: =H24 -> 10.345476 | J24: =I24 -> 10.345476 | N24: =(E24/$E$5)/($N$7-$E$13/$E$5) -> 0.017666522 | O24: {=SUMPRODUCT(P24:Q24,$P$35:$Q$35)-J24} -> -2.3092639e-14 | P24: =(VLOOKUP(P$3,配置明细!$B$2:$L$14,11,0)+VLOOKUP(P$3,配置明细!$B$3:$M$14,12,0)+VLOOKUP(P$3,配置明细!$B$3:$N$14,13,0))*运营工时费报价基准!$E$10 -> 7.2897408 | Q24: =(VLOOKUP(Q$3,配置明细!$B$2:$L$14,11,0)+VLOOKUP(Q$3,配置明细!$B$3:$M$14,12,0)+VLOOKUP(Q$3,配置明细!$B$3:$N$14,13,0))*运营工时费报价基准!$E$10 -> 3.055735
B25: —低值易耗品 | C25: 工厂费率 | D25: 工厂费率*工时 | E25: =F25*$F$5+G25*$G$5+H25*$H$5+$I$5*I25+J25*$J$5+K25*$K$5+L25*$L$5+M25*$M$5 -> 163876.36 | F25: =(配置明细!$L$14+配置明细!$M$14+配置明细!$N$14)*运营工时费报价基准!E11 -> 0.81530525 | G25: =F25 -> 0.81530525 | H25: =G25 -> 0.81530525 | I25: =H25 -> 0.81530525 | J25: =I25 -> 0.81530525 | N25: =(E25/$E$5)/($N$7-$E$13/$E$5) -> 0.0013922615 | O25: {=SUMPRODUCT(P25:Q25,$P$35:$Q$35)-J25} -> 0 | P25: =(VLOOKUP(P$3,配置明细!$B$2:$L$14,11,0)+VLOOKUP(P$3,配置明细!$B$3:$M$14,12,0)+VLOOKUP(P$3,配置明细!$B$3:$N$14,13,0))*运营工时费报价基准!$E$11 -> 0.57448918 | Q25: =(VLOOKUP(Q$3,配置明细!$B$2:$L$14,11,0)+VLOOKUP(Q$3,配置明细!$B$3:$M$14,12,0)+VLOOKUP(Q$3,配置明细!$B$3:$N$14,13,0))*运营工时费报价基准!$E$11 -> 0.24081607
B26: —机物料消耗 | C26: 工厂费率 | D26: 工厂费率*工时 | E26: =F26*$F$5+G26*$G$5+H26*$H$5+$I$5*I26+J26*$J$5+K26*$K$5+L26*$L$5+M26*$M$5 -> 772510.19 | F26: =(配置明细!$L$14+配置明细!$M$14+配置明细!$N$14)*运营工时费报价基准!E12 -> 3.8433343 | G26: =F26 -> 3.8433343 | H26: =G26 -> 3.8433343 | I26: =H26 -> 3.8433343 | J26: =I26 -> 3.8433343 | N26: =(E26/$E$5)/($N$7-$E$13/$E$5) -> 0.0065630958 | O26: {=SUMPRODUCT(P26:Q26,$P$35:$Q$35)-J26} -> 0 | P26: =(VLOOKUP(P$3,配置明细!$B$2:$L$14,11,0)+VLOOKUP(P$3,配置明细!$B$3:$M$14,12,0)+VLOOKUP(P$3,配置明细!$B$3:$N$14,13,0))*运营工时费报价基准!$E$12 -> 2.7081317 | Q26: =(VLOOKUP(Q$3,配置明细!$B$2:$L$14,11,0)+VLOOKUP(Q$3,配置明细!$B$3:$M$14,12,0)+VLOOKUP(Q$3,配置明细!$B$3:$N$14,13,0))*运营工时费报价基准!$E$12 -> 1.1352026
B27: —厂房分摊 | C27: 工厂费率 | D27: 工厂费率*工时 | E27: =F27*$F$5+G27*$G$5+H27*$H$5+$I$5*I27+J27*$J$5+K27*$K$5+L27*$L$5+M27*$M$5 -> 1240910.5 | F27: =(配置明细!$L$14+配置明细!$M$14+配置明细!$N$14)*运营工时费报价基准!E13 -> 6.1736842 | G27: =F27 -> 6.1736842 | H27: =G27 -> 6.1736842 | I27: =H27 -> 6.1736842 | J27: =I27 -> 6.1736842 | N27: =(E27/$E$5)/($N$7-$E$13/$E$5) -> 0.010542534 | O27: {=SUMPRODUCT(P27:Q27,$P$35:$Q$35)-J27} -> 0 | P27: =(VLOOKUP(P$3,配置明细!$B$2:$L$14,11,0)+VLOOKUP(P$3,配置明细!$B$3:$M$14,12,0)+VLOOKUP(P$3,配置明细!$B$3:$N$14,13,0))*运营工时费报价基准!$E$13 -> 4.350168 | Q27: =(VLOOKUP(Q$3,配置明细!$B$2:$L$14,11,0)+VLOOKUP(Q$3,配置明细!$B$3:$M$14,12,0)+VLOOKUP(Q$3,配置明细!$B$3:$N$14,13,0))*运营工时费报价基准!$E$13 -> 1.8235162
B28: —自动化仓、仓库分摊 | C28: 工厂费率 | D28: 工厂费率*工时 | E28: =F28*$F$5+G28*$G$5+H28*$H$5+$I$5*I28+J28*$J$5+K28*$K$5+L28*$L$5+M28*$M$5 -> 77840.228 | F28: =(配置明细!$L$14+配置明细!$M$14+配置明细!$N$14)*运营工时费报价基准!E14 -> 0.38726481 | G28: =F28 -> 0.38726481 | H28: =G28 -> 0.38726481 | I28: =H28 -> 0.38726481 | J28: =I28 -> 0.38726481 | N28: =(E28/$E$5)/($N$7-$E$13/$E$5) -> 0.00066131539 | O28: {=SUMPRODUCT(P28:Q28,$P$35:$Q$35)-J28} -> 4.9960036e-16 | P28: =(VLOOKUP(P$3,配置明细!$B$2:$L$14,11,0)+VLOOKUP(P$3,配置明细!$B$3:$M$14,12,0)+VLOOKUP(P$3,配置明细!$B$3:$N$14,13,0))*运营工时费报价基准!$E$14 -> 0.27287871 | Q28: =(VLOOKUP(Q$3,配置明细!$B$2:$L$14,11,0)+VLOOKUP(Q$3,配置明细!$B$3:$M$14,12,0)+VLOOKUP(Q$3,配置明细!$B$3:$N$14,13,0))*运营工时费报价基准!$E$14 -> 0.1143861
B29: —其他制费 | C29: 工厂费率 | D29: 工厂费率*工时 | E29: =F29*$F$5+G29*$G$5+H29*$H$5+$I$5*I29+J29*$J$5+K29*$K$5+L29*$L$5+M29*$M$5 -> 536821.54 | F29: =(配置明细!$L$14+配置明细!$M$14+配置明细!$N$14)*运营工时费报价基准!E15 -> 2.6707539 | G29: =F29 -> 2.6707539 | H29: =G29 -> 2.6707539 | I29: =H29 -> 2.6707539 | J29: =I29 -> 2.6707539 | N29: =(E29/$E$5)/($N$7-$E$13/$E$5) -> 0.0045607311 | O29: {=SUMPRODUCT(P29:Q29,$P$35:$Q$35)-J29} -> -3.9968029e-15 | P29: =(VLOOKUP(P$3,配置明细!$B$2:$L$14,11,0)+VLOOKUP(P$3,配置明细!$B$3:$M$14,12,0)+VLOOKUP(P$3,配置明细!$B$3:$N$14,13,0))*运营工时费报价基准!$E$15 -> 1.8818955 | Q29: =(VLOOKUP(Q$3,配置明细!$B$2:$L$14,11,0)+VLOOKUP(Q$3,配置明细!$B$3:$M$14,12,0)+VLOOKUP(Q$3,配置明细!$B$3:$N$14,13,0))*运营工时费报价基准!$E$15 -> 0.78885848
B30: -材料损耗 | C30: 材料*0.5% | E30: =F30*$F$5+G30*$G$5+H30*$H$5+$I$5*I30+J30*$J$5+K30*$K$5+L30*$L$5+M30*$M$5 -> 389066.78 | F30: =F15*0.5% -> 1.9356556 | G30: =G15*0.5% -> 1.9356556 | H30: =H15*0.5% -> 1.9356556 | I30: =I15*0.5% -> 1.9356556 | J30: =J15*0.5% -> 1.9356556 | N30: =(E30/$E$5)/($N$7-$E$13/$E$5) -> 0.0033054355 | O30: {=SUMPRODUCT(P30:Q30,$P$35:$Q$35)-J30} -> 0 | P30: =P15*0.5% -> 1.4813998 | Q30: =Q15*0.5% -> 0.45425579
A31: 研发费用（元/PCS） | D31: 投入费/产量 | E31: =F31*$F$5+G31*$G$5+H31*$H$5+$I$5*I31+J31*$J$5+K31*$K$5+L31*$L$5+M31*$M$5 -> 563400 | F31: ='研发费用 '!F19 -> 2.8029851 | G31: =F31 -> 2.8029851 | H31: =G31 -> 2.8029851 | I31: =H31 -> 2.8029851 | J31: =I31 -> 2.8029851 | N31: =(E31/$E$5)/($N$7-$E$13/$E$5) -> 0.0047865365 | O31: {=SUMPRODUCT(P31:Q31,$P$35:$Q$35)-J31} -> -1.110223e-14 | P31: ='研发费用 '!$F$21*P4 -> 2.5953566 | Q31: ='研发费用 '!$F$21*Q4 -> 0.20762852
A32: 单套包装、物流费用（元/PCS） | D32: 投入费/产量 | E32: =F32*$F$5+G32*$G$5+H32*$H$5+$I$5*I32+J32*$J$5+K32*$K$5+L32*$L$5+M32*$M$5 -> 4067560.5 | F32: =包装物流费用!L14 -> 20.236619 | G32: =F32 -> 20.236619 | H32: =G32 -> 20.236619 | I32: =H32 -> 20.236619 | J32: =I32 -> 20.236619 | N32: =(E32/$E$5)/($N$7-$E$13/$E$5) -> 0.0345572 | O32: {=SUMPRODUCT(P32:Q32,$P$35:$Q$35)-J32} -> 0 | P32: =VLOOKUP(P3,包装物流费用!$A$3:$L$13,12,0) -> 16.162657 | Q32: =VLOOKUP(Q3,包装物流费用!$A$3:$L$13,12,0) -> 4.0739627
A34: 解释：
A35: 低值易耗品费：工装板、模块、辅助工具、物料盒等 | N35: 第一页 | O35: =设备投资明细!N31 -> 装车比 | P35: {=TRANSPOSE(配置明细!E3:E4)} -> 1 | Q35: 1
A36: 机物料消耗：质量检验测试、开机测试 | O36: =设备投资明细!N32 -> 总量纲 | P36: =$E$5 -> 201000 | Q36: =$E$5 -> 201000
A37: 其他制费：差旅费、水电费、劳保用品、备品备件等 | O37: =设备投资明细!N33 -> 数量 | P37: =P35*P36 -> 201000 | Q37: =Q35*Q36 -> 201000
A39: 删除辅助工装类→和低值易耗品重复

Sheet 客户报价逻辑
B2: 零件号 | C2: 零件名称 | D2: 用量 | E2: 铜重 | F2: 铝重 | G2: 材料成本 （元） | H2: 废品率 （0.9%） | I2: 实际工时 | J2: 直接人工 (35元/H) | K2: 制造费 (47元/H) | L2: 人工+制造费 | M2: 管理费 (6%) | N2: 利润 | O2: 出厂价 | P2: 包装费 | Q2: 运输费 | R2: 到厂价
C3: *零件名称 | D3: *标配/选配 | E3: 铜重
B4: =配置明细!B3 -> 6608523073 | C4: =配置明细!D3 -> 组合式充电插座线束总成 | D4: =配置明细!E3 -> 1 | E4: =配置明细!I3 -> 0 | F4: =配置明细!J3 -> 0 | G4: =配置明细!G3 -> 296.27997 | H4: =G4*1% -> 2.9627997 | I4: =配置明细!M3+配置明细!N3 -> 1.126 | J4: =I4*35 -> 39.41 | K4: =$K$20*I4 -> 52.57294 | L4: =K4+J4 -> 91.98294 | M4: =(G4+L4)*6% -> 23.295775 | N4: =(L4+H4+G4)*6% -> 23.473543 | O4: =N4+M4+L4+G4+H4 -> 437.99503 | P4: =包装物流费用!E4+包装物流费用!F4 -> 5.9517567 | Q4: =包装物流费用!I4+包装物流费用!J4+包装物流费用!K4 -> 4.75 | R4: =Q4+P4+O4 -> 448.69678
B5: =配置明细!B4 -> 6608523072 | C5: =配置明细!D4 -> 充电线束总成 | D5: =配置明细!E4 -> 1 | E5: =配置明细!I4 -> 0 | F5: =配置明细!J4 -> 0 | G5: =配置明细!G4 -> 90.851159 | H5: =G5*1% -> 0.90851159 | I5: =配置明细!M4+配置明细!N4 -> 0.472 | J5: =I5*35 -> 16.52 | K5: =$K$20*I5 -> 22.03768 | L5: =K5+J5 -> 38.55768 | M5: =(G5+L5)*6% -> 7.7645303 | N5: =(L5+H5+G5)*6% -> 7.819041 | O5: =N5+M5+L5+G5+H5 -> 145.90092 | P5: =包装物流费用!E5+包装物流费用!F5 -> 1.1125093 | Q5: =包装物流费用!I5+包装物流费用!J5+包装物流费用!K5 -> 2.2333333 | R5: =Q5+P5+O5 -> 149.24676
B6: =配置明细!#REF! -> #REF! | C6: =配置明细!#REF! -> #REF! | D6: =配置明细!#REF! -> #REF! | E6: =配置明细!#REF! -> #REF! | F6: =配置明细!#REF! -> #REF! | G6: =配置明细!#REF! -> #REF! | H6: =G6*1% -> #REF! | I6: =配置明细!#REF!+配置明细!#REF! -> #REF! | J6: =I6*35 -> #REF! | K6: =$K$20*I6 -> #REF! | L6: =K6+J6 -> #REF! | M6: =(G6+L6)*6% -> #REF! | N6: =(L6+H6+G6)*6% -> #REF! | O6: =N6+M6+L6+G6+H6 -> #REF! | P6: =包装物流费用!#REF!+包装物流费用!#REF! -> #REF! | Q6: =包装物流费用!#REF!+包装物流费用!#REF!+包装物流费用!#REF! -> #REF! | R6: =Q6+P6+O6 -> #REF!
B7: =配置明细!#REF! -> #REF! | C7: =配置明细!#REF! -> #REF! | D7: =配置明细!#REF! -> #REF! | E7: =配置明细!#REF! -> #REF! | F7: =配置明细!#REF! -> #REF! | G7: =配置明细!#REF! -> #REF! | H7: =G7*1% -> #REF! | I7: =配置明细!#REF!+配置明细!#REF! -> #REF! | J7: =I7*35 -> #REF! | K7: =$K$20*I7 -> #REF! | L7: =K7+J7 -> #REF! | M7: =(G7+L7)*6% -> #REF! | N7: =(L7+H7+G7)*6% -> #REF! | O7: =N7+M7+L7+G7+H7 -> #REF! | P7: =包装物流费用!#REF!+包装物流费用!#REF! -> #REF! | Q7: =包装物流费用!#REF!+包装物流费用!#REF!+包装物流费用!#REF! -> #REF! | R7: =Q7+P7+O7 -> #REF!
B8: =配置明细!#REF! -> #REF! | C8: =配置明细!#REF! -> #REF! | D8: =配置明细!#REF! -> #REF! | E8: =配置明细!#REF! -> #REF! | F8: =配置明细!#REF! -> #REF! | G8: =配置明细!#REF! -> #REF! | H8: =G8*1% -> #REF! | I8: =配置明细!#REF!+配置明细!#REF! -> #REF! | J8: =I8*35 -> #REF! | K8: =$K$20*I8 -> #REF! | L8: =K8+J8 -> #REF! | M8: =(G8+L8)*6% -> #REF! | N8: =(L8+H8+G8)*6% -> #REF! | O8: =N8+M8+L8+G8+H8 -> #REF! | P8: =包装物流费用!#REF!+包装物流费用!#REF! -> #REF! | Q8: =包装物流费用!#REF!+包装物流费用!#REF!+包装物流费用!#REF! -> #REF! | R8: =Q8+P8+O8 -> #REF!
B9: =配置明细!#REF! -> #REF! | C9: =配置明细!#REF! -> #REF! | D9: =配置明细!#REF! -> #REF! | E9: =配置明细!#REF! -> #REF! | F9: =配置明细!#REF! -> #REF! | G9: =配置明细!#REF! -> #REF! | H9: =G9*1% -> #REF! | I9: =配置明细!#REF!+配置明细!#REF! -> #REF! | J9: =I9*35 -> #REF! | K9: =$K$20*I9 -> #REF! | L9: =K9+J9 -> #REF! | M9: =(G9+L9)*6% -> #REF! | N9: =(L9+H9+G9)*6% -> #REF! | O9: =N9+M9+L9+G9+H9 -> #REF! | P9: =包装物流费用!#REF!+包装物流费用!#REF! -> #REF! | Q9: =包装物流费用!#REF!+包装物流费用!#REF!+包装物流费用!#REF! -> #REF! | R9: =Q9+P9+O9 -> #REF!
B10: =配置明细!#REF! -> #REF! | C10: =配置明细!#REF! -> #REF! | D10: =配置明细!#REF! -> #REF! | E10: =配置明细!#REF! -> #REF! | F10: =配置明细!#REF! -> #REF! | G10: =配置明细!#REF! -> #REF! | H10: =G10*1% -> #REF! | I10: =配置明细!#REF!+配置明细!#REF! -> #REF! | J10: =I10*35 -> #REF! | K10: =$K$20*I10 -> #REF! | L10: =K10+J10 -> #REF! | M10: =(G10+L10)*6% -> #REF! | N10: =(L10+H10+G10)*6% -> #REF! | O10: =N10+M10+L10+G10+H10 -> #REF! | P10: =包装物流费用!#REF!+包装物流费用!#REF! -> #REF! | Q10: =包装物流费用!#REF!+包装物流费用!#REF!+包装物流费用!#REF! -> #REF! | R10: =Q10+P10+O10 -> #REF!
B11: =配置明细!#REF! -> #REF! | C11: =配置明细!#REF! -> #REF! | D11: =配置明细!#REF! -> #REF! | E11: =配置明细!#REF! -> #REF! | F11: =配置明细!#REF! -> #REF! | G11: =配置明细!#REF! -> #REF! | H11: =G11*1% -> #REF! | I11: =配置明细!#REF!+配置明细!#REF! -> #REF! | J11: =I11*35 -> #REF! | K11: =$K$20*I11 -> #REF! | L11: =K11+J11 -> #REF! | M11: =(G11+L11)*6% -> #REF! | N11: =(L11+H11+G11)*6% -> #REF! | O11: =N11+M11+L11+G11+H11 -> #REF! | P11: =包装物流费用!#REF!+包装物流费用!#REF! -> #REF! | Q11: =包装物流费用!#REF!+包装物流费用!#REF!+包装物流费用!#REF! -> #REF! | R11: =Q11+P11+O11 -> #REF!
B12: =配置明细!#REF! -> #REF! | C12: =配置明细!#REF! -> #REF! | D12: =配置明细!#REF! -> #REF! | E12: =配置明细!#REF! -> #REF! | F12: =配置明细!#REF! -> #REF! | G12: =配置明细!#REF! -> #REF! | H12: =G12*1% -> #REF! | I12: =配置明细!#REF!+配置明细!#REF! -> #REF! | J12: =I12*35 -> #REF! | K12: =$K$20*I12 -> #REF! | L12: =K12+J12 -> #REF! | M12: =(G12+L12)*6% -> #REF! | N12: =(L12+H12+G12)*6% -> #REF! | O12: =N12+M12+L12+G12+H12 -> #REF! | P12: =包装物流费用!#REF!+包装物流费用!#REF! -> #REF! | Q12: =包装物流费用!#REF!+包装物流费用!#REF!+包装物流费用!#REF! -> #REF! | R12: =Q12+P12+O12 -> #REF!
B13: =配置明细!#REF! -> #REF! | C13: =配置明细!#REF! -> #REF! | D13: =配置明细!#REF! -> #REF! | E13: =配置明细!#REF! -> #REF! | F13: =配置明细!#REF! -> #REF! | G13: =配置明细!#REF! -> #REF! | H13: =G13*1% -> #REF! | I13: =配置明细!#REF!+配置明细!#REF! -> #REF! | J13: =I13*35 -> #REF! | K13: =$K$20*I13 -> #REF! | L13: =K13+J13 -> #REF! | M13: =(G13+L13)*6% -> #REF! | N13: =(L13+H13+G13)*6% -> #REF! | O13: =N13+M13+L13+G13+H13 -> #REF! | P13: =包装物流费用!#REF!+包装物流费用!#REF! -> #REF! | Q13: =包装物流费用!#REF!+包装物流费用!#REF!+包装物流费用!#REF! -> #REF! | R13: =Q13+P13+O13 -> #REF!
B14: =配置明细!#REF! -> #REF! | C14: =配置明细!#REF! -> #REF! | D14: =配置明细!#REF! -> #REF! | E14: =配置明细!#REF! -> #REF! | F14: =配置明细!#REF! -> #REF! | G14: =配置明细!#REF! -> #REF! | H14: =G14*1% -> #REF! | I14: =配置明细!#REF!+配置明细!#REF! -> #REF! | J14: =I14*35 -> #REF! | K14: =$K$20*I14 -> #REF! | L14: =K14+J14 -> #REF! | M14: =(G14+L14)*6% -> #REF! | N14: =(L14+H14+G14)*6% -> #REF! | O14: =N14+M14+L14+G14+H14 -> #REF! | P14: =包装物流费用!#REF!+包装物流费用!#REF! -> #REF! | Q14: =包装物流费用!#REF!+包装物流费用!#REF!+包装物流费用!#REF! -> #REF! | R14: =Q14+P14+O14 -> #REF!
B17: 装车比 | E17: {=SUMPRODUCT($D$4:$D$14,E4:E14)} -> #REF! | F17: {=SUMPRODUCT($D$4:$D$14,F4:F14)} -> #REF! | G17: {=SUMPRODUCT($D$4:$D$14,G4:G14)} -> #REF! | H17: {=SUMPRODUCT($D$4:$D$14,H4:H14)} -> #REF! | I17: {=SUMPRODUCT($D$4:$D$14,I4:I14)} -> #REF! | J17: {=SUMPRODUCT($D$4:$D$14,J4:J14)} -> #REF! | K17: {=SUMPRODUCT($D$4:$D$14,K4:K14)} -> #REF! | L17: {=SUMPRODUCT($D$4:$D$14,L4:L14)} -> #REF! | ... R17: {=SUMPRODUCT($D$4:$D$14,R4:R14)} -> #REF!
R19: ='项目评估汇总（昆山90%）'!N9 -> 585.59777
K20: =37.36-1.25+0.27+11.52-1.38+0.17 -> 46.69

Sheet 运营工时费报价基准
B2: 1、运营工时费 25年1-6月 基准
B4: 区分 元/h | D4: K1K2工厂 | E4: K3工厂 | F4: 宁波工厂 | G4: 仪征工厂 | H4: 重庆工厂 低压 | I4: 重庆工厂 高压 | J4: 天津工厂
B5: 直接人工-出勤工时 | D5: 28.606853 | E5: =E8 -> 26.272887 | F5: 26.76716 | G5: 28.169428 | H5: 31.176795 | I5: 32.034397 | J5: 27.711746 | L5: 效率 | M5: =工厂效率!D17 -> 0.9
C6: -前工程效率-开线 元/h | D6: 30.198448 | G6: 28.028971 | H6: 34.195473
C7: -前工程效率 - 公共制程 元/h | D7: 28.188328 | G7: 27.662417 | H7: 30.866301
C8: -后工程 - 总装 元/h | D8: 28.580082 | E8: 26.272887 | F8: 26.76716 | G8: 32.856511 | H8: 31.038701 | I8: 32.034397 | J8: 27.711746
B9: 制造费用 | D9: 16.14+损耗 | E9: 15.17+损耗 | F9: 20.32+损耗 | G9: 15.13+损耗 | H9: 15.81+损耗 | I9: 23.46+损耗 | J9: 16.22+损耗
C10: -间接人工 元/h | D10: 8.4990788 | E10: 6.4740149 | F10: 9.45 （16.16） | G10: 10.393806 | H10: 9.748783 | I10: 11.162784 | J10: 8.8160737
C11: -低值易耗品费 元/h | D11: 0.87635407 | E11: 0.51020354 | F11: 0.41150703 | G11: 0.79522147 | H11: 2.1303395 | I11: 2.8080612 | J11: 0.51 （0.23）
C12: -机物料消耗 元/h | D12: 1.8562976 | E12: 2.4050903 | F12: 1.0939274 | G12: 0.69071852 | H12: 0.98154286 | I12: 4.9691472 | J12: 2.41 （0.11）
C13: -厂房分摊 元/h | D13: 1.45 | E13: 3.8633819 | F13: 3.2642647 | G13: 0.6107946 | H13: 1.0053462 | I13: 2.7842904 | J13: 2.9830898
C14: -自动化仓、仓库分摊 元/h | D14: 2.03 | E14: 0.24234344 | F14: 2.4354479 | G14: 0.51592727 | H14: 0.89453553 | I14: 0.89939771 | J14: 0
C15: -其他制费 元/h | D15: 1.423375 | E15: 1.6713103 | F15: 3.6629747 | G15: 2.1267819 | H15: 1.0477841 | I15: 0.83737698 | J15: 1.4978537
C16: -材料损耗 材料*0.5% | D16: 材料*0.5% | E16: 材料*0.5% | F16: 材料*0.5% | G16: 材料*0.5% | H16: 材料*0.5% | I16: 材料*0.5% | J16: 材料*0.5%
B18: 宁波工厂-间接人工 ：因产值低，按照昆山低压与仪征平均取数
B19: 天津工厂-低值易耗+机物料消耗 ：项目前期使用昆山高压物料，按照昆山高压取数
B20: K1K2工厂-厂房、自动化仓库摊销：25年1-6月产能不足，数据参考25年下半年预算

Sheet 工厂效率
B2: ● 25年报价效率：昆山低压、宁波、仪征、天津、重庆低压
B4: 总工时 | C4: 项目节拍 PCS/h | G4: 描述
C5: ≤5 | D5: 5~10 | E5: 10~20 | F5: ＞20
B6: ≤4h | C6: 0.9 | D6: 0.95 | E6: 1 | F6: 1.05 | G6: 单回路工时＞42S
B7: 4h~20h | C7: 0.85 | D7: 0.9 | E7: 0.95 | F7: 1
B8: ＞20h | C8: 0.8 | D8: 0.85 | E8: 0.9 | F8: 0.95
B9: ≤4h | C9: 0.85 | D9: 0.9 | E9: 0.95 | F9: 1 | G9: 单回路工时＜42S
B10: 4h~20h | C10: 0.8 | D10: 0.85 | E10: 0.9 | F10: 0.95
B11: ＞20h | C11: 0.75 | D11: 0.8 | E11: 0.85 | F11: 0.9
B14: ● 25年报价效率：昆山高压、天津高压、重庆高压
B16: 项目节拍 PCS/h | C16: ≤10 | D16: 10~20 | E16: >20 | F16: 描述
B17: 2025报价LE | C17: 0.85 | D17: 0.9 | E17: 0.95 | F17: 单班JPH效率

Sheet 设备投资明细
A1: ='项目评估汇总（昆山90%）'!A1 -> 吉利P162大电池包高压 | Q1: 1 | R1: 2
A2: 一、公用设备投入（前工程） | G2: 需求资产 | I2: 剩余资产 | K2: 新增资产 | M2: 单价 （标准件-财务； 非标件-申购部门） | N2: 备注 | O2: 适用范围 | P2: 供应商 | Q2: {=TRANSPOSE(配置明细!$B$3:$B$4)} -> 6608523073 | R2: 6608523072
A3: 编号 | B3: 归属 | C3: 项目投资名称 | D3: 设备名称 | E3: 工艺报价参考规格型号 | F3: 单位 | G3: 数量 | H3: 金额 | I3: 数量 | J3: 金额 | K3: 数量 | L3: 金额 | Q3: {=TRANSPOSE(配置明细!D3:D4)} -> 组合式充电插座线束总成 | R3: 充电线束总成
A4: A0001 | B4: 公用设备类 | C4: 开线 | D4: 全自动开线机/Kappa350 | E4: Kappa350 | F4: 台 | G4: =SUM(Q4:R4) -> 0.12 | K4: =G4-I4 -> 0.12 | L4: =K4*M4 -> 93600 | M4: 780000 | Q4: 0.07 | R4: 0.05
A5: A0001 | B5: 公用设备类 | C5: 开线 | D5: 全自动开线压接机/Alpha550 | E5: Alpha550 | F5: 台 | G5: =SUM(Q5:R5) -> 0.28 | K5: =G5-I5 -> 0.28 | L5: =K5*M5 -> 341946.9 | M5: 1221238.9 | Q5: 0.28 | R5: 0
A6: A0001 | B6: 公用设备类 | C6: 压接 | D6: 大平方压接机/XYD-30T | E6: XYD-30T | F6: 台 | G6: =SUM(Q6:R6) -> 0.86 | K6: =G6-I6 -> 0.86 | L6: =K6*M6 -> 72699.403 | M6: 84534.19 | Q6: 0 | R6: 0.86
A7: A0001 | B7: 公用设备类 | C7: 压接 | D7: 小平方压接机-变频/XYD-4T | E7: XYD-4T | F7: 台 | G7: =SUM(Q7:R7) -> 0.49 | K7: =G7-I7 -> 0.49 | L7: =K7*M7 -> 7742 | M7: 15800 | O7: 焊120铝（安奕吉 HVW-12/骄成 WL-B-AH9994-F） | Q7: 0.49 | R7: 0
A8: A0001 | B8: 公用设备类 | C8: 焊接 | D8: 焊接机/安奕吉 HVW-6 | E8: 安奕吉 HVW-6 | F8: 台 | G8: =SUM(Q8:R8) -> 0.54 | K8: =G8-I8 -> 0.54 | L8: =K8*M8 -> 420531.48 | M8: 778762 | O8: 焊50铝（安奕吉 HVW-6/骄成 WD-AH9940-F） | Q8: 0 | R8: 0.54
A9: A0001 | B9: 公用设备类 | C9: 焊接 | D9: 焊接机/骄成 WD-M9960-F 10KW | E9: 骄成 WD-M9960-F 10KW | F9: 台 | G9: =SUM(Q9:R9) -> 1.38 | K9: =G9-I9 -> 1.38 | L9: =K9*M9 -> 857307.47 | M9: 621237.3 | O9: 焊4方/6方铝（安奕吉 HVW-4/ WS-PH9810-F） | Q9: 1.38 | R9: 0
A10: A0001 | B10: 公用设备类 | C10: 去绝缘皮 | D10: 切剥翻一体机/定制 | E10: 定制 | F10: 台 | G10: =SUM(Q10:R10) -> 0.86 | K10: =G10-I10 -> 0.86 | L10: =K10*M10 -> 120400 | M10: 140000 | O10: 并线焊（安奕吉 AW-4/骄成 WE-AH9810-L） | Q10: 0 | R10: 0.86
A11: A0001 | B11: 公用设备类 | C11: 检测设备 | D11: 高压&气密检测/STRONG TEST-HG01 | E11: STRONG TEST-HG01 | F11: 台 | G11: =SUM(Q11:R11) -> 1.7 | K11: =G11-I11 -> 1.7 | L11: =K11*M11 -> 663000 | M11: 390000 | Q11: 0.84 | R11: 0.86
A12: A0001 | B12: 公用设备类 | C12: 检测设备 | D12: 低压电测台：小（10≤模块数≥2）/斜面-TS1700 | G12: =SUM(Q12:R12) -> 0.43 | K12: =G12-I12 -> 0.43 | L12: =K12*M12 -> 86000 | M12: 200000 | Q12: 0.43 | R12: 0
A13: A0001 | B13: 公用设备类 | C13: 扭力台 | D13: 扭力站/ST-HG-SCR | E13: ST-HG-SCR | F13: 台 | G13: =SUM(Q13:R13) -> 1 | K13: =G13-I13 -> 1 | L13: =K13*M13 -> 188000 | M13: 188000 | Q13: 1 | R13: 0
A14: A0001 | B14: 公用设备类 | C14: 焊接 | D14: 焊接机/Schunk Minic 2 plus | E14: Schunk Minic 2 plus | F14: 台 | G14: =SUM(Q14:R14) -> 0.05 | K14: =G14-I14 -> 0.05 | L14: =K14*M14 -> 11021.416 | M14: 220428.32 | Q14: 0.05 | R14: 0
A15: A0001 | B15: 公用设备类 | C15: 焊接 | D15: 焊接机/骄成 WD-MP9900-F | E15: 骄成 WD-MP9900-F | F15: 台 | G15: =SUM(Q15:R15) -> 0.14 | K15: =G15-I15 -> 0.14 | L15: =K15*M15 -> 86973.222 | M15: 621237.3 | Q15: 0.14 | R15: 0
G20: 合计 | H20: =SUM(L4:L19) -> 2949221.9 | J20: 单套费用 | K20: =H20/10*6/'项目评估汇总（昆山90%）'!E5 -> 8.8036475 | Q20: {=SUMPRODUCT(Q4:Q18,$M$4:$M$18)/10*6/Q33} -> 5.8543015 | R20: {=SUMPRODUCT(R4:R18,$M$4:$M$18)/10*6/R33} -> 2.9493459
A21: 二、专用设备投入（后工程）
A22: B0001 | B22: 专用设备 | C22: 高压气密测试模块 | D22: 高压测试模块/定制 | E22: 定制 | F22: 个 | G22: =SUM(Q22:R22) -> 6.81 | K22: =G22-I22 -> 6.81 | L22: =K22*M22 -> 79677 | M22: 11700 | O22: 充电座的需增加插拔次数监控功能 | Q22: 4.81 | R22: 2
A23: B0001 | B23: 专用设备 | C23: 卡钉台 | D23: 卡钉测试台/小（10≤模块数≥1） | E23: 小（10≤模块数≥1） | F23: 个 | G23: =SUM(Q23:R23) -> 1 | K23: =G23-I23 -> 1 | L23: =K23*M23 -> 90000 | M23: 90000 | Q23: 1 | R23: 0
K24: =G24-I24 -> 0 | L24: =K24*M24 -> 0
F27: pc | K27: =G27-I27 -> 0 | L27: =K27*M27 -> 0
G29: 合计 | H29: =SUM(L22:L28) -> 169677 | I29: 单套费用 | J29: =H29/'项目评估汇总（昆山90%）'!E5 -> 0.84416418 | Q29: {=SUMPRODUCT(Q22:Q27,$M$22:$M$27)/Q33} -> 0.72774627 | R29: {=SUMPRODUCT(R22:R27,$M$22:$M$27)/R33} -> 0.11641791
M31: 第二页 | N31: 装车比 | Q31: ='项目评估汇总（昆山90%）'!P35 -> 1 | R31: ='项目评估汇总（昆山90%）'!Q35 -> 1
N32: 总量纲 | Q32: ='项目评估汇总（昆山90%）'!$E$5 -> 201000 | R32: ='项目评估汇总（昆山90%）'!$E$5 -> 201000
A33: 填写说明： | N33: 数量 | Q33: =Q32*Q31 -> 201000 | R33: =R32*R31 -> 201000
A34: 1. 涉及自动化产线投资金额，自动化产线-公用件占比全产线金额的80%；自动化产线-专用件占比全产线金额的20%；
A35: 2. 涉及自动化产线需在备注列维护内容：a.公共部分占比自动化设备费用80%； 2、xx平参考设备尺寸：xxm*xxm*xxm； 3、涉及工序：开线，剥皮，去屏蔽层，预装；压接屏蔽环；压接端子；装塑壳；插位；
A36: 3. 如果项目设备/项目专用模具/项目工装投入表格中涉及新增内容在下拉箭头中无法选中，通知设备工程师至W:\昆山泽轩\动能工业中心\前期工艺部\04-前期设备中“泽轩设备数据库信息”中添加新增设备信息； | Q36: =Q29+项目专用模具!O10+'项目工装投入 '!O15 -> 3.9487114 | R36: =R29+项目专用模具!P10+'项目工装投入 '!P15 -> 2.0145672
O37: {=SUMPRODUCT(Q29:R29,Q31:R31)} -> 0.84416418

Sheet 项目专用模具
A1: ='项目评估汇总（昆山90%）'!A1 -> 吉利P162大电池包高压 | O1: 1 | P1: 2
A2: 专用模具投入 | G2: 需求模具（元） | I2: 沿用模具（元） | K2: 新增模具（元） | M2: 备 注 | N2: 单价 | O2: {=TRANSPOSE(配置明细!$B$3:$B$4)} -> 6608523073 | P2: 6608523072
A3: 编号 | B3: 归属 | C3: 项目投资名称 | D3: 名称 | E3: 型号 | F3: 单位 | G3: 需求数量 | H3: 需求金额 | I3: 沿用数量 | J3: 沿用金额 | K3: 新增数量 | L3: 新增金额 | M3: 设备按生命周期量核算模具的数量(低压模具20万次；高压模具5万次；防水栓模具无限制生命周期) | O3: {=TRANSPOSE(配置明细!D3:D4)} -> 组合式充电插座线束总成 | P3: 充电线束总成
A4: C0001 | B4: 模具类 | C4: 模具/模块/治具 | D4: 焊接治具/焊接治具 | E4: 焊接治具 | F4: 个 | G4: =SUM(O4:P4) -> 5 | K4: =G4-I4 -> 5 | L4: =K4*N4 -> 900000 | N4: 180000 | O4: 3 | P4: 2
A5: C0001 | B5: 模具类 | C5: 模具/模块/治具 | D5: 压接模具/小模具（40行程） | F5: 个 | G5: =SUM(O5:P5) -> 3.71 | K5: =G5-I5 -> 3.71 | L5: =K5*N5 -> 14840 | N5: 4000 | O5: 3.71 | P5: 0
A6: C0001 | B6: 模具类 | C6: 模具/模块/治具 | D6: 防水栓模具 | F6: 个 | G6: =SUM(O6:P6) -> 2.41 | K6: =G6-I6 -> 2.41 | L6: =K6*N6 -> 67480 | N6: 28000 | O6: 2.41 | P6: 0
A7: C0001 | B7: 模具类 | C7: 模具/模块/治具 | D7: 压接模具/大模具（50行程） | F7: 个 | G7: =SUM(O7:P7) -> 2 | K7: =G7-I7 -> 2 | L7: =K7*N7 -> 18000 | N7: 9000 | O7: 0 | P7: 2
K8: =G8-I8 -> 0
L10: =SUM(L4:L9) -> 1000320 | O10: {=SUMPRODUCT(O4:O9,$N$4:$N$9)/O14} -> 3.0961194 | P10: {=SUMPRODUCT(P4:P9,$N$4:$N$9)/P14} -> 1.880597
K11: 单套费用 | L11: =L10/'项目评估汇总（昆山90%）'!E5 -> 4.9767164
L12: 第三页 | N12: =设备投资明细!N31 -> 装车比 | O12: ='项目评估汇总（昆山90%）'!P35 -> 1 | P12: =设备投资明细!R31 -> 1
N13: =设备投资明细!N32 -> 总量纲 | O13: ='项目评估汇总（昆山90%）'!P36 -> 201000 | P13: =设备投资明细!R32 -> 201000
N14: =设备投资明细!N33 -> 数量 | O14: =O12*O13 -> 201000 | P14: =P12*P13 -> 201000
M16: {=SUMPRODUCT(O10:P10,O12:P12)} -> 4.9767164
A17: 说明：模具，夹具，模块

Sheet 项目工装投入 
A1: ='项目评估汇总（昆山90%）'!A1 -> 吉利P162大电池包高压 | O1: 1 | P1: 2
A2: 新增工装投入 | G2: 需求工装（元） | I2: 沿用工装（元） | K2: 新增工装（元） | M2: 备 注 | N2: 单价 | O2: {=TRANSPOSE(配置明细!$B$3:$B$4)} -> 6608523073 | P2: 6608523072
A3: 编号 | B3: 归属 | C3: 项目投资名称 | D3: 名称 | E3: 规格型号 | F3: 单位 | G3: 需求数量 | H3: 需求金额 | I3: 沿用数量 | J3: 沿用金额 | K3: 预估/实际数量 | L3: 预估/实际金额 | O3: {=TRANSPOSE(配置明细!D3:D4)} -> 组合式充电插座线束总成 | P3: 充电线束总成
A4: D0001 | B4: 工装类 | C4: 电脑 | D4: 电脑/一体机 | E4: 一体机 | F4: 台 | G4: =SUM(O4:P4) -> 2.91 | K4: =G4-I4 -> 2.91 | L4: =N4*K4 -> 12222 | N4: 4200 | O4: 2.07 | P4: 0.84
A5: D0001 | B5: 工装类 | C5: 辅助工装 | D5: 气动辅助工装/定制 | E5: 定制 | F5: 个 | G5: =SUM(O5:P5) -> 0 | K5: =G5-I5 -> 0 | L5: =N5*K5 -> 0
A6: D0001 | B6: 工装类 | C6: 辅助工装 | D6: 插位回拉工装/定制 | E6: QDKZQ | F6: 个 | G6: =SUM(O6:P6) -> 0 | K6: =G6-I6 -> 0 | L6: =N6*K6 -> 0
A7: D0001 | B7: 工装类 | C7: 辅助工装 | D7: 插位诱导工装/定制 | E7: 定制 | F7: 个 | G7: =SUM(O7:P7) -> 0 | K7: =G7-I7 -> 0 | L7: =N7*K7 -> 0
A8: D0001 | B8: 工装类 | C8: 辅助工装 | D8: 插拔力测试工装/定制 | E8: 定制 | F8: 个 | G8: =SUM(O8:P8) -> 0.41 | K8: =G8-I8 -> 0.41 | L8: =N8*K8 -> 16400 | N8: 40000 | O8: 0.41 | P8: 0
A9: D0001 | B9: 工装类 | C9: 辅助工装 | D9: 焊接机侧推工装/定制 | E9: 定制 | F9: 个 | G9: =SUM(O9:P9) -> 0 | K9: =G9-I9 -> 0 | L9: =N9*K9 -> 0
A10: D0001 | B10: 工装类 | C10: 扭力检测仪 | D10: 扭力检测仪/- | F10: 个 | G10: =SUM(O10:P10) -> 0 | K10: =G10-I10 -> 0 | L10: =N10*K10 -> 0
A11: D0001 | B11: 工装类 | C11: 辅助工装 | D11: 橡胶件气动扩张钳/QDKZQ | G11: =SUM(O11:P11) -> 0 | K11: =G11-I11 -> 0 | L11: =N11*K11 -> 0
G12: =SUM(O12:P12) -> 0
K15: 合计 | L15: {=SUMPRODUCT(G4:G12,N4:N12)} -> 28622 | O15: {=SUMPRODUCT(O4:O10,$N$4:$N$10)/O19} -> 0.12484577 | P15: {=SUMPRODUCT(P4:P10,$N$4:$N$10)/P19} -> 0.017552239
K16: 单套成本 | L16: =L15/'项目评估汇总（昆山90%）'!E5 -> 0.14239801
N17: =项目专用模具!N12 -> 装车比 | O17: ='项目评估汇总（昆山90%）'!P35 -> 1 | P17: ='项目评估汇总（昆山90%）'!Q35 -> 1
M18: 第四页 | N18: =项目专用模具!N13 -> 总量纲 | O18: ='项目评估汇总（昆山90%）'!P36 -> 201000 | P18: ='项目评估汇总（昆山90%）'!Q36 -> 201000
N19: =项目专用模具!N14 -> 数量 | O19: =O17*O18 -> 201000 | P19: =P17*P18 -> 201000
M22: {=SUMPRODUCT(O15:P15,O17:P17)} -> 0.14239801

Sheet 研发费用 
A1: ='项目评估汇总（昆山90%）'!A1 -> 吉利P162大电池包高压 | F1: 金额单位：元
A2: 研发费用成本（不包含收费样线） | G2: 备 注
A3: 编号 | B3: 归属 | C3: 项目投资名称 | D3: 单位 | E3: 新增数量 | F3: 新增金额
A4: E0001 | B4: 研发费用类 | C4: 原 材 料
A5: E0002 | B5: 研发费用类 | C5: 手工样线 | F5: 59200
A6: E0003 | B6: 研发费用类 | C6: 试验样线/样品费用
A7: E0004 | B7: 研发费用类 | C7: 工 资
A8: E0005 | B8: 研发费用类 | C8: 差 旅 费 | F8: 4200
A9: E0006 | B9: 研发费用类 | C9: 交 际 费
A10: E0007 | B10: 研发费用类 | C10: 常规DVP测试 | F10: 500000
A11: E0008 | B11: 研发费用类 | C11: 实验费
A12: E0009 | B12: 研发费用类 | C12: 资讯设备费
A13: E0010 | B13: 研发费用类 | C13: 空运费
A14: E0011 | B14: 研发费用类 | C14: 气味实验
A15: E0011 | B15: 研发费用类 | C15: 管理费用 | G15: 28,170元,费用总金额*5%
A16: E0012 | B16: 研发费用类 | C16: 专利费
A17: E0013 | B17: 研发费用类 | C17: 场地租赁
E18: 合计 | F18: =SUM(F4:F17) -> 563400
E19: 单套成本 | F19: =F18/'项目评估汇总（昆山90%）'!E5 -> 2.8029851
F21: =F19/配置明细!P14 -> 0.10381426 | G21: 第五页

Sheet 包装物流费用
A1: ='项目评估汇总（昆山90%）'!A1 -> 吉利P162大电池包高压 | F1: 金额单位：元
A2: 包装物流成本明细
A3: 客户零件号 | B3: SAP号 | C3: 物料描述 | D3: 用量 | E3: 内包装 | F3: 外包装 | G3: 运费 | H3: 服务费 | I3: 短驳（合肥仓库到客户）+其他 | J3: 三方仓费用 | K3: 围板箱折叠费 | L3: 合计 | M3: 备注
A4: =配置明细!B3 -> 6608523073 | C4: =配置明细!D3 -> 组合式充电插座线束总成 | D4: =配置明细!E3 -> 1 | E4: 4.2566 | F4: 1.6951567 | G4: 5.4609 | J4: 4.75 | L4: =SUM(E4:K4) -> 16.162657
A5: =配置明细!B4 -> 6608523072 | C5: =配置明细!D4 -> 充电线束总成 | D5: =配置明细!E4 -> 1 | E5: 0.773478 | F5: 0.33903134 | G5: 0.72811999 | J5: 2.2333333 | L5: =SUM(E5:K5) -> 4.0739627
A14: 单套成本 | E14: {=SUMPRODUCT(E4:E13,$D$4:$D$13)} -> 5.030078 | F14: {=SUMPRODUCT(F4:F13,$D$4:$D$13)} -> 2.034188 | G14: {=SUMPRODUCT(G4:G13,$D$4:$D$13)} -> 6.18902 | H14: {=SUMPRODUCT(H4:H13,$D$4:$D$13)} -> 0 | I14: {=SUMPRODUCT(I4:I13,$D$4:$D$13)} -> 0 | J14: {=SUMPRODUCT(J4:J13,$D$4:$D$13)} -> 6.9833333 | K14: {=SUMPRODUCT(K4:K13,$D$4:$D$13)} -> 0 | L14: {=SUMPRODUCT(L4:L13,$D$4:$D$13)} -> 20.236619
H16: 第六页

Sheet 配置明细
A1: ='项目评估汇总（昆山90%）'!A1 -> 吉利P162大电池包高压
A2: 序号 | B2: 零件号 | C2: 零件号SAP号 | D2: 零件名称 | E2: 数量 | F2: 单位 | G2: 材料成本（元） | H2: VAVE后材料成本 | I2: 线束铜重（KG） | J2: 线束铝重（KG） | K2: 导线成本 （元） | L2: 开线工时（H） | M2: 公共制成工时（H） | N2: 后工程工时（H） | O2: JPH | P2: 回路数 | Q2: 前工程直接人力（双班） | R2: 前工程间接人力（双班） | S2: 后工程直接人力（双班） | T2: 后工程间接人力（双班） | U2: 项目前工程占用面积（㎡） | V2: 项目后工程占用面积（㎡） | W2: 占地面积/㎡
A3: 1 | B3: 6608523073 | D3: 组合式充电插座线束总成 | E3: 1 | F3: PC | G3: =SUMIFS('KSK线束BOM明细 '!U:U,'KSK线束BOM明细 '!A:A,B3) -> 296.27997 | M3: 0.639 | N3: 0.487 | O3: 12 | P3: 25
A4: 2 | B4: 6608523072 | D4: 充电线束总成 | E4: 1 | F4: PC | G4: =SUMIFS('KSK线束BOM明细 '!U:U,'KSK线束BOM明细 '!A:A,B4) -> 90.851159 | M4: 0.315 | N4: 0.157 | O4: 29.45 | P4: 2
B14: 合计 | G14: {=SUMPRODUCT(G3:G13,$E$3:$E$13)} -> 387.13113 | H14: {=SUMPRODUCT(H3:H13,$E$3:$E$13)} -> 0 | I14: {=SUMPRODUCT(I3:I13,$E$3:$E$13)} -> 0 | J14: {=SUMPRODUCT(J3:J13,$E$3:$E$13)} -> 0 | K14: {=SUMPRODUCT(K3:K13,$E$3:$E$13)} -> 0 | L14: {=SUMPRODUCT(L3:L13,$E$3:$E$13)} -> 0 | M14: {=SUMPRODUCT(M3:M13,$E$3:$E$13)} -> 0.954 | N14: {=SUMPRODUCT(N3:N13,$E$3:$E$13)} -> 0.644 | ... P14: {=SUMPRODUCT(P3:P13,$E$3:$E$13)} -> 27 | Q14: =SUMPRODUCT(Q3:Q13,$E$3:$E$13) -> 0 | R14: =SUMPRODUCT(R3:R13,$E$3:$E$13) -> 0 | S14: =SUMPRODUCT(S3:S13,$E$3:$E$13) -> 0 | T14: =SUMPRODUCT(T3:T13,$E$3:$E$13) -> 0 | U14: =SUMPRODUCT(U3:U13,$E$3:$E$13) -> 0 | V14: =SUMPRODUCT(V3:V13,$E$3:$E$13) -> 0 | W14: =SUMPRODUCT(W3:W13,$E$3:$E$13) -> 0
G16: 铜价 | I16: 69.43
G17: 材料中铜成本 | I17: =I14*I16 -> 0
G18: 材料中铝成本 | I18: =J14*18.21 -> 0
L19: 第七页

Sheet KSK线束BOM明细 
A1: 线束零件号 | B1: 零件名称 | C1: 零件号 | D1: 物料名称/零件名称 | E1: 是否半成品 | F1: 物料型号/SAP | I1: 回路 | J1: 数量 | K1: 单位 | L1: 供应商 | M1: 总成件号 | N1: 其他备注 | O1: 责任人 | P1: 单价 | Q1: 铝重 | R1: 铜重 | S1: 非铜 | T1: 导线单价 | U1: 材料成本 | V1: 币别 | W1: 价格类型 | X1: 备注
A2: 6608523073 | B2: 组合式充电插座线束总成 | C2: PP3241918 | D2: 法兰组件 | E2: N | J2: 1 | K2: PCS | L2: 天海 | M2: TC-GADC-125A1000V32A250V-0 10Y1 充电座 | N2: 客户指定 | O2: =IFERROR(VLOOKUP($C2,二次物料明细!$A:$N,COLUMN(二次物料明细!H$1),),0) -> 江苏林 | P2: =IFERROR(VLOOKUP($C2,二次物料明细!$A:$N,COLUMN(二次物料明细!I$1),),0) -> 170 | Q2: =IFERROR(VLOOKUP($C2,二次物料明细!$A:$N,COLUMN(二次物料明细!J$1),),0) -> 0 | R2: =IFERROR(VLOOKUP($C2,二次物料明细!$A:$N,COLUMN(二次物料明细!K$1),),0) -> 0 | S2: =IFERROR(VLOOKUP($C2,二次物料明细!$A:$N,COLUMN(二次物料明细!L$1),),0) -> 0 | T2: =(R2*90.11+Q2*21.24+S2)/1000 -> 0 | U2: =(P2+T2)*J2 -> 170 | V2: =IFERROR(VLOOKUP($C2,二次物料明细!$A:$N,COLUMN(二次物料明细!M$1),),0) -> 0 | W2: =IFERROR(VLOOKUP($C2,二次物料明细!$A:$N,COLUMN(二次物料明细!N$1),),0) -> 总成参考价-销售估价
A3: 6608523073 | B3: 组合式充电插座线束总成 | C3: PP3241190 | D3: 防尘盖组件 | E3: N | F3: A02102700 | J3: 1 | K3: PCS | L3: 天海 | N3: 客户指定 | O3: =IFERROR(VLOOKUP($C3,二次物料明细!$A:$N,COLUMN(二次物料明细!H$1),),0) -> 江苏林 | P3: =IFERROR(VLOOKUP($C3,二次物料明细!$A:$N,COLUMN(二次物料明细!I$1),),0) -> 0 | Q3: =IFERROR(VLOOKUP($C3,二次物料明细!$A:$N,COLUMN(二次物料明细!J$1),),0) -> 0 | R3: =IFERROR(VLOOKUP($C3,二次物料明细!$A:$N,COLUMN(二次物料明细!K$1),),0) -> 0 | S3: =IFERROR(VLOOKUP($C3,二次物料明细!$A:$N,COLUMN(二次物料明细!L$1),),0) -> 0 | T3: =(R3*90.11+Q3*21.24+S3)/1000 -> 0 | U3: =(P3+T3)*J3 -> 0 | V3: =IFERROR(VLOOKUP($C3,二次物料明细!$A:$N,COLUMN(二次物料明细!M$1),),0) -> CNY | W3: =IFERROR(VLOOKUP($C3,二次物料明细!$A:$N,COLUMN(二次物料明细!N$1),),0) -> 散件
A4: 6608523073 | B4: 组合式充电插座线束总成 | C4: PP3241410 | D4: 70平DC端子 | E4: N | F4: A03103099 | J4: 2 | K4: PCS | L4: 天海 | N4: 客户指定 | O4: =IFERROR(VLOOKUP($C4,二次物料明细!$A:$N,COLUMN(二次物料明细!H$1),),0) -> 江苏林 | P4: =IFERROR(VLOOKUP($C4,二次物料明细!$A:$N,COLUMN(二次物料明细!I$1),),0) -> 0 | Q4: =IFERROR(VLOOKUP($C4,二次物料明细!$A:$N,COLUMN(二次物料明细!J$1),),0) -> 0 | R4: =IFERROR(VLOOKUP($C4,二次物料明细!$A:$N,COLUMN(二次物料明细!K$1),),0) -> 0 | S4: =IFERROR(VLOOKUP($C4,二次物料明细!$A:$N,COLUMN(二次物料明细!L$1),),0) -> 0 | T4: =(R4*90.11+Q4*21.24+S4)/1000 -> 0 | U4: =(P4+T4)*J4 -> 0 | V4: =IFERROR(VLOOKUP($C4,二次物料明细!$A:$N,COLUMN(二次物料明细!M$1),),0) -> 0 | W4: =IFERROR(VLOOKUP($C4,二次物料明细!$A:$N,COLUMN(二次物料明细!N$1),),0) -> 散件
A5: 6608523073 | B5: 组合式充电插座线束总成 | C5: PP3241183 | D5: 50平DC尾盖 | E5: N | F5: A02104381 | J5: 2 | K5: PCS | L5: 天海 | N5: 客户指定 | O5: =IFERROR(VLOOKUP($C5,二次物料明细!$A:$N,COLUMN(二次物料明细!H$1),),0) -> 江苏林 | P5: =IFERROR(VLOOKUP($C5,二次物料明细!$A:$N,COLUMN(二次物料明细!I$1),),0) -> 0 | Q5: =IFERROR(VLOOKUP($C5,二次物料明细!$A:$N,COLUMN(二次物料明细!J$1),),0) -> 0 | R5: =IFERROR(VLOOKUP($C5,二次物料明细!$A:$N,COLUMN(二次物料明细!K$1),),0) -> 0 | S5: =IFERROR(VLOOKUP($C5,二次物料明细!$A:$N,COLUMN(二次物料明细!L$1),),0) -> 0 | T5: =(R5*90.11+Q5*21.24+S5)/1000 -> 0 | U5: =(P5+T5)*J5 -> 0 | V5: =IFERROR(VLOOKUP($C5,二次物料明细!$A:$N,COLUMN(二次物料明细!M$1),),0) -> 0 | W5: =IFERROR(VLOOKUP($C5,二次物料明细!$A:$N,COLUMN(二次物料明细!N$1),),0) -> 散件
A6: 6608523073 | B6: 组合式充电插座线束总成 | C6: PP3241184 | D6: 50平DC线塞 | E6: N | F6: A02104379 | J6: 2 | K6: PCS | L6: 天海 | N6: 客户指定 | O6: =IFERROR(VLOOKUP($C6,二次物料明细!$A:$N,COLUMN(二次物料明细!H$1),),0) -> 江苏林 | P6: =IFERROR(VLOOKUP($C6,二次物料明细!$A:$N,COLUMN(二次物料明细!I$1),),0) -> 0 | Q6: =IFERROR(VLOOKUP($C6,二次物料明细!$A:$N,COLUMN(二次物料明细!J$1),),0) -> 0 | R6: =IFERROR(VLOOKUP($C6,二次物料明细!$A:$N,COLUMN(二次物料明细!K$1),),0) -> 0 | S6: =IFERROR(VLOOKUP($C6,二次物料明细!$A:$N,COLUMN(二次物料明细!L$1),),0) -> 0 | T6: =(R6*90.11+Q6*21.24+S6)/1000 -> 0 | U6: =(P6+T6)*J6 -> 0 | V6: =IFERROR(VLOOKUP($C6,二次物料明细!$A:$N,COLUMN(二次物料明细!M$1),),0) -> 0 | W6: =IFERROR(VLOOKUP($C6,二次物料明细!$A:$N,COLUMN(二次物料明细!N$1),),0) -> 散件
A7: 6608523073 | B7: 组合式充电插座线束总成 | C7: PP3241319 | D7: PE端子 | E7: N | F7: A03101934 | J7: 1 | K7: PCS | L7: 天海 | N7: 客户指定 | O7: =IFERROR(VLOOKUP($C7,二次物料明细!$A:$N,COLUMN(二次物料明细!H$1),),0) -> 江苏林 | P7: =IFERROR(VLOOKUP($C7,二次物料明细!$A:$N,COLUMN(二次物料明细!I$1),),0) -> 0 | Q7: =IFERROR(VLOOKUP($C7,二次物料明细!$A:$N,COLUMN(二次物料明细!J$1),),0) -> 0 | R7: =IFERROR(VLOOKUP($C7,二次物料明细!$A:$N,COLUMN(二次物料明细!K$1),),0) -> 0 | S7: =IFERROR(VLOOKUP($C7,二次物料明细!$A:$N,COLUMN(二次物料明细!L$1),),0) -> 0 | T7: =(R7*90.11+Q7*21.24+S7)/1000 -> 0 | U7: =(P7+T7)*J7 -> 0 | V7: =IFERROR(VLOOKUP($C7,二次物料明细!$A:$N,COLUMN(二次物料明细!M$1),),0) -> CNY | W7: =IFERROR(VLOOKUP($C7,二次物料明细!$A:$N,COLUMN(二次物料明细!N$1),),0) -> 散件
A8: 6608523073 | B8: 组合式充电插座线束总成 | C8: PP3241115 | D8: PE胶圈 | E8: N | F8: A02102631 | J8: 1 | K8: PCS | L8: 天海 | N8: 客户指定 | O8: =IFERROR(VLOOKUP($C8,二次物料明细!$A:$N,COLUMN(二次物料明细!H$1),),0) -> 江苏林 | P8: =IFERROR(VLOOKUP($C8,二次物料明细!$A:$N,COLUMN(二次物料明细!I$1),),0) -> 0 | Q8: =IFERROR(VLOOKUP($C8,二次物料明细!$A:$N,COLUMN(二次物料明细!J$1),),0) -> 0 | R8: =IFERROR(VLOOKUP($C8,二次物料明细!$A:$N,COLUMN(二次物料明细!K$1),),0) -> 0 | S8: =IFERROR(VLOOKUP($C8,二次物料明细!$A:$N,COLUMN(二次物料明细!L$1),),0) -> 0 | T8: =(R8*90.11+Q8*21.24+S8)/1000 -> 0 | U8: =(P8+T8)*J8 -> 0 | V8: =IFERROR(VLOOKUP($C8,二次物料明细!$A:$N,COLUMN(二次物料明细!M$1),),0) -> CNY | W8: =IFERROR(VLOOKUP($C8,二次物料明细!$A:$N,COLUMN(二次物料明细!N$1),),0) -> 散件
A9: 6608523073 | B9: 组合式充电插座线束总成 | C9: PP3241195 | D9: 6平PE尾盖 | E9: N | F9: A02102630 | J9: 1 | K9: PCS | L9: 天海 | N9: 客户指定 | O9: =IFERROR(VLOOKUP($C9,二次物料明细!$A:$N,COLUMN(二次物料明细!H$1),),0) -> 江苏林 | P9: =IFERROR(VLOOKUP($C9,二次物料明细!$A:$N,COLUMN(二次物料明细!I$1),),0) -> 0 | Q9: =IFERROR(VLOOKUP($C9,二次物料明细!$A:$N,COLUMN(二次物料明细!J$1),),0) -> 0 | R9: =IFERROR(VLOOKUP($C9,二次物料明细!$A:$N,COLUMN(二次物料明细!K$1),),0) -> 0 | S9: =IFERROR(VLOOKUP($C9,二次物料明细!$A:$N,COLUMN(二次物料明细!L$1),),0) -> 0 | T9: =(R9*90.11+Q9*21.24+S9)/1000 -> 0 | U9: =(P9+T9)*J9 -> 0 | V9: =IFERROR(VLOOKUP($C9,二次物料明细!$A:$N,COLUMN(二次物料明细!M$1),),0) -> CNY | W9: =IFERROR(VLOOKUP($C9,二次物料明细!$A:$N,COLUMN(二次物料明细!N$1),),0) -> 散件
A10: 6608523073 | B10: 组合式充电插座线束总成 | C10: PP3241196 | D10: 6平PE线塞 | E10: N | F10: A02102629 | J10: 1 | K10: PCS | L10: 天海 | N10: 客户指定 | O10: =IFERROR(VLOOKUP($C10,二次物料明细!$A:$N,COLUMN(二次物料明细!H$1),),0) -> 江苏林 | P10: =IFERROR(VLOOKUP($C10,二次物料明细!$A:$N,COLUMN(二次物料明细!I$1),),0) -> 0 | Q10: =IFERROR(VLOOKUP($C10,二次物料明细!$A:$N,COLUMN(二次物料明细!J$1),),0) -> 0 | R10: =IFERROR(VLOOKUP($C10,二次物料明细!$A:$N,COLUMN(二次物料明细!K$1),),0) -> 0 | S10: =IFERROR(VLOOKUP($C10,二次物料明细!$A:$N,COLUMN(二次物料明细!L$1),),0) -> 0 | T10: =(R10*90.11+Q10*21.24+S10)/1000 -> 0 | U10: =(P10+T10)*J10 -> 0 | V10: =IFERROR(VLOOKUP($C10,二次物料明细!$A:$N,COLUMN(二次物料明细!M$1),),0) -> CNY | W10: =IFERROR(VLOOKUP($C10,二次物料明细!$A:$N,COLUMN(二次物料明细!N$1),),0) -> 散件
A11: 6608523073 | B11: 组合式充电插座线束总成 | C11: PP3241175 | D11: 5平AC线塞 | E11: N | F11: A02104380 | J11: 1 | K11: PCS | L11: 天海 | N11: 客户指定 | O11: =IFERROR(VLOOKUP($C11,二次物料明细!$A:$N,COLUMN(二次物料明细!H$1),),0) -> 江苏林 | P11: =IFERROR(VLOOKUP($C11,二次物料明细!$A:$N,COLUMN(二次物料明细!I$1),),0) -> 0 | Q11: =IFERROR(VLOOKUP($C11,二次物料明细!$A:$N,COLUMN(二次物料明细!J$1),),0) -> 0 | R11: =IFERROR(VLOOKUP($C11,二次物料明细!$A:$N,COLUMN(二次物料明细!K$1),),0) -> 0 | S11: =IFERROR(VLOOKUP($C11,二次物料明细!$A:$N,COLUMN(二次物料明细!L$1),),0) -> 0 | T11: =(R11*90.11+Q11*21.24+S11)/1000 -> 0 | U11: =(P11+T11)*J11 -> 0 | V11: =IFERROR(VLOOKUP($C11,二次物料明细!$A:$N,COLUMN(二次物料明细!M$1),),0) -> 0 | W11: =IFERROR(VLOOKUP($C11,二次物料明细!$A:$N,COLUMN(二次物料明细!N$1),),0) -> 散件
A12: 6608523073 | B12: 组合式充电插座线束总成 | C12: PP3241174 | D12: 5平AC小尾盖 | E12: N | F12: A02104378 | J12: 1 | K12: PCS | L12: 天海 | N12: 客户指定 | O12: =IFERROR(VLOOKUP($C12,二次物料明细!$A:$N,COLUMN(二次物料明细!H$1),),0) -> 江苏林 | P12: =IFERROR(VLOOKUP($C12,二次物料明细!$A:$N,COLUMN(二次物料明细!I$1),),0) -> 0 | Q12: =IFERROR(VLOOKUP($C12,二次物料明细!$A:$N,COLUMN(二次物料明细!J$1),),0) -> 0 | R12: =IFERROR(VLOOKUP($C12,二次物料明细!$A:$N,COLUMN(二次物料明细!K$1),),0) -> 0 | S12: =IFERROR(VLOOKUP($C12,二次物料明细!$A:$N,COLUMN(二次物料明细!L$1),),0) -> 0 | T12: =(R12*90.11+Q12*21.24+S12)/1000 -> 0 | U12: =(P12+T12)*J12 -> 0 | V12: =IFERROR(VLOOKUP($C12,二次物料明细!$A:$N,COLUMN(二次物料明细!M$1),),0) -> 0 | W12: =IFERROR(VLOOKUP($C12,二次物料明细!$A:$N,COLUMN(二次物料明细!N$1),),0) -> 散件
A13: 6608523073 | B13: 组合式充电插座线束总成 | C13: PP3241321 | D13: 6平功率插孔 | E13: N | F13: A03101936 | J13: 3 | K13: PCS | L13: 天海 | N13: 客户指定 | O13: =IFERROR(VLOOKUP($C13,二次物料明细!$A:$N,COLUMN(二次物料明细!H$1),),0) -> 江苏林 | P13: =IFERROR(VLOOKUP($C13,二次物料明细!$A:$N,COLUMN(二次物料明细!I$1),),0) -> 0 | Q13: =IFERROR(VLOOKUP($C13,二次物料明细!$A:$N,COLUMN(二次物料明细!J$1),),0) -> 0 | R13: =IFERROR(VLOOKUP($C13,二次物料明细!$A:$N,COLUMN(二次物料明细!K$1),),0) -> 0 | S13: =IFERROR(VLOOKUP($C13,二次物料明细!$A:$N,COLUMN(二次物料明细!L$1),),0) -> 0 | T13: =(R13*90.11+Q13*21.24+S13)/1000 -> 0 | U13: =(P13+T13)*J13 -> 0 | V13: =IFERROR(VLOOKUP($C13,二次物料明细!$A:$N,COLUMN(二次物料明细!M$1),),0) -> CNY | W13: =IFERROR(VLOOKUP($C13,二次物料明细!$A:$N,COLUMN(二次物料明细!N$1),),0) -> 散件
A14: 6608523073 | B14: 组合式充电插座线束总成 | C14: PP3241117 | D14: 6mm功率胶圈 | E14: N | F14: A02102708 | J14: 3 | K14: PCS | L14: 天海 | N14: 客户指定 | O14: =IFERROR(VLOOKUP($C14,二次物料明细!$A:$N,COLUMN(二次物料明细!H$1),),0) -> 江苏林 | P14: =IFERROR(VLOOKUP($C14,二次物料明细!$A:$N,COLUMN(二次物料明细!I$1),),0) -> 0 | Q14: =IFERROR(VLOOKUP($C14,二次物料明细!$A:$N,COLUMN(二次物料明细!J$1),),0) -> 0 | R14: =IFERROR(VLOOKUP($C14,二次物料明细!$A:$N,COLUMN(二次物料明细!K$1),),0) -> 0 | S14: =IFERROR(VLOOKUP($C14,二次物料明细!$A:$N,COLUMN(二次物料明细!L$1),),0) -> 0 | T14: =(R14*90.11+Q14*21.24+S14)/1000 -> 0 | U14: =(P14+T14)*J14 -> 0 | V14: =IFERROR(VLOOKUP($C14,二次物料明细!$A:$N,COLUMN(二次物料明细!M$1),),0) -> CNY | W14: =IFERROR(VLOOKUP($C14,二次物料明细!$A:$N,COLUMN(二次物料明细!N$1),),0) -> 散件
A15: 6608523073 | B15: 组合式充电插座线束总成 | C15: M21009005 | D15: P161电子锁 | E15: N | J15: 1 | K15: PCS | L15: 天海 | N15: 客户指定 | O15: =IFERROR(VLOOKUP($C15,二次物料明细!$A:$N,COLUMN(二次物料明细!H$1),),0) -> 江苏林 | P15: =IFERROR(VLOOKUP($C15,二次物料明细!$A:$N,COLUMN(二次物料明细!I$1),),0) -> 0 | Q15: =IFERROR(VLOOKUP($C15,二次物料明细!$A:$N,COLUMN(二次物料明细!J$1),),0) -> 0 | R15: =IFERROR(VLOOKUP($C15,二次物料明细!$A:$N,COLUMN(二次物料明细!K$1),),0) -> 0 | S15: =IFERROR(VLOOKUP($C15,二次物料明细!$A:$N,COLUMN(二次物料明细!L$1),),0) -> 0 | T15: =(R15*90.11+Q15*21.24+S15)/1000 -> 0 | U15: =(P15+T15)*J15 -> 0 | V15: =IFERROR(VLOOKUP($C15,二次物料明细!$A:$N,COLUMN(二次物料明细!M$1),),0) -> 0 | W15: =IFERROR(VLOOKUP($C15,二次物料明细!$A:$N,COLUMN(二次物料明细!N$1),),0) -> 散件
A16: 6608523073 | B16: 组合式充电插座线束总成 | C16: M93000476 | D16: ST2.9*16 | E16: N | F16: A07100113 | J16: 2 | K16: PCS | L16: 天海 | N16: 客户指定 | O16: =IFERROR(VLOOKUP($C16,二次物料明细!$A:$N,COLUMN(二次物料明细!H$1),),0) -> 江苏林 | P16: =IFERROR(VLOOKUP($C16,二次物料明细!$A:$N,COLUMN(二次物料明细!I$1),),0) -> 0 | Q16: =IFERROR(VLOOKUP($C16,二次物料明细!$A:$N,COLUMN(二次物料明细!J$1),),0) -> 0 | R16: =IFERROR(VLOOKUP($C16,二次物料明细!$A:$N,COLUMN(二次物料明细!K$1),),0) -> 0 | S16: =IFERROR(VLOOKUP($C16,二次物料明细!$A:$N,COLUMN(二次物料明细!L$1),),0) -> 0 | T16: =(R16*90.11+Q16*21.24+S16)/1000 -> 0 | U16: =(P16+T16)*J16 -> 0 | V16: =IFERROR(VLOOKUP($C16,二次物料明细!$A:$N,COLUMN(二次物料明细!M$1),),0) -> 0 | W16: =IFERROR(VLOOKUP($C16,二次物料明细!$A:$N,COLUMN(二次物料明细!N$1),),0) -> 散件
A17: 6608523073 | B17: 组合式充电插座线束总成 | C17: HVPC2P1600FE6-NH-MP010 | D17: 护套塑壳 | E17: N | F17: A02104377 | J17: 1 | K17: PCS | L17: 安费诺 | M17: HVSPC2P1600FE650-NH-P010 50mm²单芯非屏蔽硅胶铝导线 直流接ODP端 | N17: 客户指定 | O17: =IFERROR(VLOOKUP($C17,二次物料明细!$A:$N,COLUMN(二次物料明细!H$1),),0) -> 胡继燕 | P17: =IFERROR(VLOOKUP($C17,二次物料明细!$A:$N,COLUMN(二次物料明细!I$1),),0) -> 24 | Q17: =IFERROR(VLOOKUP($C17,二次物料明细!$A:$N,COLUMN(二次物料明细!J$1),),0) -> 0 | R17: =IFERROR(VLOOKUP($C17,二次物料明细!$A:$N,COLUMN(二次物料明细!K$1),),0) -> 0 | S17: =IFERROR(VLOOKUP($C17,二次物料明细!$A:$N,COLUMN(二次物料明细!L$1),),0) -> 0 | T17: =(R17*90.11+Q17*21.24+S17)/1000 -> 0 | U17: =(P17+T17)*J17 -> 24 | V17: =IFERROR(VLOOKUP($C17,二次物料明细!$A:$N,COLUMN(二次物料明细!M$1),),0) -> 0 | W17: =IFERROR(VLOOKUP($C17,二次物料明细!$A:$N,COLUMN(二次物料明细!N$1),),0) -> 总成参考价
A18: 6608523073 | B18: 组合式充电插座线束总成 | C18: HVPC2P1600FE-05P010 | D18: 焊接端子 | E18: N | F18: A03103097 | J18: 2 | K18: PCS | L18: 安费诺 | N18: 客户指定 | O18: =IFERROR(VLOOKUP($C18,二次物料明细!$A:$N,COLUMN(二次物料明细!H$1),),0) -> 胡继燕 | P18: =IFERROR(VLOOKUP($C18,二次物料明细!$A:$N,COLUMN(二次物料明细!I$1),),0) -> 0 | Q18: =IFERROR(VLOOKUP($C18,二次物料明细!$A:$N,COLUMN(二次物料明细!J$1),),0) -> 0 | R18: =IFERROR(VLOOKUP($C18,二次物料明细!$A:$N,COLUMN(二次物料明细!K$1),),0) -> 0 | S18: =IFERROR(VLOOKUP($C18,二次物料明细!$A:$N,COLUMN(二次物料明细!L$1),),0) -> 0 | T18: =(R18*90.11+Q18*21.24+S18)/1000 -> 0 | U18: =(P18+T18)*J18 -> 0 | V18: =IFERROR(VLOOKUP($C18,二次物料明细!$A:$N,COLUMN(二次物料明细!M$1),),0) -> 0 | W18: =IFERROR(VLOOKUP($C18,二次物料明细!$A:$N,COLUMN(二次物料明细!N$1),),0) -> 散件
A19: 6608523073 | B19: 组合式充电插座线束总成 | C19: HVPC2P1600FV-15P010 | D19: 挡板 | E19: N | F19: A02104375 | J19: 2 | K19: PCS | L19: 安费诺 | N19: 客户指定 | O19: =IFERROR(VLOOKUP($C19,二次物料明细!$A:$N,COLUMN(二次物料明细!H$1),),0) -> 胡继燕 | P19: =IFERROR(VLOOKUP($C19,二次物料明细!$A:$N,COLUMN(二次物料明细!I$1),),0) -> 0 | Q19: =IFERROR(VLOOKUP($C19,二次物料明细!$A:$N,COLUMN(二次物料明细!J$1),),0) -> 0 | R19: =IFERROR(VLOOKUP($C19,二次物料明细!$A:$N,COLUMN(二次物料明细!K$1),),0) -> 0 | S19: =IFERROR(VLOOKUP($C19,二次物料明细!$A:$N,COLUMN(二次物料明细!L$1),),0) -> 0 | T19: =(R19*90.11+Q19*21.24+S19)/1000 -> 0 | U19: =(P19+T19)*J19 -> 0 | V19: =IFERROR(VLOOKUP($C19,二次物料明细!$A:$N,COLUMN(二次物料明细!M$1),),0) -> 0 | W19: =IFERROR(VLOOKUP($C19,二次物料明细!$A:$N,COLUMN(二次物料明细!N$1),),0) -> 散件
A20: 6608523073 | B20: 组合式充电插座线束总成 | C20: HVSPC2P1600FV-12-50P010 | D20: 插头线束密封圈 | E20: N | F20: A02104376 | J20: 2 | K20: PCS | L20: 安费诺 | N20: 客户指定 | O20: =IFERROR(VLOOKUP($C20,二次物料明细!$A:$N,COLUMN(二次物料明细!H$1),),0) -> 胡继燕 | P20: =IFERROR(VLOOKUP($C20,二次物料明细!$A:$N,COLUMN(二次物料明细!I$1),),0) -> 0 | Q20: =IFERROR(VLOOKUP($C20,二次物料明细!$A:$N,COLUMN(二次物料明细!J$1),),0) -> 0 | R20: =IFERROR(VLOOKUP($C20,二次物料明细!$A:$N,COLUMN(二次物料明细!K$1),),0) -> 0 | S20: =IFERROR(VLOOKUP($C20,二次物料明细!$A:$N,COLUMN(二次物料明细!L$1),),0) -> 0 | T20: =(R20*90.11+Q20*21.24+S20)/1000 -> 0 | U20: =(P20+T20)*J20 -> 0 | V20: =IFERROR(VLOOKUP($C20,二次物料明细!$A:$N,COLUMN(二次物料明细!M$1),),0) -> 0 | W20: =IFERROR(VLOOKUP($C20,二次物料明细!$A:$N,COLUMN(二次物料明细!N$1),),0) -> 散件
A21: 6608523073 | B21: 组合式充电插座线束总成 | C21: HVSPC2P1600FV-11-50P010 | D21: 插头线卡 | E21: N | F21: A02104374 | J21: 2 | K21: PCS | L21: 安费诺 | N21: 客户指定 | O21: =IFERROR(VLOOKUP($C21,二次物料明细!$A:$N,COLUMN(二次物料明细!H$1),),0) -> 胡继燕 | P21: =IFERROR(VLOOKUP($C21,二次物料明细!$A:$N,COLUMN(二次物料明细!I$1),),0) -> 0 | Q21: =IFERROR(VLOOKUP($C21,二次物料明细!$A:$N,COLUMN(二次物料明细!J$1),),0) -> 0 | R21: =IFERROR(VLOOKUP($C21,二次物料明细!$A:$N,COLUMN(二次物料明细!K$1),),0) -> 0 | S21: =IFERROR(VLOOKUP($C21,二次物料明细!$A:$N,COLUMN(二次物料明细!L$1),),0) -> 0 | T21: =(R21*90.11+Q21*21.24+S21)/1000 -> 0 | U21: =(P21+T21)*J21 -> 0 | V21: =IFERROR(VLOOKUP($C21,二次物料明细!$A:$N,COLUMN(二次物料明细!M$1),),0) -> 0 | W21: =IFERROR(VLOOKUP($C21,二次物料明细!$A:$N,COLUMN(二次物料明细!N$1),),0) -> 散件
A22: 6608523073 | B22: 组合式充电插座线束总成 | C22: HVSPC2P1600FV-10-50P010 | D22: 插头尾盖 | E22: N | F22: A02104373 | J22: 2 | K22: PCS | L22: 安费诺 | N22: 客户指定 | O22: =IFERROR(VLOOKUP($C22,二次物料明细!$A:$N,COLUMN(二次物料明细!H$1),),0) -> 胡继燕 | P22: =IFERROR(VLOOKUP($C22,二次物料明细!$A:$N,COLUMN(二次物料明细!I$1),),0) -> 0 | Q22: =IFERROR(VLOOKUP($C22,二次物料明细!$A:$N,COLUMN(二次物料明细!J$1),),0) -> 0 | R22: =IFERROR(VLOOKUP($C22,二次物料明细!$A:$N,COLUMN(二次物料明细!K$1),),0) -> 0 | S22: =IFERROR(VLOOKUP($C22,二次物料明细!$A:$N,COLUMN(二次物料明细!L$1),),0) -> 0 | T22: =(R22*90.11+Q22*21.24+S22)/1000 -> 0 | U22: =(P22+T22)*J22 -> 0 | V22: =IFERROR(VLOOKUP($C22,二次物料明细!$A:$N,COLUMN(二次物料明细!M$1),),0) -> 0 | W22: =IFERROR(VLOOKUP($C22,二次物料明细!$A:$N,COLUMN(二次物料明细!N$1),),0) -> 散件
A23: 6608523073 | B23: 组合式充电插座线束总成 | C23: HVC2PG263UFSW106-NH-P010 | D23: 高压线束总成 | E23: N | J23: 1 | K23: SET | L23: 安费诺 | M23: HVC2PG263UFSW106-NH-P010 6mm²高压非屏蔽交联铝线 交流接ODP端 | N23: 客户指定 | O23: =IFERROR(VLOOKUP($C23,二次物料明细!$A:$N,COLUMN(二次物料明细!H$1),),0) -> 胡继燕 | P23: =IFERROR(VLOOKUP($C23,二次物料明细!$A:$N,COLUMN(二次物料明细!I$1),),0) -> 10 | Q23: =IFERROR(VLOOKUP($C23,二次物料明细!$A:$N,COLUMN(二次物料明细!J$1),),0) -> 0 | R23: =IFERROR(VLOOKUP($C23,二次物料明细!$A:$N,COLUMN(二次物料明细!K$1),),0) -> 0 | S23: =IFERROR(VLOOKUP($C23,二次物料明细!$A:$N,COLUMN(二次物料明细!L$1),),0) -> 0 | T23: =(R23*90.11+Q23*21.24+S23)/1000 -> 0 | U23: =(P23+T23)*J23 -> 10 | V23: =IFERROR(VLOOKUP($C23,二次物料明细!$A:$N,COLUMN(二次物料明细!M$1),),0) -> 0 | W23: =IFERROR(VLOOKUP($C23,二次物料明细!$A:$N,COLUMN(二次物料明细!N$1),),0) -> 总成参考价
A24: 6608523073 | B24: 组合式充电插座线束总成 | C24: 5-2385463-1 | D24: 护套塑壳 | E24: N | F24: A02101947 | J24: 1 | K24: PCS | L24: TE | M24: 5-2385463-1 0.5mm²低压线 接整车低压线束 | N24: 客户指定 | O24: =IFERROR(VLOOKUP($C24,二次物料明细!$A:$N,COLUMN(二次物料明细!H$1),),0) -> 洪巧明 | P24: =IFERROR(VLOOKUP($C24,二次物料明细!$A:$N,COLUMN(二次物料明细!I$1),),0) -> 1.5 | Q24: =IFERROR(VLOOKUP($C24,二次物料明细!$A:$N,COLUMN(二次物料明细!J$1),),0) -> 0 | R24: =IFERROR(VLOOKUP($C24,二次物料明细!$A:$N,COLUMN(二次物料明细!K$1),),0) -> 0 | S24: =IFERROR(VLOOKUP($C24,二次物料明细!$A:$N,COLUMN(二次物料明细!L$1),),0) -> 0 | T24: =(R24*90.11+Q24*21.24+S24)/1000 -> 0 | U24: =(P24+T24)*J24 -> 1.5 | V24: =IFERROR(VLOOKUP($C24,二次物料明细!$A:$N,COLUMN(二次物料明细!M$1),),0) -> CNY | W24: =IFERROR(VLOOKUP($C24,二次物料明细!$A:$N,COLUMN(二次物料明细!N$1),),0) -> 系统价
A25: 6608523073 | B25: 组合式充电插座线束总成 | C25: 2377023-2 | D25: 压接端子 | E25: N | F25: A03033091 | J25: 17 | K25: PCS | L25: TE | N25: 客户指定 | O25: =IFERROR(VLOOKUP($C25,二次物料明细!$A:$N,COLUMN(二次物料明细!H$1),),0) -> 洪巧明 | P25: =IFERROR(VLOOKUP($C25,二次物料明细!$A:$N,COLUMN(二次物料明细!I$1),),0) -> 0.06 | Q25: =IFERROR(VLOOKUP($C25,二次物料明细!$A:$N,COLUMN(二次物料明细!J$1),),0) -> 0 | R25: =IFERROR(VLOOKUP($C25,二次物料明细!$A:$N,COLUMN(二次物料明细!K$1),),0) -> 0 | S25: =IFERROR(VLOOKUP($C25,二次物料明细!$A:$N,COLUMN(二次物料明细!L$1),),0) -> 0 | T25: =(R25*90.11+Q25*21.24+S25)/1000 -> 0 | U25: =(P25+T25)*J25 -> 1.02 | V25: =IFERROR(VLOOKUP($C25,二次物料明细!$A:$N,COLUMN(二次物料明细!M$1),),0) -> CNY | W25: =IFERROR(VLOOKUP($C25,二次物料明细!$A:$N,COLUMN(二次物料明细!N$1),),0) -> 系统价
A26: 6608523073 | B26: 组合式充电插座线束总成 | C26: 2377665-4 | D26: 密封塞 | E26: N | F26: A03033097 | J26: 17 | K26: PCS | L26: TE | N26: 客户指定 | O26: =IFERROR(VLOOKUP($C26,二次物料明细!$A:$N,COLUMN(二次物料明细!H$1),),0) -> 洪巧明 | P26: =IFERROR(VLOOKUP($C26,二次物料明细!$A:$N,COLUMN(二次物料明细!I$1),),0) -> 0.055 | Q26: =IFERROR(VLOOKUP($C26,二次物料明细!$A:$N,COLUMN(二次物料明细!J$1),),0) -> 0 | R26: =IFERROR(VLOOKUP($C26,二次物料明细!$A:$N,COLUMN(二次物料明细!K$1),),0) -> 0 | S26: =IFERROR(VLOOKUP($C26,二次物料明细!$A:$N,COLUMN(二次物料明细!L$1),),0) -> 0 | T26: =(R26*90.11+Q26*21.24+S26)/1000 -> 0 | U26: =(P26+T26)*J26 -> 0.935 | V26: =IFERROR(VLOOKUP($C26,二次物料明细!$A:$N,COLUMN(二次物料明细!M$1),),0) -> CNY | W26: =IFERROR(VLOOKUP($C26,二次物料明细!$A:$N,COLUMN(二次物料明细!N$1),),0) -> 系统价
A27: 6608523073 | B27: 组合式充电插座线束总成 | C27: 2377665-3 | D27: 小盲堵 | E27: N | F27: A02034386 | J27: 1 | K27: PCS | L27: TE | N27: 客户指定 | O27: =IFERROR(VLOOKUP($C27,二次物料明细!$A:$N,COLUMN(二次物料明细!H$1),),0) -> 洪巧明 | P27: =IFERROR(VLOOKUP($C27,二次物料明细!$A:$N,COLUMN(二次物料明细!I$1),),0) -> 0.045 | Q27: =IFERROR(VLOOKUP($C27,二次物料明细!$A:$N,COLUMN(二次物料明细!J$1),),0) -> 0 | R27: =IFERROR(VLOOKUP($C27,二次物料明细!$A:$N,COLUMN(二次物料明细!K$1),),0) -> 0 | S27: =IFERROR(VLOOKUP($C27,二次物料明细!$A:$N,COLUMN(二次物料明细!L$1),),0) -> 0 | T27: =(R27*90.11+Q27*21.24+S27)/1000 -> 0 | U27: =(P27+T27)*J27 -> 0.045 | V27: =IFERROR(VLOOKUP($C27,二次物料明细!$A:$N,COLUMN(二次物料明细!M$1),),0) -> CNY | W27: =IFERROR(VLOOKUP($C27,二次物料明细!$A:$N,COLUMN(二次物料明细!N$1),),0) -> 系统价
A28: 6608523073 | B28: 组合式充电插座线束总成 | C28: 963143-1 | D28: 大盲堵（1、8、15、22） | E28: N | F28: A02031363 | J28: 4 | K28: PCS | L28: TE | N28: 客户指定 | O28: =IFERROR(VLOOKUP($C28,二次物料明细!$A:$N,COLUMN(二次物料明细!H$1),),0) -> 洪巧明 | P28: =IFERROR(VLOOKUP($C28,二次物料明细!$A:$N,COLUMN(二次物料明细!I$1),),0) -> 0.182 | Q28: =IFERROR(VLOOKUP($C28,二次物料明细!$A:$N,COLUMN(二次物料明细!J$1),),0) -> 0 | R28: =IFERROR(VLOOKUP($C28,二次物料明细!$A:$N,COLUMN(二次物料明细!K$1),),0) -> 0 | S28: =IFERROR(VLOOKUP($C28,二次物料明细!$A:$N,COLUMN(二次物料明细!L$1),),0) -> 0 | T28: =(R28*90.11+Q28*21.24+S28)/1000 -> 0 | U28: =(P28+T28)*J28 -> 0.728 | V28: =IFERROR(VLOOKUP($C28,二次物料明细!$A:$N,COLUMN(二次物料明细!M$1),),0) -> CNY | W28: =IFERROR(VLOOKUP($C28,二次物料明细!$A:$N,COLUMN(二次物料明细!N$1),),0) -> 系统价
A29: 6608523073 | B29: 组合式充电插座线束总成 | C29: BH4311701 | D29: 卡花 | E29: N | F29: A06004040 | J29: 1 | K29: PCS | L29: 博昊 | N29: ★ | O29: =IFERROR(VLOOKUP($C29,二次物料明细!$A:$N,COLUMN(二次物料明细!H$1),),0) -> 邹娇 | P29: =IFERROR(VLOOKUP($C29,二次物料明细!$A:$N,COLUMN(二次物料明细!I$1),),0) -> 0.1 | Q29: =IFERROR(VLOOKUP($C29,二次物料明细!$A:$N,COLUMN(二次物料明细!J$1),),0) -> 0 | R29: =IFERROR(VLOOKUP($C29,二次物料明细!$A:$N,COLUMN(二次物料明细!K$1),),0) -> 0 | S29: =IFERROR(VLOOKUP($C29,二次物料明细!$A:$N,COLUMN(二次物料明细!L$1),),0) -> 0 | T29: =(R29*90.11+Q29*21.24+S29)/1000 -> 0 | U29: =(P29+T29)*J29 -> 0.1 | V29: =IFERROR(VLOOKUP($C29,二次物料明细!$A:$N,COLUMN(二次物料明细!M$1),),0) -> CNY | W29: =IFERROR(VLOOKUP($C29,二次物料明细!$A:$N,COLUMN(二次物料明细!N$1),),0) -> 系统价
A30: 6608523073 | B30: 组合式充电插座线束总成 | C30: PP6509712 | D30: 护套 | E30: N | F30: A02102696 | J30: 1 | K30: PCS | L30: 天海 | M30: DMS120LL-10P-10TA 0.5mm²低压线 接直流充电座 | N30: 客户指定 | O30: =IFERROR(VLOOKUP($C30,二次物料明细!$A:$N,COLUMN(二次物料明细!H$1),),0) -> 江苏林 | P30: =IFERROR(VLOOKUP($C30,二次物料明细!$A:$N,COLUMN(二次物料明细!I$1),),0) -> 3.3 | Q30: =IFERROR(VLOOKUP($C30,二次物料明细!$A:$N,COLUMN(二次物料明细!J$1),),0) -> 0 | R30: =IFERROR(VLOOKUP($C30,二次物料明细!$A:$N,COLUMN(二次物料明细!K$1),),0) -> 0 | S30: =IFERROR(VLOOKUP($C30,二次物料明细!$A:$N,COLUMN(二次物料明细!L$1),),0) -> 0 | T30: =(R30*90.11+Q30*21.24+S30)/1000 -> 0 | U30: =(P30+T30)*J30 -> 3.3 | V30: =IFERROR(VLOOKUP($C30,二次物料明细!$A:$N,COLUMN(二次物料明细!M$1),),0) -> CNY | W30: =IFERROR(VLOOKUP($C30,二次物料明细!$A:$N,COLUMN(二次物料明细!N$1),),0) -> 系统价
